Workbook

Sheet Summary
A1: Investment plan: summary
A2: Live formulas. Change Assumptions or Hiring Plan and this page updates.
A3: Cost
A4: New roles hired | B4: ='Hiring Plan'!F32 -> 26
A5: Annual loaded cost of new roles at full run-rate ($) | B5: ='Hiring Plan'!Q32 -> 1162961.7
A6: Monthly run-rate: new roles plus programs, month 12 ($) | B6: ='Monthly Model'!N6+'Monthly Model'!N8 -> 112413.48
A7: One-time hiring cost, all roles ($) | B7: ='Hiring Plan'!S32 -> 95739.777
A8: Cash in and out
A9: Pre-investment, months 1-6, Nov-Apr ($) | B9: =SUM('Monthly Model'!C9:H9) -> 490313.54
A10: Pre-investment, months 1-8, Nov-Jun ($) | B10: =SUM('Monthly Model'!C9:J9) -> 716340.49
A11: Investment, months 1-12, Nov-Oct ($) | B11: =SUM('Monthly Model'!C9:N9) -> 1165994.4
A12: Incremental gross profit back, months 1-12 ($) | B12: =SUM('Monthly Model'!C24:N24) -> 825452.16
A13: Net position at month 12 ($) | B13: ='Monthly Model'!N26 -> -340542.22
A14: Net position at month 18 ($) | B14: ='Monthly Model'!T26 -> 864889.35
A15: Payback month (cumulative gross profit covers cumulative investment) | B15: =IF(COUNT('Monthly Model'!C28:T28)=0,"Beyond month 18",INDEX('Monthly Model'!C4:T4,MIN('Monthly Model'!C28:T28))) -> Jan 28
A16: Revenue
A17: MRR at month 12, investment case ($) | B17: ='Monthly Model'!N22 -> 851644.76
A18: MRR at month 12, baseline with no hires ($) | B18: ='Monthly Model'!N12 -> 506128.9
A19: Net new MRR vs today ($) | B19: ='Monthly Model'!N22-Assumptions!B10 -> 401644.76
A20: Net new MRR the hires add vs baseline ($) | B20: ='Monthly Model'!N23 -> 345515.86
A21: ARR at month 12, investment case ($) | B21: ='Monthly Model'!N27 -> 10219737
A22: Gap to target MRR at month 12 ($) | B22: =MAX(0,Assumptions!B47-'Monthly Model'!N22) -> 148355.24
A24: Stretch: set Assumptions!B35 to 3 (three more US AEs from month 3) and B28 to 1.5% churn to model the $1M MRR case.

Sheet Assumptions
A1: Assumptions
A2: Blue = input you can change; yellow = key assumption. Every other tab recalculates from here.
A3: People costs
A4: FX rate (INR per USD) | B4: 94 | C4: From the Paid Media tracker (Leadership Dashboard input)
A5: Employer loading, India payroll | B5: 0.04 | C5: From the Paid Media tracker (Employer loading on salaries)
A6: Employer loading, USD payroll | B6: 0.12 | C6: Assumption: payroll taxes and benefits for USD-paid roles
A7: Agency fee on senior hires (% of annual OTE) | B7: 0.0833 | C7: Assumption: one month of CTC, standard India search fee
A8: Onboarding cost per hire ($, laptop and setup) | B8: 1200 | C8: Assumption
A9: Revenue base
A10: Opening MRR, TripleDart ($) | B10: 450000 | C10: From the user: $450K MRR today
A11: Baseline new MRR a month from today's engine ($) | B11: 19000 | C11: Client master: 2026 kick-offs ($180K active MRR) over ~9.5 months
A12: Baseline monthly gross churn | B12: 0.03 | C12: Assumption; paid media runs ~7% (Client Book), SEO and RevOps unknown
A13: Gross margin on incremental revenue | B13: 0.6 | C13: P&L Jun-Sep 2026: direct cost 39-45% of revenue
A14: Sales productivity
A15: Quota per India and RoW closer (new ARR a year, $) | B15: 1200000 | C15: User target: India and RoW team $3.5-4M (leader + 2 AEs)
A16: Quota per US AE (new ARR a year, $) | B16: 1200000 | C16: Assumption, ramped
A17: Sudharshan's added bookings from US SDR meetings (new ARR a year, $) | B17: 600000 | C17: Assumption
A18: Partnerships manager (new ARR a year, $) | B18: 500000 | C18: Assumption
A19: Months before first bookings, India and RoW and SDR-sourced | B19: 2 | C19: 30-60 day sales cycle
A20: Months before first bookings, US AE | B20: 3 | C20: 60-90 day sales cycle
A21: Months before first bookings, partnerships | B21: 3 | C21: Assumption
A22: Ramp step per month after first bookings | B22: 0.25 | C22: Full productivity four months after first bookings
A23: Expansion
A24: Expansion from account management at full run-rate ($ new MRR a month) | B24: 5000 | C24: Price-ups and cross-sell; assumption
A25: Expansion per FDM at full run-rate ($ new MRR a month) | B25: 4000 | C25: Tier-1 account expansion; assumption
A26: Months after start before expansion begins | B26: 2 | C26: Half run-rate in that month, full after
A27: Retention
A28: Churn floor with the account management layer | B28: 0.02 | C28: Target
A29: Churn reduction per month, from month 3 | B29: 0.002 | C29: Reaches the floor in month 7
A30: Programs
A31: Sales tools and data ($ a month) | B31: 2500 | C31: Sales Navigator, Apollo/Clay, dialer
A32: Marketing programs ($ a month) | B32: 10000 | C32: ABM ads, events, content tools
A33: Travel and events ($ a month) | B33: 3000 | C33: US sales and FDM travel
A34: Stretch lever
A35: Stretch lever: extra US AEs (count) | B35: 0 | C35: Set to 3 to model the $1M MRR case
A36: Stretch lever: start month for extra US AEs | B36: 3 | C36: 1 = Nov 2026
A37: Stretch lever: OTE per extra US AE ($) | B37: 130000 | C37: Same as the planned US AE
A38: Funnel
A39: New-logo ACV, India and RoW ($) | B39: 60000 | C39: Assumption
A40: New-logo ACV, US ($) | B40: 100000 | C40: Org design doc, Part 2
...

Sheet Hiring Plan
A1: Hiring plan: new roles, timing, owner and cost
A2: Blue = input. Start month 1 = Nov 2026. OTE = fixed + variable at 100% of target. Annual loaded cost includes employer loading.
A4: # | B4: Role | C4: Function | D4: Shift / location | E4: Currency | F4: Count | G4: OTE per head (native) | H4: Fixed % | I4: Fixed per head (native) | J4: Variable per head (native) | K4: Start month # | L4: Start month | M4: Hiring owner | N4: Senior search (1 = agency) | O4: OTE per head ($) | P4: Loading | Q4: Annual loaded cost ($) | R4: Monthly loaded cost ($) | S4: One-time hiring cost ($)
A5: 1 | B5: Recruiter | C5: People and HR | D5: Day, India | E5: INR | F5: 1 | G5: 1500000 | H5: 1 | I5: =G5*H5 -> 1500000 | J5: =G5-I5 -> 0 | K5: 1 | L5: =TEXT(DATE(2026,10+K5,1),"mmm yyyy") -> Nov 2026 | M5: Gayu (COO) | N5: 0 | O5: =IF(E5="INR",G5/Assumptions!$B$4,G5) -> 15957.447 | P5: =IF(E5="INR",Assumptions!$B$5,Assumptions!$B$6) -> 0.04 | Q5: =F5*O5*(1+P5) -> 16595.745 | R5: =Q5/12 -> 1382.9787 | S5: =F5*(Assumptions!$B$8+N5*Assumptions!$B$7*O5) -> 1200
A6: 2 | B6: Head of Account Management | C6: Account management | D6: Both shifts | E6: INR | F6: 1 | G6: 6000000 | H6: 0.7 | I6: =G6*H6 -> 4200000 | J6: =G6-I6 -> 1800000 | K6: 2 | L6: =TEXT(DATE(2026,10+K6,1),"mmm yyyy") -> Dec 2026 | M6: Gayu (COO) | N6: 1 | O6: =IF(E6="INR",G6/Assumptions!$B$4,G6) -> 63829.787 | P6: =IF(E6="INR",Assumptions!$B$5,Assumptions!$B$6) -> 0.04 | Q6: =F6*O6*(1+P6) -> 66382.979 | R6: =Q6/12 -> 5531.9149 | S6: =F6*(Assumptions!$B$8+N6*Assumptions!$B$7*O6) -> 6517.0213
A7: 3 | B7: Finance Manager | C7: Finance | D7: Day, India | E7: INR | F7: 1 | G7: 2400000 | H7: 1 | I7: =G7*H7 -> 2400000 | J7: =G7-I7 -> 0 | K7: 2 | L7: =TEXT(DATE(2026,10+K7,1),"mmm yyyy") -> Dec 2026 | M7: JK | N7: 0 | O7: =IF(E7="INR",G7/Assumptions!$B$4,G7) -> 25531.915 | P7: =IF(E7="INR",Assumptions!$B$5,Assumptions!$B$6) -> 0.04 | Q7: =F7*O7*(1+P7) -> 26553.191 | R7: =Q7/12 -> 2212.766 | S7: =F7*(Assumptions!$B$8+N7*Assumptions!$B$7*O7) -> 1200
A8: 4 | B8: Sales Leader, India and RoW | C8: Sales | D8: GMT shift, India and RoW | E8: INR | F8: 1 | G8: 7140000 | H8: 0.7 | I8: =G8*H8 -> 4998000 | J8: =G8-I8 -> 2142000 | K8: 2 | L8: =TEXT(DATE(2026,10+K8,1),"mmm yyyy") -> Dec 2026 | M8: Sudharshan | N8: 1 | O8: =IF(E8="INR",G8/Assumptions!$B$4,G8) -> 75957.447 | P8: =IF(E8="INR",Assumptions!$B$5,Assumptions!$B$6) -> 0.04 | Q8: =F8*O8*(1+P8) -> 78995.745 | R8: =Q8/12 -> 6582.9787 | S8: =F8*(Assumptions!$B$8+N8*Assumptions!$B$7*O8) -> 7527.2553
A9: 5 | B9: SDR, India and RoW | C9: Sales | D9: GMT shift, India and RoW | E9: INR | F9: 1 | G9: 1750000 | H9: 0.8 | I9: =G9*H9 -> 1400000 | J9: =G9-I9 -> 350000 | K9: 2 | L9: =TEXT(DATE(2026,10+K9,1),"mmm yyyy") -> Dec 2026 | M9: Sudharshan, then India and RoW lead | N9: 0 | O9: =IF(E9="INR",G9/Assumptions!$B$4,G9) -> 18617.021 | P9: =IF(E9="INR",Assumptions!$B$5,Assumptions!$B$6) -> 0.04 | Q9: =F9*O9*(1+P9) -> 19361.702 | R9: =Q9/12 -> 1613.4752 | S9: =F9*(Assumptions!$B$8+N9*Assumptions!$B$7*O9) -> 1200
A10: 6 | B10: SDR, US shift | C10: Sales | D10: EST shift, US and Canada | E10: INR | F10: 1 | G10: 1750000 | H10: 0.8 | I10: =G10*H10 -> 1400000 | J10: =G10-I10 -> 350000 | K10: 2 | L10: =TEXT(DATE(2026,10+K10,1),"mmm yyyy") -> Dec 2026 | M10: Sudharshan | N10: 0 | O10: =IF(E10="INR",G10/Assumptions!$B$4,G10) -> 18617.021 | P10: =IF(E10="INR",Assumptions!$B$5,Assumptions!$B$6) -> 0.04 | Q10: =F10*O10*(1+P10) -> 19361.702 | R10: =Q10/12 -> 1613.4752 | S10: =F10*(Assumptions!$B$8+N10*Assumptions!$B$7*O10) -> 1200
A11: 7 | B11: Social and founder-brand manager | C11: Growth | D11: Day, India | E11: INR | F11: 1 | G11: 1400000 | H11: 1 | I11: =G11*H11 -> 1400000 | J11: =G11-I11 -> 0 | K11: 2 | L11: =TEXT(DATE(2026,10+K11,1),"mmm yyyy") -> Dec 2026 | M11: Mahesh | N11: 0 | O11: =IF(E11="INR",G11/Assumptions!$B$4,G11) -> 14893.617 | P11: =IF(E11="INR",Assumptions!$B$5,Assumptions!$B$6) -> 0.04 | Q11: =F11*O11*(1+P11) -> 15489.362 | R11: =Q11/12 -> 1290.7801 | S11: =F11*(Assumptions!$B$8+N11*Assumptions!$B$7*O11) -> 1200
A12: 8 | B12: Director, Paid Media, India and RoW | C12: Delivery leadership | D12: GMT shift, India and RoW | E12: INR | F12: 1 | G12: 5000000 | H12: 0.8 | I12: =G12*H12 -> 4000000 | J12: =G12-I12 -> 1000000 | K12: 3 | L12: =TEXT(DATE(2026,10+K12,1),"mmm yyyy") -> Jan 2027 | M12: Sabari | N12: 1 | O12: =IF(E12="INR",G12/Assumptions!$B$4,G12) -> 53191.489 | P12: =IF(E12="INR",Assumptions!$B$5,Assumptions!$B$6) -> 0.04 | Q12: =F12*O12*(1+P12) -> 55319.149 | R12: =Q12/12 -> 4609.9291 | S12: =F12*(Assumptions!$B$8+N12*Assumptions!$B$7*O12) -> 5630.8511
A13: 9 | B13: Director, SEO and GEO, India and RoW | C13: Delivery leadership | D13: GMT shift, India and RoW | E13: INR | F13: 1 | G13: 5000000 | H13: 0.8 | I13: =G13*H13 -> 4000000 | J13: =G13-I13 -> 1000000 | K13: 3 | L13: =TEXT(DATE(2026,10+K13,1),"mmm yyyy") -> Jan 2027 | M13: Manoj | N13: 1 | O13: =IF(E13="INR",G13/Assumptions!$B$4,G13) -> 53191.489 | P13: =IF(E13="INR",Assumptions!$B$5,Assumptions!$B$6) -> 0.04 | Q13: =F13*O13*(1+P13) -> 55319.149 | R13: =Q13/12 -> 4609.9291 | S13: =F13*(Assumptions!$B$8+N13*Assumptions!$B$7*O13) -> 5630.8511
A14: 10 | B14: Account Manager, US shift | C14: Account management | D14: EST shift, US and Canada | E14: INR | F14: 1 | G14: 2400000 | H14: 0.7 | I14: =G14*H14 -> 1680000 | J14: =G14-I14 -> 720000 | K14: 3 | L14: =TEXT(DATE(2026,10+K14,1),"mmm yyyy") -> Jan 2027 | M14: Head of Account Management | N14: 0 | O14: =IF(E14="INR",G14/Assumptions!$B$4,G14) -> 25531.915 | P14: =IF(E14="INR",Assumptions!$B$5,Assumptions!$B$6) -> 0.04 | Q14: =F14*O14*(1+P14) -> 26553.191 | R14: =Q14/12 -> 2212.766 | S14: =F14*(Assumptions!$B$8+N14*Assumptions!$B$7*O14) -> 1200
A15: 11 | B15: Project Manager | C15: Project management | D15: GMT shift, India and RoW | E15: INR | F15: 1 | G15: 1600000 | H15: 1 | I15: =G15*H15 -> 1600000 | J15: =G15-I15 -> 0 | K15: 3 | L15: =TEXT(DATE(2026,10+K15,1),"mmm yyyy") -> Jan 2027 | M15: Gayu (COO) | N15: 0 | O15: =IF(E15="INR",G15/Assumptions!$B$4,G15) -> 17021.277 | P15: =IF(E15="INR",Assumptions!$B$5,Assumptions!$B$6) -> 0.04 | Q15: =F15*O15*(1+P15) -> 17702.128 | R15: =Q15/12 -> 1475.1773 | S15: =F15*(Assumptions!$B$8+N15*Assumptions!$B$7*O15) -> 1200
A16: 12 | B16: AE, India and RoW | C16: Sales | D16: GMT shift, India and RoW | E16: INR | F16: 1 | G16: 2500000 | H16: 0.7 | I16: =G16*H16 -> 1750000 | J16: =G16-I16 -> 750000 | K16: 3 | L16: =TEXT(DATE(2026,10+K16,1),"mmm yyyy") -> Jan 2027 | M16: India and RoW sales lead | N16: 0 | O16: =IF(E16="INR",G16/Assumptions!$B$4,G16) -> 26595.745 | P16: =IF(E16="INR",Assumptions!$B$5,Assumptions!$B$6) -> 0.04 | Q16: =F16*O16*(1+P16) -> 27659.574 | R16: =Q16/12 -> 2304.9645 | S16: =F16*(Assumptions!$B$8+N16*Assumptions!$B$7*O16) -> 1200
... A30: 26 | B30: Partnerships Manager | C30: Sales | D30: GMT shift, India and RoW | E30: INR | F30: 1 | G30: 2800000 | H30: 0.7 | I30: =G30*H30 -> 1960000 | J30: =G30-I30 -> 840000 | K30: 7 | L30: =TEXT(DATE(2026,10+K30,1),"mmm yyyy") -> May 2027 | M30: Sudharshan | N30: 0 | O30: =IF(E30="INR",G30/Assumptions!$B$4,G30) -> 29787.234 | P30: =IF(E30="INR",Assumptions!$B$5,Assumptions!$B$6) -> 0.04 | Q30: =F30*O30*(1+P30) -> 30978.723 | R30: =Q30/12 -> 2581.5603 | S30: =F30*(Assumptions!$B$8+N30*Assumptions!$B$7*O30) -> 1200
A31: 27 | B31: AE, US (stretch lever) | C31: Sales | D31: US-based | E31: USD | F31: =Assumptions!B35 -> 0 | G31: =Assumptions!B37 -> 130000 | H31: 0.5 | I31: =G31*H31 -> 65000 | J31: =G31-I31 -> 65000 | K31: =Assumptions!B36 -> 3 | L31: =TEXT(DATE(2026,10+K31,1),"mmm yyyy") -> Jan 2027 | M31: Sudharshan | N31: 1 | O31: =IF(E31="INR",G31/Assumptions!$B$4,G31) -> 130000 | P31: =IF(E31="INR",Assumptions!$B$5,Assumptions!$B$6) -> 0.12 | Q31: =F31*O31*(1+P31) -> 0 | R31: =Q31/12 -> 0 | S31: =F31*(Assumptions!$B$8+N31*Assumptions!$B$7*O31) -> 0
B32: Total | F32: =SUM(F5:F31) -> 26 | Q32: =SUM(Q5:Q31) -> 1162961.7 | R32: =SUM(R5:R31) -> 96913.475 | S32: =SUM(S5:S31) -> 95739.777
B33: Total excluding stretch lever | F33: =SUM(F5:F30) -> 26 | Q33: =SUM(Q5:Q30) -> 1162961.7 | R33: =SUM(R5:R30) -> 96913.475 | S33: =SUM(S5:S30) -> 95739.777
B35: Backfill, not in this plan: People Manager (Hitali leaves 30 Oct) is a replacement, not a new cost.
B36: Salary bands from the user: India and RoW directors Rs40L + Rs10L; US-shift directors $60-70K + $10-15K (midpoint used); India sales lead Rs50L fixed at 70/30; India AEs Rs25L OTE at 70/30; US AE $60-70K fixed at 50/50; SDRs Rs15-20L at 80/20. Other bands are assumptions.

Sheet Monthly Model
A1: Monthly model: investment against return, Nov 2026 to Apr 2028
A2: All values are formulas from Assumptions and Hiring Plan. Baseline = no new hires; investment case = the hiring plan.
A3: Month # | B3: Open | C3: 1 | D3: 2 | E3: 3 | F3: 4 | G3: 5 | H3: 6 | I3: 7 | J3: 8 | K3: 9 | L3: 10 | M3: 11 | N3: 12 | O3: 13 | P3: 14 | Q3: 15 | R3: 16 | S3: 17 | T3: 18
A4: Month | C4: =TEXT(DATE(2026,10+C3,1),"mmm yy") -> Nov 26 | D4: =TEXT(DATE(2026,10+D3,1),"mmm yy") -> Dec 26 | E4: =TEXT(DATE(2026,10+E3,1),"mmm yy") -> Jan 27 | F4: =TEXT(DATE(2026,10+F3,1),"mmm yy") -> Feb 27 | G4: =TEXT(DATE(2026,10+G3,1),"mmm yy") -> Mar 27 | H4: =TEXT(DATE(2026,10+H3,1),"mmm yy") -> Apr 27 | I4: =TEXT(DATE(2026,10+I3,1),"mmm yy") -> May 27 | J4: =TEXT(DATE(2026,10+J3,1),"mmm yy") -> Jun 27 | ... T4: =TEXT(DATE(2026,10+T3,1),"mmm yy") -> Apr 28
A5: Investment
A6: People cost of new roles ($) | C6: =SUMPRODUCT(('Hiring Plan'!$K$5:$K$31<=C$3)*'Hiring Plan'!$R$5:$R$31) -> 1382.9787 | D6: =SUMPRODUCT(('Hiring Plan'!$K$5:$K$31<=D$3)*'Hiring Plan'!$R$5:$R$31) -> 20228.369 | E6: =SUMPRODUCT(('Hiring Plan'!$K$5:$K$31<=E$3)*'Hiring Plan'!$R$5:$R$31) -> 55226.95 | F6: =SUMPRODUCT(('Hiring Plan'!$K$5:$K$31<=F$3)*'Hiring Plan'!$R$5:$R$31) -> 73842.553 | G6: =SUMPRODUCT(('Hiring Plan'!$K$5:$K$31<=G$3)*'Hiring Plan'!$R$5:$R$31) -> 89260.993 | H6: =SUMPRODUCT(('Hiring Plan'!$K$5:$K$31<=H$3)*'Hiring Plan'!$R$5:$R$31) -> 94331.915 | I6: =SUMPRODUCT(('Hiring Plan'!$K$5:$K$31<=I$3)*'Hiring Plan'!$R$5:$R$31) -> 96913.475 | J6: =SUMPRODUCT(('Hiring Plan'!$K$5:$K$31<=J$3)*'Hiring Plan'!$R$5:$R$31) -> 96913.475 | ... T6: =SUMPRODUCT(('Hiring Plan'!$K$5:$K$31<=T$3)*'Hiring Plan'!$R$5:$R$31) -> 96913.475
A7: One-time hiring cost ($) | C7: =SUMPRODUCT(('Hiring Plan'!$K$5:$K$31=C$3)*'Hiring Plan'!$S$5:$S$31) -> 1200 | D7: =SUMPRODUCT(('Hiring Plan'!$K$5:$K$31=D$3)*'Hiring Plan'!$S$5:$S$31) -> 18844.277 | E7: =SUMPRODUCT(('Hiring Plan'!$K$5:$K$31=E$3)*'Hiring Plan'!$S$5:$S$31) -> 34349.213 | F7: =SUMPRODUCT(('Hiring Plan'!$K$5:$K$31=F$3)*'Hiring Plan'!$S$5:$S$31) -> 17711.5 | G7: =SUMPRODUCT(('Hiring Plan'!$K$5:$K$31=G$3)*'Hiring Plan'!$S$5:$S$31) -> 16360.851 | H7: =SUMPRODUCT(('Hiring Plan'!$K$5:$K$31=H$3)*'Hiring Plan'!$S$5:$S$31) -> 6073.9362 | I7: =SUMPRODUCT(('Hiring Plan'!$K$5:$K$31=I$3)*'Hiring Plan'!$S$5:$S$31) -> 1200 | J7: =SUMPRODUCT(('Hiring Plan'!$K$5:$K$31=J$3)*'Hiring Plan'!$S$5:$S$31) -> 0 | ... T7: =SUMPRODUCT(('Hiring Plan'!$K$5:$K$31=T$3)*'Hiring Plan'!$S$5:$S$31) -> 0
A8: Programs: tools, marketing, travel ($) | C8: =IF(C$3>=2,Assumptions!$B$31,0)+IF(C$3>=3,Assumptions!$B$32,0)+IF(C$3>=4,Assumptions!$B$33,0) -> 0 | D8: =IF(D$3>=2,Assumptions!$B$31,0)+IF(D$3>=3,Assumptions!$B$32,0)+IF(D$3>=4,Assumptions!$B$33,0) -> 2500 | E8: =IF(E$3>=2,Assumptions!$B$31,0)+IF(E$3>=3,Assumptions!$B$32,0)+IF(E$3>=4,Assumptions!$B$33,0) -> 12500 | F8: =IF(F$3>=2,Assumptions!$B$31,0)+IF(F$3>=3,Assumptions!$B$32,0)+IF(F$3>=4,Assumptions!$B$33,0) -> 15500 | G8: =IF(G$3>=2,Assumptions!$B$31,0)+IF(G$3>=3,Assumptions!$B$32,0)+IF(G$3>=4,Assumptions!$B$33,0) -> 15500 | H8: =IF(H$3>=2,Assumptions!$B$31,0)+IF(H$3>=3,Assumptions!$B$32,0)+IF(H$3>=4,Assumptions!$B$33,0) -> 15500 | I8: =IF(I$3>=2,Assumptions!$B$31,0)+IF(I$3>=3,Assumptions!$B$32,0)+IF(I$3>=4,Assumptions!$B$33,0) -> 15500 | J8: =IF(J$3>=2,Assumptions!$B$31,0)+IF(J$3>=3,Assumptions!$B$32,0)+IF(J$3>=4,Assumptions!$B$33,0) -> 15500 | ... T8: =IF(T$3>=2,Assumptions!$B$31,0)+IF(T$3>=3,Assumptions!$B$32,0)+IF(T$3>=4,Assumptions!$B$33,0) -> 15500
A9: Total investment ($) | C9: =SUM(C6:C8) -> 2582.9787 | D9: =SUM(D6:D8) -> 41572.645 | E9: =SUM(E6:E8) -> 102076.16 | F9: =SUM(F6:F8) -> 107054.05 | G9: =SUM(G6:G8) -> 121121.84 | H9: =SUM(H6:H8) -> 115905.85 | I9: =SUM(I6:I8) -> 113613.48 | J9: =SUM(J6:J8) -> 112413.48 | ... T9: =SUM(T6:T8) -> 112413.48
A10: Cumulative investment ($) | B10: 0 | C10: =B10+C9 -> 2582.9787 | D10: =C10+D9 -> 44155.624 | E10: =D10+E9 -> 146231.79 | F10: =E10+F9 -> 253285.84 | G10: =F10+G9 -> 374407.68 | H10: =G10+H9 -> 490313.54 | I10: =H10+I9 -> 603927.01 | J10: =I10+J9 -> 716340.49 | ... T10: =S10+T9 -> 1840475.2
A11: Revenue
A12: Baseline MRR, no new hires ($) | B12: =Assumptions!B10 -> 450000 | C12: =B12*(1-Assumptions!$B$12)+Assumptions!$B$11 -> 455500 | D12: =C12*(1-Assumptions!$B$12)+Assumptions!$B$11 -> 460835 | E12: =D12*(1-Assumptions!$B$12)+Assumptions!$B$11 -> 466009.95 | F12: =E12*(1-Assumptions!$B$12)+Assumptions!$B$11 -> 471029.65 | G12: =F12*(1-Assumptions!$B$12)+Assumptions!$B$11 -> 475898.76 | H12: =G12*(1-Assumptions!$B$12)+Assumptions!$B$11 -> 480621.8 | I12: =H12*(1-Assumptions!$B$12)+Assumptions!$B$11 -> 485203.15 | J12: =I12*(1-Assumptions!$B$12)+Assumptions!$B$11 -> 489647.05 | ... T12: =S12*(1-Assumptions!$B$12)+Assumptions!$B$11 -> 527375.6
A14: New MRR: India and RoW sales team ($) | C14: =Assumptions!$B$15/144*(IF(C$3-'Hiring Plan'!$K$8<Assumptions!$B$19,0,MIN(1,Assumptions!$B$22*(C$3-'Hiring Plan'!$K$8-Assumptions!$B$19+1)))+IF(C$3-'Hiring Plan'!$K$16<Assumptions!$B$19,0,MIN(1,Assumptions!$B$22*(C$3-'Hiring Plan'!$K$16-Assumptions!$B$19+1)))+IF(C$3-'Hiring Plan'!$K$24<Assumptions!$B$19,0,MIN(1,Assumptions!$B$22*(C$3-'Hiring Plan'!$K$24-Assumptions!$B$19+1)))) -> 0 | D14: =Assumptions!$B$15/144*(IF(D$3-'Hiring Plan'!$K$8<Assumptions!$B$19,0,MIN(1,Assumptions!$B$22*(D$3-'Hiring Plan'!$K$8-Assumptions!$B$19+1)))+IF(D$3-'Hiring Plan'!$K$16<Assumptions!$B$19,0,MIN(1,Assumptions!$B$22*(D$3-'Hiring Plan'!$K$16-Assumptions!$B$19+1)))+IF(D$3-'Hiring Plan'!$K$24<Assumptions!$B$19,0,MIN(1,Assumptions!$B$22*(D$3-'Hiring Plan'!$K$24-Assumptions!$B$19+1)))) -> 0 | E14: =Assumptions!$B$15/144*(IF(E$3-'Hiring Plan'!$K$8<Assumptions!$B$19,0,MIN(1,Assumptions!$B$22*(E$3-'Hiring Plan'!$K$8-Assumptions!$B$19+1)))+IF(E$3-'Hiring Plan'!$K$16<Assumptions!$B$19,0,MIN(1,Assumptions!$B$22*(E$3-'Hiring Plan'!$K$16-Assumptions!$B$19+1)))+IF(E$3-'Hiring Plan'!$K$24<Assumptions!$B$19,0,MIN(1,Assumptions!$B$22*(E$3-'Hiring Plan'!$K$24-Assumptions!$B$19+1)))) -> 0 | F14: =Assumptions!$B$15/144*(IF(F$3-'Hiring Plan'!$K$8<Assumptions!$B$19,0,MIN(1,Assumptions!$B$22*(F$3-'Hiring Plan'!$K$8-Assumptions!$B$19+1)))+IF(F$3-'Hiring Plan'!$K$16<Assumptions!$B$19,0,MIN(1,Assumptions!$B$22*(F$3-'Hiring Plan'!$K$16-Assumptions!$B$19+1)))+IF(F$3-'Hiring Plan'!$K$24<Assumptions!$B$19,0,MIN(1,Assumptions!$B$22*(F$3-'Hiring Plan'!$K$24-Assumptions!$B$19+1)))) -> 2083.3333 | G14: =Assumptions!$B$15/144*(IF(G$3-'Hiring Plan'!$K$8<Assumptions!$B$19,0,MIN(1,Assumptions!$B$22*(G$3-'Hiring Plan'!$K$8-Assumptions!$B$19+1)))+IF(G$3-'Hiring Plan'!$K$16<Assumptions!$B$19,0,MIN(1,Assumptions!$B$22*(G$3-'Hiring Plan'!$K$16-Assumptions!$B$19+1)))+IF(G$3-'Hiring Plan'!$K$24<Assumptions!$B$19,0,MIN(1,Assumptions!$B$22*(G$3-'Hiring Plan'!$K$24-Assumptions!$B$19+1)))) -> 6250 | H14: =Assumptions!$B$15/144*(IF(H$3-'Hiring Plan'!$K$8<Assumptions!$B$19,0,MIN(1,Assumptions!$B$22*(H$3-'Hiring Plan'!$K$8-Assumptions!$B$19+1)))+IF(H$3-'Hiring Plan'!$K$16<Assumptions!$B$19,0,MIN(1,Assumptions!$B$22*(H$3-'Hiring Plan'!$K$16-Assumptions!$B$19+1)))+IF(H$3-'Hiring Plan'!$K$24<Assumptions!$B$19,0,MIN(1,Assumptions!$B$22*(H$3-'Hiring Plan'!$K$24-Assumptions!$B$19+1)))) -> 12500 | I14: =Assumptions!$B$15/144*(IF(I$3-'Hiring Plan'!$K$8<Assumptions!$B$19,0,MIN(1,Assumptions!$B$22*(I$3-'Hiring Plan'!$K$8-Assumptions!$B$19+1)))+IF(I$3-'Hiring Plan'!$K$16<Assumptions!$B$19,0,MIN(1,Assumptions!$B$22*(I$3-'Hiring Plan'!$K$16-Assumptions!$B$19+1)))+IF(I$3-'Hiring Plan'!$K$24<Assumptions!$B$19,0,MIN(1,Assumptions!$B$22*(I$3-'Hiring Plan'!$K$24-Assumptions!$B$19+1)))) -> 18750 | J14: =Assumptions!$B$15/144*(IF(J$3-'Hiring Plan'!$K$8<Assumptions!$B$19,0,MIN(1,Assumptions!$B$22*(J$3-'Hiring Plan'!$K$8-Assumptions!$B$19+1)))+IF(J$3-'Hiring Plan'!$K$16<Assumptions!$B$19,0,MIN(1,Assumptions!$B$22*(J$3-'Hiring Plan'!$K$16-Assumptions!$B$19+1)))+IF(J$3-'Hiring Plan'!$K$24<Assumptions!$B$19,0,MIN(1,Assumptions!$B$22*(J$3-'Hiring Plan'!$K$24-Assumptions!$B$19+1)))) -> 22916.667 | ... T14: =Assumptions!$B$15/144*(IF(T$3-'Hiring Plan'!$K$8<Assumptions!$B$19,0,MIN(1,Assumptions!$B$22*(T$3-'Hiring Plan'!$K$8-Assumptions!$B$19+1)))+IF(T$3-'Hiring Plan'!$K$16<Assumptions!$B$19,0,MIN(1,Assumptions!$B$22*(T$3-'Hiring Plan'!$K$16-Assumptions!$B$19+1)))+IF(T$3-'Hiring Plan'!$K$24<Assumptions!$B$19,0,MIN(1,Assumptions!$B$22*(T$3-'Hiring Plan'!$K$24-Assumptions!$B$19+1)))) -> 25000
A15: New MRR: US AEs ($) | C15: =Assumptions!$B$16/144*(IF(C$3-'Hiring Plan'!$K$17<Assumptions!$B$20,0,MIN(1,Assumptions!$B$22*(C$3-'Hiring Plan'!$K$17-Assumptions!$B$20+1)))+Assumptions!$B$35*IF(C$3-Assumptions!$B$36<Assumptions!$B$20,0,MIN(1,Assumptions!$B$22*(C$3-Assumptions!$B$36-Assumptions!$B$20+1)))) -> 0 | D15: =Assumptions!$B$16/144*(IF(D$3-'Hiring Plan'!$K$17<Assumptions!$B$20,0,MIN(1,Assumptions!$B$22*(D$3-'Hiring Plan'!$K$17-Assumptions!$B$20+1)))+Assumptions!$B$35*IF(D$3-Assumptions!$B$36<Assumptions!$B$20,0,MIN(1,Assumptions!$B$22*(D$3-Assumptions!$B$36-Assumptions!$B$20+1)))) -> 0 | E15: =Assumptions!$B$16/144*(IF(E$3-'Hiring Plan'!$K$17<Assumptions!$B$20,0,MIN(1,Assumptions!$B$22*(E$3-'Hiring Plan'!$K$17-Assumptions!$B$20+1)))+Assumptions!$B$35*IF(E$3-Assumptions!$B$36<Assumptions!$B$20,0,MIN(1,Assumptions!$B$22*(E$3-Assumptions!$B$36-Assumptions!$B$20+1)))) -> 0 | F15: =Assumptions!$B$16/144*(IF(F$3-'Hiring Plan'!$K$17<Assumptions!$B$20,0,MIN(1,Assumptions!$B$22*(F$3-'Hiring Plan'!$K$17-Assumptions!$B$20+1)))+Assumptions!$B$35*IF(F$3-Assumptions!$B$36<Assumptions!$B$20,0,MIN(1,Assumptions!$B$22*(F$3-Assumptions!$B$36-Assumptions!$B$20+1)))) -> 0 | G15: =Assumptions!$B$16/144*(IF(G$3-'Hiring Plan'!$K$17<Assumptions!$B$20,0,MIN(1,Assumptions!$B$22*(G$3-'Hiring Plan'!$K$17-Assumptions!$B$20+1)))+Assumptions!$B$35*IF(G$3-Assumptions!$B$36<Assumptions!$B$20,0,MIN(1,Assumptions!$B$22*(G$3-Assumptions!$B$36-Assumptions!$B$20+1)))) -> 0 | H15: =Assumptions!$B$16/144*(IF(H$3-'Hiring Plan'!$K$17<Assumptions!$B$20,0,MIN(1,Assumptions!$B$22*(H$3-'Hiring Plan'!$K$17-Assumptions!$B$20+1)))+Assumptions!$B$35*IF(H$3-Assumptions!$B$36<Assumptions!$B$20,0,MIN(1,Assumptions!$B$22*(H$3-Assumptions!$B$36-Assumptions!$B$20+1)))) -> 2083.3333 | I15: =Assumptions!$B$16/144*(IF(I$3-'Hiring Plan'!$K$17<Assumptions!$B$20,0,MIN(1,Assumptions!$B$22*(I$3-'Hiring Plan'!$K$17-Assumptions!$B$20+1)))+Assumptions!$B$35*IF(I$3-Assumptions!$B$36<Assumptions!$B$20,0,MIN(1,Assumptions!$B$22*(I$3-Assumptions!$B$36-Assumptions!$B$20+1)))) -> 4166.6667 | J15: =Assumptions!$B$16/144*(IF(J$3-'Hiring Plan'!$K$17<Assumptions!$B$20,0,MIN(1,Assumptions!$B$22*(J$3-'Hiring Plan'!$K$17-Assumptions!$B$20+1)))+Assumptions!$B$35*IF(J$3-Assumptions!$B$36<Assumptions!$B$20,0,MIN(1,Assumptions!$B$22*(J$3-Assumptions!$B$36-Assumptions!$B$20+1)))) -> 6250 | ... T15: =Assumptions!$B$16/144*(IF(T$3-'Hiring Plan'!$K$17<Assumptions!$B$20,0,MIN(1,Assumptions!$B$22*(T$3-'Hiring Plan'!$K$17-Assumptions!$B$20+1)))+Assumptions!$B$35*IF(T$3-Assumptions!$B$36<Assumptions!$B$20,0,MIN(1,Assumptions!$B$22*(T$3-Assumptions!$B$36-Assumptions!$B$20+1)))) -> 8333.3333
A16: New MRR: Sudharshan's added US bookings ($) | C16: =Assumptions!$B$17/144*IF(C$3-'Hiring Plan'!$K$10<Assumptions!$B$19,0,MIN(1,Assumptions!$B$22*(C$3-'Hiring Plan'!$K$10-Assumptions!$B$19+1))) -> 0 | D16: =Assumptions!$B$17/144*IF(D$3-'Hiring Plan'!$K$10<Assumptions!$B$19,0,MIN(1,Assumptions!$B$22*(D$3-'Hiring Plan'!$K$10-Assumptions!$B$19+1))) -> 0 | E16: =Assumptions!$B$17/144*IF(E$3-'Hiring Plan'!$K$10<Assumptions!$B$19,0,MIN(1,Assumptions!$B$22*(E$3-'Hiring Plan'!$K$10-Assumptions!$B$19+1))) -> 0 | F16: =Assumptions!$B$17/144*IF(F$3-'Hiring Plan'!$K$10<Assumptions!$B$19,0,MIN(1,Assumptions!$B$22*(F$3-'Hiring Plan'!$K$10-Assumptions!$B$19+1))) -> 1041.6667 | G16: =Assumptions!$B$17/144*IF(G$3-'Hiring Plan'!$K$10<Assumptions!$B$19,0,MIN(1,Assumptions!$B$22*(G$3-'Hiring Plan'!$K$10-Assumptions!$B$19+1))) -> 2083.3333 | H16: =Assumptions!$B$17/144*IF(H$3-'Hiring Plan'!$K$10<Assumptions!$B$19,0,MIN(1,Assumptions!$B$22*(H$3-'Hiring Plan'!$K$10-Assumptions!$B$19+1))) -> 3125 | I16: =Assumptions!$B$17/144*IF(I$3-'Hiring Plan'!$K$10<Assumptions!$B$19,0,MIN(1,Assumptions!$B$22*(I$3-'Hiring Plan'!$K$10-Assumptions!$B$19+1))) -> 4166.6667 | J16: =Assumptions!$B$17/144*IF(J$3-'Hiring Plan'!$K$10<Assumptions!$B$19,0,MIN(1,Assumptions!$B$22*(J$3-'Hiring Plan'!$K$10-Assumptions!$B$19+1))) -> 4166.6667 | ... T16: =Assumptions!$B$17/144*IF(T$3-'Hiring Plan'!$K$10<Assumptions!$B$19,0,MIN(1,Assumptions!$B$22*(T$3-'Hiring Plan'!$K$10-Assumptions!$B$19+1))) -> 4166.6667
A17: New MRR: partnerships ($) | C17: =Assumptions!$B$18/144*IF(C$3-'Hiring Plan'!$K$30<Assumptions!$B$21,0,MIN(1,Assumptions!$B$22*(C$3-'Hiring Plan'!$K$30-Assumptions!$B$21+1))) -> 0 | D17: =Assumptions!$B$18/144*IF(D$3-'Hiring Plan'!$K$30<Assumptions!$B$21,0,MIN(1,Assumptions!$B$22*(D$3-'Hiring Plan'!$K$30-Assumptions!$B$21+1))) -> 0 | E17: =Assumptions!$B$18/144*IF(E$3-'Hiring Plan'!$K$30<Assumptions!$B$21,0,MIN(1,Assumptions!$B$22*(E$3-'Hiring Plan'!$K$30-Assumptions!$B$21+1))) -> 0 | F17: =Assumptions!$B$18/144*IF(F$3-'Hiring Plan'!$K$30<Assumptions!$B$21,0,MIN(1,Assumptions!$B$22*(F$3-'Hiring Plan'!$K$30-Assumptions!$B$21+1))) -> 0 | G17: =Assumptions!$B$18/144*IF(G$3-'Hiring Plan'!$K$30<Assumptions!$B$21,0,MIN(1,Assumptions!$B$22*(G$3-'Hiring Plan'!$K$30-Assumptions!$B$21+1))) -> 0 | H17: =Assumptions!$B$18/144*IF(H$3-'Hiring Plan'!$K$30<Assumptions!$B$21,0,MIN(1,Assumptions!$B$22*(H$3-'Hiring Plan'!$K$30-Assumptions!$B$21+1))) -> 0 | I17: =Assumptions!$B$18/144*IF(I$3-'Hiring Plan'!$K$30<Assumptions!$B$21,0,MIN(1,Assumptions!$B$22*(I$3-'Hiring Plan'!$K$30-Assumptions!$B$21+1))) -> 0 | J17: =Assumptions!$B$18/144*IF(J$3-'Hiring Plan'!$K$30<Assumptions!$B$21,0,MIN(1,Assumptions!$B$22*(J$3-'Hiring Plan'!$K$30-Assumptions!$B$21+1))) -> 0 | ... T17: =Assumptions!$B$18/144*IF(T$3-'Hiring Plan'!$K$30<Assumptions!$B$21,0,MIN(1,Assumptions!$B$22*(T$3-'Hiring Plan'!$K$30-Assumptions!$B$21+1))) -> 3472.2222
A18: Expansion MRR: account management ($) | C18: =Assumptions!$B$24*IF(C$3-'Hiring Plan'!$K$6<Assumptions!$B$26,0,IF(C$3-'Hiring Plan'!$K$6=Assumptions!$B$26,0.5,1)) -> 0 | D18: =Assumptions!$B$24*IF(D$3-'Hiring Plan'!$K$6<Assumptions!$B$26,0,IF(D$3-'Hiring Plan'!$K$6=Assumptions!$B$26,0.5,1)) -> 0 | E18: =Assumptions!$B$24*IF(E$3-'Hiring Plan'!$K$6<Assumptions!$B$26,0,IF(E$3-'Hiring Plan'!$K$6=Assumptions!$B$26,0.5,1)) -> 0 | F18: =Assumptions!$B$24*IF(F$3-'Hiring Plan'!$K$6<Assumptions!$B$26,0,IF(F$3-'Hiring Plan'!$K$6=Assumptions!$B$26,0.5,1)) -> 2500 | G18: =Assumptions!$B$24*IF(G$3-'Hiring Plan'!$K$6<Assumptions!$B$26,0,IF(G$3-'Hiring Plan'!$K$6=Assumptions!$B$26,0.5,1)) -> 5000 | H18: =Assumptions!$B$24*IF(H$3-'Hiring Plan'!$K$6<Assumptions!$B$26,0,IF(H$3-'Hiring Plan'!$K$6=Assumptions!$B$26,0.5,1)) -> 5000 | I18: =Assumptions!$B$24*IF(I$3-'Hiring Plan'!$K$6<Assumptions!$B$26,0,IF(I$3-'Hiring Plan'!$K$6=Assumptions!$B$26,0.5,1)) -> 5000 | J18: =Assumptions!$B$24*IF(J$3-'Hiring Plan'!$K$6<Assumptions!$B$26,0,IF(J$3-'Hiring Plan'!$K$6=Assumptions!$B$26,0.5,1)) -> 5000 | ... T18: =Assumptions!$B$24*IF(T$3-'Hiring Plan'!$K$6<Assumptions!$B$26,0,IF(T$3-'Hiring Plan'!$K$6=Assumptions!$B$26,0.5,1)) -> 5000
A19: Expansion MRR: FDMs ($) | C19: =Assumptions!$B$25*(IF(C$3-'Hiring Plan'!$K$28<Assumptions!$B$26,0,IF(C$3-'Hiring Plan'!$K$28=Assumptions!$B$26,0.5,1))+IF(C$3-'Hiring Plan'!$K$29<Assumptions!$B$26,0,IF(C$3-'Hiring Plan'!$K$29=Assumptions!$B$26,0.5,1))) -> 0 | D19: =Assumptions!$B$25*(IF(D$3-'Hiring Plan'!$K$28<Assumptions!$B$26,0,IF(D$3-'Hiring Plan'!$K$28=Assumptions!$B$26,0.5,1))+IF(D$3-'Hiring Plan'!$K$29<Assumptions!$B$26,0,IF(D$3-'Hiring Plan'!$K$29=Assumptions!$B$26,0.5,1))) -> 0 | E19: =Assumptions!$B$25*(IF(E$3-'Hiring Plan'!$K$28<Assumptions!$B$26,0,IF(E$3-'Hiring Plan'!$K$28=Assumptions!$B$26,0.5,1))+IF(E$3-'Hiring Plan'!$K$29<Assumptions!$B$26,0,IF(E$3-'Hiring Plan'!$K$29=Assumptions!$B$26,0.5,1))) -> 0 | F19: =Assumptions!$B$25*(IF(F$3-'Hiring Plan'!$K$28<Assumptions!$B$26,0,IF(F$3-'Hiring Plan'!$K$28=Assumptions!$B$26,0.5,1))+IF(F$3-'Hiring Plan'!$K$29<Assumptions!$B$26,0,IF(F$3-'Hiring Plan'!$K$29=Assumptions!$B$26,0.5,1))) -> 0 | G19: =Assumptions!$B$25*(IF(G$3-'Hiring Plan'!$K$28<Assumptions!$B$26,0,IF(G$3-'Hiring Plan'!$K$28=Assumptions!$B$26,0.5,1))+IF(G$3-'Hiring Plan'!$K$29<Assumptions!$B$26,0,IF(G$3-'Hiring Plan'!$K$29=Assumptions!$B$26,0.5,1))) -> 0 | H19: =Assumptions!$B$25*(IF(H$3-'Hiring Plan'!$K$28<Assumptions!$B$26,0,IF(H$3-'Hiring Plan'!$K$28=Assumptions!$B$26,0.5,1))+IF(H$3-'Hiring Plan'!$K$29<Assumptions!$B$26,0,IF(H$3-'Hiring Plan'!$K$29=Assumptions!$B$26,0.5,1))) -> 0 | I19: =Assumptions!$B$25*(IF(I$3-'Hiring Plan'!$K$28<Assumptions!$B$26,0,IF(I$3-'Hiring Plan'!$K$28=Assumptions!$B$26,0.5,1))+IF(I$3-'Hiring Plan'!$K$29<Assumptions!$B$26,0,IF(I$3-'Hiring Plan'!$K$29=Assumptions!$B$26,0.5,1))) -> 2000 | J19: =Assumptions!$B$25*(IF(J$3-'Hiring Plan'!$K$28<Assumptions!$B$26,0,IF(J$3-'Hiring Plan'!$K$28=Assumptions!$B$26,0.5,1))+IF(J$3-'Hiring Plan'!$K$29<Assumptions!$B$26,0,IF(J$3-'Hiring Plan'!$K$29=Assumptions!$B$26,0.5,1))) -> 6000 | ... T19: =Assumptions!$B$25*(IF(T$3-'Hiring Plan'!$K$28<Assumptions!$B$26,0,IF(T$3-'Hiring Plan'!$K$28=Assumptions!$B$26,0.5,1))+IF(T$3-'Hiring Plan'!$K$29<Assumptions!$B$26,0,IF(T$3-'Hiring Plan'!$K$29=Assumptions!$B$26,0.5,1))) -> 8000
A20: New MRR: today's engine ($) | C20: =Assumptions!$B$11 -> 19000 | D20: =Assumptions!$B$11 -> 19000 | E20: =Assumptions!$B$11 -> 19000 | F20: =Assumptions!$B$11 -> 19000 | G20: =Assumptions!$B$11 -> 19000 | H20: =Assumptions!$B$11 -> 19000 | I20: =Assumptions!$B$11 -> 19000 | J20: =Assumptions!$B$11 -> 19000 | ... T20: =Assumptions!$B$11 -> 19000
A21: Monthly gross churn, investment case | C21: =MAX(Assumptions!$B$28,Assumptions!$B$12-Assumptions!$B$29*MAX(0,C$3-2)) -> 0.03 | D21: =MAX(Assumptions!$B$28,Assumptions!$B$12-Assumptions!$B$29*MAX(0,D$3-2)) -> 0.03 | E21: =MAX(Assumptions!$B$28,Assumptions!$B$12-Assumptions!$B$29*MAX(0,E$3-2)) -> 0.028 | F21: =MAX(Assumptions!$B$28,Assumptions!$B$12-Assumptions!$B$29*MAX(0,F$3-2)) -> 0.026 | G21: =MAX(Assumptions!$B$28,Assumptions!$B$12-Assumptions!$B$29*MAX(0,G$3-2)) -> 0.024 | H21: =MAX(Assumptions!$B$28,Assumptions!$B$12-Assumptions!$B$29*MAX(0,H$3-2)) -> 0.022 | I21: =MAX(Assumptions!$B$28,Assumptions!$B$12-Assumptions!$B$29*MAX(0,I$3-2)) -> 0.02 | J21: =MAX(Assumptions!$B$28,Assumptions!$B$12-Assumptions!$B$29*MAX(0,J$3-2)) -> 0.02 | ... T21: =MAX(Assumptions!$B$28,Assumptions!$B$12-Assumptions!$B$29*MAX(0,T$3-2)) -> 0.02
A22: Investment-case MRR ($) | B22: =Assumptions!B10 -> 450000 | C22: =B22*(1-C21)+SUM(C14:C20) -> 455500 | D22: =C22*(1-D21)+SUM(D14:D20) -> 460835 | E22: =D22*(1-E21)+SUM(E14:E20) -> 466931.62 | F22: =E22*(1-F21)+SUM(F14:F20) -> 479416.4 | G22: =F22*(1-G21)+SUM(G14:G20) -> 500243.74 | H22: =G22*(1-H21)+SUM(H14:H20) -> 530946.71 | I22: =H22*(1-I21)+SUM(I14:I20) -> 573411.11 | J22: =I22*(1-J21)+SUM(J14:J20) -> 625276.22 | ... T22: =S22*(1-T21)+SUM(T14:T20) -> 1170939.8
A23: Incremental MRR vs baseline ($) | C23: =C22-C12 -> 0 | D23: =D22-D12 -> 0 | E23: =E22-E12 -> 921.67 | F23: =F22-F12 -> 8386.7464 | G23: =G22-G12 -> 24344.976 | H23: =H22-H12 -> 50324.91 | I23: =I22-I12 -> 88207.963 | J23: =J22-J12 -> 135629.17 | ... T23: =T22-T12 -> 643564.17
A24: Incremental gross profit ($) | C24: =C23*Assumptions!$B$13 -> 0 | D24: =D23*Assumptions!$B$13 -> 0 | E24: =E23*Assumptions!$B$13 -> 553.002 | F24: =F23*Assumptions!$B$13 -> 5032.0478 | G24: =G23*Assumptions!$B$13 -> 14606.985 | H24: =H23*Assumptions!$B$13 -> 30194.946 | I24: =I23*Assumptions!$B$13 -> 52924.778 | J24: =J23*Assumptions!$B$13 -> 81377.501 | ... T24: =T23*Assumptions!$B$13 -> 386138.5
A25: Cumulative incremental gross profit ($) | B25: 0 | C25: =B25+C24 -> 0 | D25: =C25+D24 -> 0 | E25: =D25+E24 -> 553.002 | F25: =E25+F24 -> 5585.0498 | G25: =F25+G24 -> 20192.035 | H25: =G25+H24 -> 50386.981 | I25: =H25+I24 -> 103311.76 | J25: =I25+J24 -> 184689.26 | ... T25: =S25+T24 -> 2705364.6
A26: Net position: cumulative gross profit less investment ($) | C26: =C25-C10 -> -2582.9787 | D26: =D25-D10 -> -44155.624 | E26: =E25-E10 -> -145678.79 | F26: =F25-F10 -> -247700.79 | G26: =G25-G10 -> -354215.65 | H26: =H25-H10 -> -439926.55 | I26: =I25-I10 -> -500615.25 | J26: =J25-J10 -> -531651.23 | ... T26: =T25-T10 -> 864889.35
A27: Investment-case ARR ($) | C27: =C22*12 -> 5466000 | D27: =D22*12 -> 5530020 | E27: =E22*12 -> 5603179.4 | F27: =F22*12 -> 5752996.8 | G27: =G22*12 -> 6002924.9 | H27: =H22*12 -> 6371360.5 | I27: =I22*12 -> 6880933.3 | J27: =J22*12 -> 7503314.6 | ... T27: =T22*12 -> 14051277
A28: Payback month flag | C28: =IF(C26>=0,C$3,"") | D28: =IF(D26>=0,D$3,"") | E28: =IF(E26>=0,E$3,"") | F28: =IF(F26>=0,F$3,"") | G28: =IF(G26>=0,G$3,"") | H28: =IF(H26>=0,H$3,"") | I28: =IF(I26>=0,I$3,"") | J28: =IF(J26>=0,J$3,"") | ... T28: =IF(T26>=0,T$3,"") -> 18

Sheet P&L
A1: Monthly P&L at fully loaded cost
A2: Today = Sep 2026 cost base at $450K MRR. Direct delivery cost on revenue above today scales at (1 - gross margin).
A4: $ a month | B4: Today | C4: New structure fully loaded, today's revenue | D4: Month 12, investment case | E4: At target MRR
A5: Revenue (MRR) | B5: =Assumptions!B10 -> 450000 | C5: =Assumptions!B10 -> 450000 | D5: ='Monthly Model'!N22 -> 851644.76 | E5: =Assumptions!B47 -> 1000000
A6: Direct delivery cost | B6: =Assumptions!$B$45+(1-Assumptions!$B$13)*(B5-Assumptions!$B$10) -> 156405 | C6: =Assumptions!$B$45+(1-Assumptions!$B$13)*(C5-Assumptions!$B$10) -> 156405 | D6: =Assumptions!$B$45+(1-Assumptions!$B$13)*(D5-Assumptions!$B$10) -> 317062.9 | E6: =Assumptions!$B$45+(1-Assumptions!$B$13)*(E5-Assumptions!$B$10) -> 376405
A7: Indirect cost (today) | B7: =Assumptions!$B$46 -> 40102 | C7: =Assumptions!$B$46 -> 40102 | D7: =Assumptions!$B$46 -> 40102 | E7: =Assumptions!$B$46 -> 40102
A8: New roles, loaded | B8: 0 | C8: ='Hiring Plan'!R33 -> 96913.475 | D8: ='Monthly Model'!N6 -> 96913.475 | E8: ='Hiring Plan'!R32 -> 96913.475
A9: Programs: tools, marketing, travel | B9: 0 | C9: =Assumptions!B31+Assumptions!B32+Assumptions!B33 -> 15500 | D9: ='Monthly Model'!N8 -> 15500 | E9: =Assumptions!B31+Assumptions!B32+Assumptions!B33 -> 15500
A10: Total cost | B10: =SUM(B6:B9) -> 196507 | C10: =SUM(C6:C9) -> 308920.48 | D10: =SUM(D6:D9) -> 469578.38 | E10: =SUM(E6:E9) -> 528920.48
A11: EBITDA | B11: =B5-B10 -> 253493 | C11: =C5-C10 -> 141079.52 | D11: =D5-D10 -> 382066.38 | E11: =E5-E10 -> 471079.52
A12: EBITDA margin | B12: =IF(B5=0,0,B11/B5) -> 0.56331778 | C12: =IF(C5=0,0,C11/C5) -> 0.31351006 | D12: =IF(D5=0,0,D11/D5) -> 0.44862177 | E12: =IF(E5=0,0,E11/E5) -> 0.47107952
A13: Delivery gross margin | B13: =IF(B5=0,0,(B5-B6)/B5) -> 0.65243333 | C13: =IF(C5=0,0,(C5-C6)/C5) -> 0.65243333 | D13: =IF(D5=0,0,(D5-D6)/D5) -> 0.62770521 | E13: =IF(E5=0,0,(E5-E6)/E5) -> 0.623595
A15: Sep 2026 revenue implied by the 40% direct-cost ratio was ~$391K; at that revenue today's EBITDA margin is ~50%, not the 56% shown at $450K MRR.

Sheet Meetings
A1: Bookings and meetings needed, months 1-12
A3: Source | B3: New ARR booked, months 1-12 ($) | C3: New-logo ACV ($) | D3: Deals | E3: Booked meeting to won | F3: Meetings booked, year | G3: Meetings booked, a month | H3: Full run-rate meetings a month
A4: India and RoW sales team | B4: =SUM('Monthly Model'!C14:N14)*12 -> 1950000 | C4: =Assumptions!B39 -> 60000 | D4: =IF(C4=0,0,B4/C4) -> 32.5 | E4: =Assumptions!B42 -> 0.117 | F4: =IF(E4=0,0,D4/E4) -> 277.77778 | G4: =F4/12 -> 23.148148 | H4: =3*Assumptions!B15/Assumptions!B39/12/Assumptions!B42 -> 42.735043
A5: US AEs and Sudharshan | B5: =SUM('Monthly Model'!C15:N16)*12 -> 925000 | C5: =Assumptions!B40 -> 100000 | D5: =IF(C5=0,0,B5/C5) -> 9.25 | E5: =Assumptions!B43 -> 0.08 | F5: =IF(E5=0,0,D5/E5) -> 115.625 | G5: =F5/12 -> 9.6354167 | H5: =((1+Assumptions!B35)*Assumptions!B16+Assumptions!B17)/Assumptions!B40/12/Assumptions!B43 -> 18.75
A6: Partnerships | B6: =SUM('Monthly Model'!C17:N17)*12 -> 62500 | C6: =Assumptions!B41 -> 50000 | D6: =IF(C6=0,0,B6/C6) -> 1.25 | E6: =Assumptions!B42 -> 0.117 | F6: =IF(E6=0,0,D6/E6) -> 10.683761 | G6: =F6/12 -> 0.89031339 | H6: =Assumptions!B18/Assumptions!B41/12/Assumptions!B42 -> 7.1225071
A7: Today's engine (founders, referrals, inbound) | B7: =SUM('Monthly Model'!C20:N20)*12 -> 2736000 | C7: =Assumptions!B41 -> 50000 | D7: =IF(C7=0,0,B7/C7) -> 54.72 | E7: =Assumptions!B42 -> 0.117 | F7: =IF(E7=0,0,D7/E7) -> 467.69231 | G7: =F7/12 -> 38.974359 | H7: =Assumptions!B11*12/Assumptions!B41/Assumptions!B42 -> 38.974359
A8: Total | B8: =SUM(B4:B7) -> 5673500 | D8: =SUM(D4:D7) -> 97.72 | F8: =SUM(F4:F7) -> 871.77885 | G8: =SUM(G4:G7) -> 72.648237 | H8: =SUM(H4:H7) -> 107.58191
A10: SDR capacity: 4 SDRs at 12-15 qualified meetings a month = 48-60 a month.
