Workbook

Sheet How It Works
B1: Slate – Growth Lead Commission Plan (draft for brainstorming)
B3: THE FORMULA (one line)
B4: Commission per deal = Year-1 ACV × Base rate (deal size × lead source) × Contract/payment multiplier
B5: Monthly payout = Sum of deal commissions in the month × Revenue-attainment multiplier × Conversion gate
B7: STEP 1 – Deal size band (MRR after discount)
B8: • < $1,000/mo → Growth ($499) and Scale ($999) • $1,000–$3,000/mo → Agency ($2,000) • $3,000+/mo → Enterprise / custom
B9: STEP 2 – Lead source (who did the work to create the deal)
B10: • Inbound – marketing/another team generated it; she ran the demo and closed. Lowest rate.
B11: • Co-sourced – inbound lead that had gone cold / needed real nurturing, or a referral she actively worked. Middle rate.
B12: • Self-sourced – she prospected / outreached and created the opportunity herself. Highest rate (~1.5–1.75x inbound).
B13: STEP 3 – Contract & payment type multiplier
B14: • Annual upfront 1.00x (baseline) · Annual billed monthly 0.75x · Multi-year upfront 1.30x · Multi-year billed annually 1.15x · Month-to-month 0.40x
... B31: • Review the plan after 1 quarter; recalibrate targets from actual MQL volume and conversion.

Sheet Inputs
A1: Inputs – all plan levers
A2: Legend: blue text = editable input · yellow fill = key decision to agree on · black = formula. Defaults are benchmark-based starting points (see Benchmarks tab).
A4: 1. Base commission rate (% of Year-1 ACV) by deal size and lead source
A5: Deal band | B5: Min MRR ($/mo) | C5: Inbound (closer only) | D5: Co-sourced | E5: Self-sourced | F5: Rationale
A6: < $1,000/mo (Growth, Scale) | B6: 0 | C6: 0.06 | D6: 0.08 | E6: 0.1 | F6: Small, fast deals; mostly inbound demo-and-close. Lower rate keeps cost of sale in line with ~$5–10k ACV.
A7: $1,000–$3,000/mo (Agency) | B7: 1000 | C7: 0.07 | D7: 0.09 | E7: 0.12 | F7: Mid-market cycle, more stakeholders. Near the ~10% AE benchmark for self-sourced.
A8: $3,000+/mo (Enterprise / custom) | B8: 3000 | C8: 0.08 | D8: 0.1 | E8: 0.14 | F8: Longest cycle, negotiation, procurement. Highest rate to reward the hardest deals.
A10: 2. Contract & payment multiplier (applied to base rate)
A11: Payment type | B11: Multiplier | C11: Annual discount applies? | D11: When commission is paid | F11: Rationale
A12: Annual - Upfront | B12: 1 | C12: Yes | D12: 100% when invoice is paid | F12: Baseline. Full year of cash in hand, lowest churn risk.
A13: Annual - Monthly billing | B13: 0.75 | C13: Yes | D13: 50% after 1st payment, 50% after 6th payment | F13: Same commitment but cash risk sits with Slate; discount reflects that.
A14: Multi-year - Upfront | B14: 1.3 | C14: Yes | D14: 100% when invoice is paid | F14: 2+ yr cash upfront is the best outcome. Calculated on Year-1 ACV only, never full TCV.
A15: Multi-year - Annual billing | B15: 1.15 | C15: Yes | D15: 100% when Year-1 invoice is paid | F15: Long commitment, but only year 1 cash collected.
A16: Month-to-month | B16: 0.4 | C16: No | D16: 100% after 3rd monthly payment | F16: No commitment, highest churn. Small reward; push her toward annual.
A18: 3. Lead source definitions (tag in CRM at deal creation)
A19: Source | B19: Definition | F19: Evidence required
A20: Inbound | B20: Lead came from marketing / website / another team; she ran demo and closed. | F20: Default for any MQL routed to her.
A21: Co-sourced | B21: Inbound or referral lead that needed meaningful work from her: revived a cold lead, multi-thread outreach, ran a custom pilot. | F21: Founder sign-off; activity visible in CRM.
A22: Self-sourced | B22: She found the account and did first outreach (LinkedIn, email, events, network). No prior inbound touch in last 90 days. | F22: First-touch activity logged by her in CRM before any marketing touch.
A24: 4. Monthly targets & gates
A25: New MRR target ($/mo, all sources) | B25: 6000 | F25: PLACEHOLDER – set from trailing 3-month avg new MRR × ~1.1. Includes inbound + self-sourced.
A26: MQL → Closed-won target % | B26: 0.05 | F26: PLACEHOLDER – B2B SaaS benchmark is ~1–5% MQL→customer; demo-request MQLs convert higher. Calibrate to your last 3 months.
A27: Payout multiplier if conversion target missed | B27: 0.75 | F27: 0.75x = soft gate. Set to 0 to make it a hard 'must hit to earn' gate.
A28: Monthly payout cap ($, 0 = no cap) | B28: 0 | F28: Optional safety valve while the plan is new.
A29: Clawback window (days) | B29: 90 | F29: Commission reversed if customer churns/refunds inside this window.
A30: Annual plan discount | B30: 0.2 | F30: From Slate pricing page (Annual = 20% off).
A32: 5. Revenue attainment → payout multiplier (New MRR ÷ target)
A33: Attainment from | B33: Multiplier | C33: Meaning
A34: 0 | B34: 0 | C34: Below threshold – no commission this month
A35: 0.5 | B35: 0.5 | C35: Partial
A36: 0.8 | B36: 0.8 | C36: Near target
A37: 1 | B37: 1 | C37: At target – full commission
A38: 1.2 | B38: 1.25 | C38: Accelerator – over-delivery
A40: 6. OTE sanity check (does the plan land near a 70/30 split?)
A41: Her annual base salary ($) | B41: 60000 | F41: PLACEHOLDER – replace with actual base (in $).
A42: Variable share of OTE | B42: 0.3 | F42: 70/30 base/variable as requested.
A43: Target annual variable ($) | B43: =B41*B42/(1-B42) -> 25714.286 | F43: Variable she'd earn at 100% target under a true 70/30.
A44: Target monthly variable ($) | B44: =B43/12 -> 2142.8571
A45: Expected monthly commission at 100% target ($) | B45: =B25*12*B46 -> 5040 | F45: New MRR target × 12 × blended rate.
A46: Assumed blended effective rate (deal mix) | B46: 0.07 | F46: Rough mix: mostly inbound, small deals, some annual-monthly. Check Deal Log actuals.
...

Sheet Scenario Matrix
A1: Scenario Matrix – commission per deal (before monthly gates)
A2: List MRR is editable (blue). Net MRR applies the annual discount where Inputs says it applies. Everything else is driven by the Inputs tab.
A4: Plan | B4: List MRR ($/mo) | C4: Payment type | D4: Net MRR ($/mo) | E4: Year-1 ACV ($) | F4: Inbound ($) | G4: Co-sourced ($) | H4: Self-sourced ($)
A5: Growth | B5: 499 | C5: Annual - Upfront | D5: =B5*(1-IF(INDEX(Inputs!$C$12:$C$16,MATCH(C5,Inputs!$A$12:$A$16,0))="Yes",Inputs!$B$30,0)) -> 399.2 | E5: =D5*12 -> 4790.4 | F5: =E5*INDEX(Inputs!$C$6:$C$8,MATCH(D5,Inputs!$B$6:$B$8,1))*INDEX(Inputs!$B$12:$B$16,MATCH(C5,Inputs!$A$12:$A$16,0)) -> 287.424 | G5: =E5*INDEX(Inputs!$D$6:$D$8,MATCH(D5,Inputs!$B$6:$B$8,1))*INDEX(Inputs!$B$12:$B$16,MATCH(C5,Inputs!$A$12:$A$16,0)) -> 383.232 | H5: =E5*INDEX(Inputs!$E$6:$E$8,MATCH(D5,Inputs!$B$6:$B$8,1))*INDEX(Inputs!$B$12:$B$16,MATCH(C5,Inputs!$A$12:$A$16,0)) -> 479.04
A6: Growth | B6: =B5 -> 499 | C6: Annual - Monthly billing | D6: =B6*(1-IF(INDEX(Inputs!$C$12:$C$16,MATCH(C6,Inputs!$A$12:$A$16,0))="Yes",Inputs!$B$30,0)) -> 399.2 | E6: =D6*12 -> 4790.4 | F6: =E6*INDEX(Inputs!$C$6:$C$8,MATCH(D6,Inputs!$B$6:$B$8,1))*INDEX(Inputs!$B$12:$B$16,MATCH(C6,Inputs!$A$12:$A$16,0)) -> 215.568 | G6: =E6*INDEX(Inputs!$D$6:$D$8,MATCH(D6,Inputs!$B$6:$B$8,1))*INDEX(Inputs!$B$12:$B$16,MATCH(C6,Inputs!$A$12:$A$16,0)) -> 287.424 | H6: =E6*INDEX(Inputs!$E$6:$E$8,MATCH(D6,Inputs!$B$6:$B$8,1))*INDEX(Inputs!$B$12:$B$16,MATCH(C6,Inputs!$A$12:$A$16,0)) -> 359.28
A7: Growth | B7: =B6 -> 499 | C7: Multi-year - Upfront | D7: =B7*(1-IF(INDEX(Inputs!$C$12:$C$16,MATCH(C7,Inputs!$A$12:$A$16,0))="Yes",Inputs!$B$30,0)) -> 399.2 | E7: =D7*12 -> 4790.4 | F7: =E7*INDEX(Inputs!$C$6:$C$8,MATCH(D7,Inputs!$B$6:$B$8,1))*INDEX(Inputs!$B$12:$B$16,MATCH(C7,Inputs!$A$12:$A$16,0)) -> 373.6512 | G7: =E7*INDEX(Inputs!$D$6:$D$8,MATCH(D7,Inputs!$B$6:$B$8,1))*INDEX(Inputs!$B$12:$B$16,MATCH(C7,Inputs!$A$12:$A$16,0)) -> 498.2016 | H7: =E7*INDEX(Inputs!$E$6:$E$8,MATCH(D7,Inputs!$B$6:$B$8,1))*INDEX(Inputs!$B$12:$B$16,MATCH(C7,Inputs!$A$12:$A$16,0)) -> 622.752
A8: Growth | B8: =B7 -> 499 | C8: Multi-year - Annual billing | D8: =B8*(1-IF(INDEX(Inputs!$C$12:$C$16,MATCH(C8,Inputs!$A$12:$A$16,0))="Yes",Inputs!$B$30,0)) -> 399.2 | E8: =D8*12 -> 4790.4 | F8: =E8*INDEX(Inputs!$C$6:$C$8,MATCH(D8,Inputs!$B$6:$B$8,1))*INDEX(Inputs!$B$12:$B$16,MATCH(C8,Inputs!$A$12:$A$16,0)) -> 330.5376 | G8: =E8*INDEX(Inputs!$D$6:$D$8,MATCH(D8,Inputs!$B$6:$B$8,1))*INDEX(Inputs!$B$12:$B$16,MATCH(C8,Inputs!$A$12:$A$16,0)) -> 440.7168 | H8: =E8*INDEX(Inputs!$E$6:$E$8,MATCH(D8,Inputs!$B$6:$B$8,1))*INDEX(Inputs!$B$12:$B$16,MATCH(C8,Inputs!$A$12:$A$16,0)) -> 550.896
A9: Growth | B9: =B8 -> 499 | C9: Month-to-month | D9: =B9*(1-IF(INDEX(Inputs!$C$12:$C$16,MATCH(C9,Inputs!$A$12:$A$16,0))="Yes",Inputs!$B$30,0)) -> 499 | E9: =D9*12 -> 5988 | F9: =E9*INDEX(Inputs!$C$6:$C$8,MATCH(D9,Inputs!$B$6:$B$8,1))*INDEX(Inputs!$B$12:$B$16,MATCH(C9,Inputs!$A$12:$A$16,0)) -> 143.712 | G9: =E9*INDEX(Inputs!$D$6:$D$8,MATCH(D9,Inputs!$B$6:$B$8,1))*INDEX(Inputs!$B$12:$B$16,MATCH(C9,Inputs!$A$12:$A$16,0)) -> 191.616 | H9: =E9*INDEX(Inputs!$E$6:$E$8,MATCH(D9,Inputs!$B$6:$B$8,1))*INDEX(Inputs!$B$12:$B$16,MATCH(C9,Inputs!$A$12:$A$16,0)) -> 239.52
A10: Scale | B10: 999 | C10: Annual - Upfront | D10: =B10*(1-IF(INDEX(Inputs!$C$12:$C$16,MATCH(C10,Inputs!$A$12:$A$16,0))="Yes",Inputs!$B$30,0)) -> 799.2 | E10: =D10*12 -> 9590.4 | F10: =E10*INDEX(Inputs!$C$6:$C$8,MATCH(D10,Inputs!$B$6:$B$8,1))*INDEX(Inputs!$B$12:$B$16,MATCH(C10,Inputs!$A$12:$A$16,0)) -> 575.424 | G10: =E10*INDEX(Inputs!$D$6:$D$8,MATCH(D10,Inputs!$B$6:$B$8,1))*INDEX(Inputs!$B$12:$B$16,MATCH(C10,Inputs!$A$12:$A$16,0)) -> 767.232 | H10: =E10*INDEX(Inputs!$E$6:$E$8,MATCH(D10,Inputs!$B$6:$B$8,1))*INDEX(Inputs!$B$12:$B$16,MATCH(C10,Inputs!$A$12:$A$16,0)) -> 959.04
A11: Scale | B11: =B10 -> 999 | C11: Annual - Monthly billing | D11: =B11*(1-IF(INDEX(Inputs!$C$12:$C$16,MATCH(C11,Inputs!$A$12:$A$16,0))="Yes",Inputs!$B$30,0)) -> 799.2 | E11: =D11*12 -> 9590.4 | F11: =E11*INDEX(Inputs!$C$6:$C$8,MATCH(D11,Inputs!$B$6:$B$8,1))*INDEX(Inputs!$B$12:$B$16,MATCH(C11,Inputs!$A$12:$A$16,0)) -> 431.568 | G11: =E11*INDEX(Inputs!$D$6:$D$8,MATCH(D11,Inputs!$B$6:$B$8,1))*INDEX(Inputs!$B$12:$B$16,MATCH(C11,Inputs!$A$12:$A$16,0)) -> 575.424 | H11: =E11*INDEX(Inputs!$E$6:$E$8,MATCH(D11,Inputs!$B$6:$B$8,1))*INDEX(Inputs!$B$12:$B$16,MATCH(C11,Inputs!$A$12:$A$16,0)) -> 719.28
A12: Scale | B12: =B11 -> 999 | C12: Multi-year - Upfront | D12: =B12*(1-IF(INDEX(Inputs!$C$12:$C$16,MATCH(C12,Inputs!$A$12:$A$16,0))="Yes",Inputs!$B$30,0)) -> 799.2 | E12: =D12*12 -> 9590.4 | F12: =E12*INDEX(Inputs!$C$6:$C$8,MATCH(D12,Inputs!$B$6:$B$8,1))*INDEX(Inputs!$B$12:$B$16,MATCH(C12,Inputs!$A$12:$A$16,0)) -> 748.0512 | G12: =E12*INDEX(Inputs!$D$6:$D$8,MATCH(D12,Inputs!$B$6:$B$8,1))*INDEX(Inputs!$B$12:$B$16,MATCH(C12,Inputs!$A$12:$A$16,0)) -> 997.4016 | H12: =E12*INDEX(Inputs!$E$6:$E$8,MATCH(D12,Inputs!$B$6:$B$8,1))*INDEX(Inputs!$B$12:$B$16,MATCH(C12,Inputs!$A$12:$A$16,0)) -> 1246.752
A13: Scale | B13: =B12 -> 999 | C13: Multi-year - Annual billing | D13: =B13*(1-IF(INDEX(Inputs!$C$12:$C$16,MATCH(C13,Inputs!$A$12:$A$16,0))="Yes",Inputs!$B$30,0)) -> 799.2 | E13: =D13*12 -> 9590.4 | F13: =E13*INDEX(Inputs!$C$6:$C$8,MATCH(D13,Inputs!$B$6:$B$8,1))*INDEX(Inputs!$B$12:$B$16,MATCH(C13,Inputs!$A$12:$A$16,0)) -> 661.7376 | G13: =E13*INDEX(Inputs!$D$6:$D$8,MATCH(D13,Inputs!$B$6:$B$8,1))*INDEX(Inputs!$B$12:$B$16,MATCH(C13,Inputs!$A$12:$A$16,0)) -> 882.3168 | H13: =E13*INDEX(Inputs!$E$6:$E$8,MATCH(D13,Inputs!$B$6:$B$8,1))*INDEX(Inputs!$B$12:$B$16,MATCH(C13,Inputs!$A$12:$A$16,0)) -> 1102.896
A14: Scale | B14: =B13 -> 999 | C14: Month-to-month | D14: =B14*(1-IF(INDEX(Inputs!$C$12:$C$16,MATCH(C14,Inputs!$A$12:$A$16,0))="Yes",Inputs!$B$30,0)) -> 999 | E14: =D14*12 -> 11988 | F14: =E14*INDEX(Inputs!$C$6:$C$8,MATCH(D14,Inputs!$B$6:$B$8,1))*INDEX(Inputs!$B$12:$B$16,MATCH(C14,Inputs!$A$12:$A$16,0)) -> 287.712 | G14: =E14*INDEX(Inputs!$D$6:$D$8,MATCH(D14,Inputs!$B$6:$B$8,1))*INDEX(Inputs!$B$12:$B$16,MATCH(C14,Inputs!$A$12:$A$16,0)) -> 383.616 | H14: =E14*INDEX(Inputs!$E$6:$E$8,MATCH(D14,Inputs!$B$6:$B$8,1))*INDEX(Inputs!$B$12:$B$16,MATCH(C14,Inputs!$A$12:$A$16,0)) -> 479.52
A15: Agency | B15: 2000 | C15: Annual - Upfront | D15: =B15*(1-IF(INDEX(Inputs!$C$12:$C$16,MATCH(C15,Inputs!$A$12:$A$16,0))="Yes",Inputs!$B$30,0)) -> 1600 | E15: =D15*12 -> 19200 | F15: =E15*INDEX(Inputs!$C$6:$C$8,MATCH(D15,Inputs!$B$6:$B$8,1))*INDEX(Inputs!$B$12:$B$16,MATCH(C15,Inputs!$A$12:$A$16,0)) -> 1344 | G15: =E15*INDEX(Inputs!$D$6:$D$8,MATCH(D15,Inputs!$B$6:$B$8,1))*INDEX(Inputs!$B$12:$B$16,MATCH(C15,Inputs!$A$12:$A$16,0)) -> 1728 | H15: =E15*INDEX(Inputs!$E$6:$E$8,MATCH(D15,Inputs!$B$6:$B$8,1))*INDEX(Inputs!$B$12:$B$16,MATCH(C15,Inputs!$A$12:$A$16,0)) -> 2304
A16: Agency | B16: =B15 -> 2000 | C16: Annual - Monthly billing | D16: =B16*(1-IF(INDEX(Inputs!$C$12:$C$16,MATCH(C16,Inputs!$A$12:$A$16,0))="Yes",Inputs!$B$30,0)) -> 1600 | E16: =D16*12 -> 19200 | F16: =E16*INDEX(Inputs!$C$6:$C$8,MATCH(D16,Inputs!$B$6:$B$8,1))*INDEX(Inputs!$B$12:$B$16,MATCH(C16,Inputs!$A$12:$A$16,0)) -> 1008 | G16: =E16*INDEX(Inputs!$D$6:$D$8,MATCH(D16,Inputs!$B$6:$B$8,1))*INDEX(Inputs!$B$12:$B$16,MATCH(C16,Inputs!$A$12:$A$16,0)) -> 1296 | H16: =E16*INDEX(Inputs!$E$6:$E$8,MATCH(D16,Inputs!$B$6:$B$8,1))*INDEX(Inputs!$B$12:$B$16,MATCH(C16,Inputs!$A$12:$A$16,0)) -> 1728
A17: Agency | B17: =B16 -> 2000 | C17: Multi-year - Upfront | D17: =B17*(1-IF(INDEX(Inputs!$C$12:$C$16,MATCH(C17,Inputs!$A$12:$A$16,0))="Yes",Inputs!$B$30,0)) -> 1600 | E17: =D17*12 -> 19200 | F17: =E17*INDEX(Inputs!$C$6:$C$8,MATCH(D17,Inputs!$B$6:$B$8,1))*INDEX(Inputs!$B$12:$B$16,MATCH(C17,Inputs!$A$12:$A$16,0)) -> 1747.2 | G17: =E17*INDEX(Inputs!$D$6:$D$8,MATCH(D17,Inputs!$B$6:$B$8,1))*INDEX(Inputs!$B$12:$B$16,MATCH(C17,Inputs!$A$12:$A$16,0)) -> 2246.4 | H17: =E17*INDEX(Inputs!$E$6:$E$8,MATCH(D17,Inputs!$B$6:$B$8,1))*INDEX(Inputs!$B$12:$B$16,MATCH(C17,Inputs!$A$12:$A$16,0)) -> 2995.2
A18: Agency | B18: =B17 -> 2000 | C18: Multi-year - Annual billing | D18: =B18*(1-IF(INDEX(Inputs!$C$12:$C$16,MATCH(C18,Inputs!$A$12:$A$16,0))="Yes",Inputs!$B$30,0)) -> 1600 | E18: =D18*12 -> 19200 | F18: =E18*INDEX(Inputs!$C$6:$C$8,MATCH(D18,Inputs!$B$6:$B$8,1))*INDEX(Inputs!$B$12:$B$16,MATCH(C18,Inputs!$A$12:$A$16,0)) -> 1545.6 | G18: =E18*INDEX(Inputs!$D$6:$D$8,MATCH(D18,Inputs!$B$6:$B$8,1))*INDEX(Inputs!$B$12:$B$16,MATCH(C18,Inputs!$A$12:$A$16,0)) -> 1987.2 | H18: =E18*INDEX(Inputs!$E$6:$E$8,MATCH(D18,Inputs!$B$6:$B$8,1))*INDEX(Inputs!$B$12:$B$16,MATCH(C18,Inputs!$A$12:$A$16,0)) -> 2649.6
A19: Agency | B19: =B18 -> 2000 | C19: Month-to-month | D19: =B19*(1-IF(INDEX(Inputs!$C$12:$C$16,MATCH(C19,Inputs!$A$12:$A$16,0))="Yes",Inputs!$B$30,0)) -> 2000 | E19: =D19*12 -> 24000 | F19: =E19*INDEX(Inputs!$C$6:$C$8,MATCH(D19,Inputs!$B$6:$B$8,1))*INDEX(Inputs!$B$12:$B$16,MATCH(C19,Inputs!$A$12:$A$16,0)) -> 672 | G19: =E19*INDEX(Inputs!$D$6:$D$8,MATCH(D19,Inputs!$B$6:$B$8,1))*INDEX(Inputs!$B$12:$B$16,MATCH(C19,Inputs!$A$12:$A$16,0)) -> 864 | H19: =E19*INDEX(Inputs!$E$6:$E$8,MATCH(D19,Inputs!$B$6:$B$8,1))*INDEX(Inputs!$B$12:$B$16,MATCH(C19,Inputs!$A$12:$A$16,0)) -> 1152
A20: Enterprise | B20: 4000 | C20: Annual - Upfront | D20: =B20*(1-IF(INDEX(Inputs!$C$12:$C$16,MATCH(C20,Inputs!$A$12:$A$16,0))="Yes",Inputs!$B$30,0)) -> 3200 | E20: =D20*12 -> 38400 | F20: =E20*INDEX(Inputs!$C$6:$C$8,MATCH(D20,Inputs!$B$6:$B$8,1))*INDEX(Inputs!$B$12:$B$16,MATCH(C20,Inputs!$A$12:$A$16,0)) -> 3072 | G20: =E20*INDEX(Inputs!$D$6:$D$8,MATCH(D20,Inputs!$B$6:$B$8,1))*INDEX(Inputs!$B$12:$B$16,MATCH(C20,Inputs!$A$12:$A$16,0)) -> 3840 | H20: =E20*INDEX(Inputs!$E$6:$E$8,MATCH(D20,Inputs!$B$6:$B$8,1))*INDEX(Inputs!$B$12:$B$16,MATCH(C20,Inputs!$A$12:$A$16,0)) -> 5376
A21: Enterprise | B21: =B20 -> 4000 | C21: Annual - Monthly billing | D21: =B21*(1-IF(INDEX(Inputs!$C$12:$C$16,MATCH(C21,Inputs!$A$12:$A$16,0))="Yes",Inputs!$B$30,0)) -> 3200 | E21: =D21*12 -> 38400 | F21: =E21*INDEX(Inputs!$C$6:$C$8,MATCH(D21,Inputs!$B$6:$B$8,1))*INDEX(Inputs!$B$12:$B$16,MATCH(C21,Inputs!$A$12:$A$16,0)) -> 2304 | G21: =E21*INDEX(Inputs!$D$6:$D$8,MATCH(D21,Inputs!$B$6:$B$8,1))*INDEX(Inputs!$B$12:$B$16,MATCH(C21,Inputs!$A$12:$A$16,0)) -> 2880 | H21: =E21*INDEX(Inputs!$E$6:$E$8,MATCH(D21,Inputs!$B$6:$B$8,1))*INDEX(Inputs!$B$12:$B$16,MATCH(C21,Inputs!$A$12:$A$16,0)) -> 4032
A22: Enterprise | B22: =B21 -> 4000 | C22: Multi-year - Upfront | D22: =B22*(1-IF(INDEX(Inputs!$C$12:$C$16,MATCH(C22,Inputs!$A$12:$A$16,0))="Yes",Inputs!$B$30,0)) -> 3200 | E22: =D22*12 -> 38400 | F22: =E22*INDEX(Inputs!$C$6:$C$8,MATCH(D22,Inputs!$B$6:$B$8,1))*INDEX(Inputs!$B$12:$B$16,MATCH(C22,Inputs!$A$12:$A$16,0)) -> 3993.6 | G22: =E22*INDEX(Inputs!$D$6:$D$8,MATCH(D22,Inputs!$B$6:$B$8,1))*INDEX(Inputs!$B$12:$B$16,MATCH(C22,Inputs!$A$12:$A$16,0)) -> 4992 | H22: =E22*INDEX(Inputs!$E$6:$E$8,MATCH(D22,Inputs!$B$6:$B$8,1))*INDEX(Inputs!$B$12:$B$16,MATCH(C22,Inputs!$A$12:$A$16,0)) -> 6988.8
A23: Enterprise | B23: =B22 -> 4000 | C23: Multi-year - Annual billing | D23: =B23*(1-IF(INDEX(Inputs!$C$12:$C$16,MATCH(C23,Inputs!$A$12:$A$16,0))="Yes",Inputs!$B$30,0)) -> 3200 | E23: =D23*12 -> 38400 | F23: =E23*INDEX(Inputs!$C$6:$C$8,MATCH(D23,Inputs!$B$6:$B$8,1))*INDEX(Inputs!$B$12:$B$16,MATCH(C23,Inputs!$A$12:$A$16,0)) -> 3532.8 | G23: =E23*INDEX(Inputs!$D$6:$D$8,MATCH(D23,Inputs!$B$6:$B$8,1))*INDEX(Inputs!$B$12:$B$16,MATCH(C23,Inputs!$A$12:$A$16,0)) -> 4416 | H23: =E23*INDEX(Inputs!$E$6:$E$8,MATCH(D23,Inputs!$B$6:$B$8,1))*INDEX(Inputs!$B$12:$B$16,MATCH(C23,Inputs!$A$12:$A$16,0)) -> 6182.4
A24: Enterprise | B24: =B23 -> 4000 | C24: Month-to-month | D24: =B24*(1-IF(INDEX(Inputs!$C$12:$C$16,MATCH(C24,Inputs!$A$12:$A$16,0))="Yes",Inputs!$B$30,0)) -> 4000 | E24: =D24*12 -> 48000 | F24: =E24*INDEX(Inputs!$C$6:$C$8,MATCH(D24,Inputs!$B$6:$B$8,1))*INDEX(Inputs!$B$12:$B$16,MATCH(C24,Inputs!$A$12:$A$16,0)) -> 1536 | G24: =E24*INDEX(Inputs!$D$6:$D$8,MATCH(D24,Inputs!$B$6:$B$8,1))*INDEX(Inputs!$B$12:$B$16,MATCH(C24,Inputs!$A$12:$A$16,0)) -> 1920 | H24: =E24*INDEX(Inputs!$E$6:$E$8,MATCH(D24,Inputs!$B$6:$B$8,1))*INDEX(Inputs!$B$12:$B$16,MATCH(C24,Inputs!$A$12:$A$16,0)) -> 2688

Sheet Deal Log
A1: Deal Log – one row per closed-won deal
A2: Fill the blue columns (A, C–H, Q). Net MRR = actual billed monthly amount after discounts. Rows 5–10 are EXAMPLES – overwrite them.
A4: Close date | B4: Month | C4: Customer | D4: Plan | E4: Net MRR ($/mo) | F4: Term (months) | G4: Payment type | H4: Lead source | I4: Year-1 ACV ($) | J4: Total contract value ($) | K4: Deal band | L4: Base rate | M4: Payment mult. | N4: Effective rate | O4: Commission ($) | P4: When paid | Q4: Notes
A5: 46330 | B5: =IF(A5="","",DATE(YEAR(A5),MONTH(A5),1)) -> 46327 | C5: Example – Acme Co | D5: Growth | E5: 399.2 | F5: 12 | G5: Annual - Upfront | H5: Inbound | I5: =IF(E5="","",E5*12) -> 4790.4 | J5: =IF(OR(E5="",F5=""),"",E5*F5) -> 4790.4 | K5: =IF(E5="","",INDEX(Inputs!$A$6:$A$8,MATCH(E5,Inputs!$B$6:$B$8,1))) -> < $1,000/mo (Growth, Scale) | L5: =IF(OR(E5="",H5=""),"",INDEX(Inputs!$C$6:$E$8,MATCH(E5,Inputs!$B$6:$B$8,1),MATCH(H5,Inputs!$A$20:$A$22,0))) -> 0.06 | M5: =IF(G5="","",INDEX(Inputs!$B$12:$B$16,MATCH(G5,Inputs!$A$12:$A$16,0))) -> 1 | N5: =IF(OR(L5="",M5=""),"",L5*M5) -> 0.06 | O5: =IF(OR(I5="",N5=""),0,I5*N5) -> 287.424 | P5: =IF(G5="","",INDEX(Inputs!$D$12:$D$16,MATCH(G5,Inputs!$A$12:$A$16,0))) -> 100% when invoice is paid
A6: 46334 | B6: =IF(A6="","",DATE(YEAR(A6),MONTH(A6),1)) -> 46327 | C6: Example – Brightline | D6: Scale | E6: 799.2 | F6: 12 | G6: Annual - Monthly billing | H6: Inbound | I6: =IF(E6="","",E6*12) -> 9590.4 | J6: =IF(OR(E6="",F6=""),"",E6*F6) -> 9590.4 | K6: =IF(E6="","",INDEX(Inputs!$A$6:$A$8,MATCH(E6,Inputs!$B$6:$B$8,1))) -> < $1,000/mo (Growth, Scale) | L6: =IF(OR(E6="",H6=""),"",INDEX(Inputs!$C$6:$E$8,MATCH(E6,Inputs!$B$6:$B$8,1),MATCH(H6,Inputs!$A$20:$A$22,0))) -> 0.06 | M6: =IF(G6="","",INDEX(Inputs!$B$12:$B$16,MATCH(G6,Inputs!$A$12:$A$16,0))) -> 0.75 | N6: =IF(OR(L6="",M6=""),"",L6*M6) -> 0.045 | O6: =IF(OR(I6="",N6=""),0,I6*N6) -> 431.568 | P6: =IF(G6="","",INDEX(Inputs!$D$12:$D$16,MATCH(G6,Inputs!$A$12:$A$16,0))) -> 50% after 1st payment, 50% after 6th payment
A7: 46338 | B7: =IF(A7="","",DATE(YEAR(A7),MONTH(A7),1)) -> 46327 | C7: Example – Northpeak Agency | D7: Agency | E7: 1600 | F7: 24 | G7: Multi-year - Upfront | H7: Self-sourced | I7: =IF(E7="","",E7*12) -> 19200 | J7: =IF(OR(E7="",F7=""),"",E7*F7) -> 38400 | K7: =IF(E7="","",INDEX(Inputs!$A$6:$A$8,MATCH(E7,Inputs!$B$6:$B$8,1))) -> $1,000–$3,000/mo (Agency) | L7: =IF(OR(E7="",H7=""),"",INDEX(Inputs!$C$6:$E$8,MATCH(E7,Inputs!$B$6:$B$8,1),MATCH(H7,Inputs!$A$20:$A$22,0))) -> 0.12 | M7: =IF(G7="","",INDEX(Inputs!$B$12:$B$16,MATCH(G7,Inputs!$A$12:$A$16,0))) -> 1.3 | N7: =IF(OR(L7="",M7=""),"",L7*M7) -> 0.156 | O7: =IF(OR(I7="",N7=""),0,I7*N7) -> 2995.2 | P7: =IF(G7="","",INDEX(Inputs!$D$12:$D$16,MATCH(G7,Inputs!$A$12:$A$16,0))) -> 100% when invoice is paid
A8: 46344 | B8: =IF(A8="","",DATE(YEAR(A8),MONTH(A8),1)) -> 46327 | C8: Example – Lumen Health | D8: Growth | E8: 499 | F8: 1 | G8: Month-to-month | H8: Inbound | I8: =IF(E8="","",E8*12) -> 5988 | J8: =IF(OR(E8="",F8=""),"",E8*F8) -> 499 | K8: =IF(E8="","",INDEX(Inputs!$A$6:$A$8,MATCH(E8,Inputs!$B$6:$B$8,1))) -> < $1,000/mo (Growth, Scale) | L8: =IF(OR(E8="",H8=""),"",INDEX(Inputs!$C$6:$E$8,MATCH(E8,Inputs!$B$6:$B$8,1),MATCH(H8,Inputs!$A$20:$A$22,0))) -> 0.06 | M8: =IF(G8="","",INDEX(Inputs!$B$12:$B$16,MATCH(G8,Inputs!$A$12:$A$16,0))) -> 0.4 | N8: =IF(OR(L8="",M8=""),"",L8*M8) -> 0.024 | O8: =IF(OR(I8="",N8=""),0,I8*N8) -> 143.712 | P8: =IF(G8="","",INDEX(Inputs!$D$12:$D$16,MATCH(G8,Inputs!$A$12:$A$16,0))) -> 100% after 3rd monthly payment
A9: 46351 | B9: =IF(A9="","",DATE(YEAR(A9),MONTH(A9),1)) -> 46327 | C9: Example – Vertex Retail | D9: Enterprise | E9: 3500 | F9: 12 | G9: Annual - Upfront | H9: Co-sourced | I9: =IF(E9="","",E9*12) -> 42000 | J9: =IF(OR(E9="",F9=""),"",E9*F9) -> 42000 | K9: =IF(E9="","",INDEX(Inputs!$A$6:$A$8,MATCH(E9,Inputs!$B$6:$B$8,1))) -> $3,000+/mo (Enterprise / custom) | L9: =IF(OR(E9="",H9=""),"",INDEX(Inputs!$C$6:$E$8,MATCH(E9,Inputs!$B$6:$B$8,1),MATCH(H9,Inputs!$A$20:$A$22,0))) -> 0.1 | M9: =IF(G9="","",INDEX(Inputs!$B$12:$B$16,MATCH(G9,Inputs!$A$12:$A$16,0))) -> 1 | N9: =IF(OR(L9="",M9=""),"",L9*M9) -> 0.1 | O9: =IF(OR(I9="",N9=""),0,I9*N9) -> 4200 | P9: =IF(G9="","",INDEX(Inputs!$D$12:$D$16,MATCH(G9,Inputs!$A$12:$A$16,0))) -> 100% when invoice is paid
A10: 46359 | B10: =IF(A10="","",DATE(YEAR(A10),MONTH(A10),1)) -> 46357 | C10: Example – Orbit Labs | D10: Scale | E10: 799.2 | F10: 12 | G10: Annual - Upfront | H10: Self-sourced | I10: =IF(E10="","",E10*12) -> 9590.4 | J10: =IF(OR(E10="",F10=""),"",E10*F10) -> 9590.4 | K10: =IF(E10="","",INDEX(Inputs!$A$6:$A$8,MATCH(E10,Inputs!$B$6:$B$8,1))) -> < $1,000/mo (Growth, Scale) | L10: =IF(OR(E10="",H10=""),"",INDEX(Inputs!$C$6:$E$8,MATCH(E10,Inputs!$B$6:$B$8,1),MATCH(H10,Inputs!$A$20:$A$22,0))) -> 0.1 | M10: =IF(G10="","",INDEX(Inputs!$B$12:$B$16,MATCH(G10,Inputs!$A$12:$A$16,0))) -> 1 | N10: =IF(OR(L10="",M10=""),"",L10*M10) -> 0.1 | O10: =IF(OR(I10="",N10=""),0,I10*N10) -> 959.04 | P10: =IF(G10="","",INDEX(Inputs!$D$12:$D$16,MATCH(G10,Inputs!$A$12:$A$16,0))) -> 100% when invoice is paid
B11: =IF(A11="","",DATE(YEAR(A11),MONTH(A11),1)) | I11: =IF(E11="","",E11*12) | J11: =IF(OR(E11="",F11=""),"",E11*F11) | K11: =IF(E11="","",INDEX(Inputs!$A$6:$A$8,MATCH(E11,Inputs!$B$6:$B$8,1))) | L11: =IF(OR(E11="",H11=""),"",INDEX(Inputs!$C$6:$E$8,MATCH(E11,Inputs!$B$6:$B$8,1),MATCH(H11,Inputs!$A$20:$A$22,0))) | M11: =IF(G11="","",INDEX(Inputs!$B$12:$B$16,MATCH(G11,Inputs!$A$12:$A$16,0))) | N11: =IF(OR(L11="",M11=""),"",L11*M11) | O11: =IF(OR(I11="",N11=""),0,I11*N11) -> 0 | P11: =IF(G11="","",INDEX(Inputs!$D$12:$D$16,MATCH(G11,Inputs!$A$12:$A$16,0)))
B12: =IF(A12="","",DATE(YEAR(A12),MONTH(A12),1)) | I12: =IF(E12="","",E12*12) | J12: =IF(OR(E12="",F12=""),"",E12*F12) | K12: =IF(E12="","",INDEX(Inputs!$A$6:$A$8,MATCH(E12,Inputs!$B$6:$B$8,1))) | L12: =IF(OR(E12="",H12=""),"",INDEX(Inputs!$C$6:$E$8,MATCH(E12,Inputs!$B$6:$B$8,1),MATCH(H12,Inputs!$A$20:$A$22,0))) | M12: =IF(G12="","",INDEX(Inputs!$B$12:$B$16,MATCH(G12,Inputs!$A$12:$A$16,0))) | N12: =IF(OR(L12="",M12=""),"",L12*M12) | O12: =IF(OR(I12="",N12=""),0,I12*N12) -> 0 | P12: =IF(G12="","",INDEX(Inputs!$D$12:$D$16,MATCH(G12,Inputs!$A$12:$A$16,0)))
B13: =IF(A13="","",DATE(YEAR(A13),MONTH(A13),1)) | I13: =IF(E13="","",E13*12) | J13: =IF(OR(E13="",F13=""),"",E13*F13) | K13: =IF(E13="","",INDEX(Inputs!$A$6:$A$8,MATCH(E13,Inputs!$B$6:$B$8,1))) | L13: =IF(OR(E13="",H13=""),"",INDEX(Inputs!$C$6:$E$8,MATCH(E13,Inputs!$B$6:$B$8,1),MATCH(H13,Inputs!$A$20:$A$22,0))) | M13: =IF(G13="","",INDEX(Inputs!$B$12:$B$16,MATCH(G13,Inputs!$A$12:$A$16,0))) | N13: =IF(OR(L13="",M13=""),"",L13*M13) | O13: =IF(OR(I13="",N13=""),0,I13*N13) -> 0 | P13: =IF(G13="","",INDEX(Inputs!$D$12:$D$16,MATCH(G13,Inputs!$A$12:$A$16,0)))
B14: =IF(A14="","",DATE(YEAR(A14),MONTH(A14),1)) | I14: =IF(E14="","",E14*12) | J14: =IF(OR(E14="",F14=""),"",E14*F14) | K14: =IF(E14="","",INDEX(Inputs!$A$6:$A$8,MATCH(E14,Inputs!$B$6:$B$8,1))) | L14: =IF(OR(E14="",H14=""),"",INDEX(Inputs!$C$6:$E$8,MATCH(E14,Inputs!$B$6:$B$8,1),MATCH(H14,Inputs!$A$20:$A$22,0))) | M14: =IF(G14="","",INDEX(Inputs!$B$12:$B$16,MATCH(G14,Inputs!$A$12:$A$16,0))) | N14: =IF(OR(L14="",M14=""),"",L14*M14) | O14: =IF(OR(I14="",N14=""),0,I14*N14) -> 0 | P14: =IF(G14="","",INDEX(Inputs!$D$12:$D$16,MATCH(G14,Inputs!$A$12:$A$16,0)))
B15: =IF(A15="","",DATE(YEAR(A15),MONTH(A15),1)) | I15: =IF(E15="","",E15*12) | J15: =IF(OR(E15="",F15=""),"",E15*F15) | K15: =IF(E15="","",INDEX(Inputs!$A$6:$A$8,MATCH(E15,Inputs!$B$6:$B$8,1))) | L15: =IF(OR(E15="",H15=""),"",INDEX(Inputs!$C$6:$E$8,MATCH(E15,Inputs!$B$6:$B$8,1),MATCH(H15,Inputs!$A$20:$A$22,0))) | M15: =IF(G15="","",INDEX(Inputs!$B$12:$B$16,MATCH(G15,Inputs!$A$12:$A$16,0))) | N15: =IF(OR(L15="",M15=""),"",L15*M15) | O15: =IF(OR(I15="",N15=""),0,I15*N15) -> 0 | P15: =IF(G15="","",INDEX(Inputs!$D$12:$D$16,MATCH(G15,Inputs!$A$12:$A$16,0)))
B16: =IF(A16="","",DATE(YEAR(A16),MONTH(A16),1)) | I16: =IF(E16="","",E16*12) | J16: =IF(OR(E16="",F16=""),"",E16*F16) | K16: =IF(E16="","",INDEX(Inputs!$A$6:$A$8,MATCH(E16,Inputs!$B$6:$B$8,1))) | L16: =IF(OR(E16="",H16=""),"",INDEX(Inputs!$C$6:$E$8,MATCH(E16,Inputs!$B$6:$B$8,1),MATCH(H16,Inputs!$A$20:$A$22,0))) | M16: =IF(G16="","",INDEX(Inputs!$B$12:$B$16,MATCH(G16,Inputs!$A$12:$A$16,0))) | N16: =IF(OR(L16="",M16=""),"",L16*M16) | O16: =IF(OR(I16="",N16=""),0,I16*N16) -> 0 | P16: =IF(G16="","",INDEX(Inputs!$D$12:$D$16,MATCH(G16,Inputs!$A$12:$A$16,0)))
B17: =IF(A17="","",DATE(YEAR(A17),MONTH(A17),1)) | I17: =IF(E17="","",E17*12) | J17: =IF(OR(E17="",F17=""),"",E17*F17) | K17: =IF(E17="","",INDEX(Inputs!$A$6:$A$8,MATCH(E17,Inputs!$B$6:$B$8,1))) | L17: =IF(OR(E17="",H17=""),"",INDEX(Inputs!$C$6:$E$8,MATCH(E17,Inputs!$B$6:$B$8,1),MATCH(H17,Inputs!$A$20:$A$22,0))) | M17: =IF(G17="","",INDEX(Inputs!$B$12:$B$16,MATCH(G17,Inputs!$A$12:$A$16,0))) | N17: =IF(OR(L17="",M17=""),"",L17*M17) | O17: =IF(OR(I17="",N17=""),0,I17*N17) -> 0 | P17: =IF(G17="","",INDEX(Inputs!$D$12:$D$16,MATCH(G17,Inputs!$A$12:$A$16,0)))
B18: =IF(A18="","",DATE(YEAR(A18),MONTH(A18),1)) | I18: =IF(E18="","",E18*12) | J18: =IF(OR(E18="",F18=""),"",E18*F18) | K18: =IF(E18="","",INDEX(Inputs!$A$6:$A$8,MATCH(E18,Inputs!$B$6:$B$8,1))) | L18: =IF(OR(E18="",H18=""),"",INDEX(Inputs!$C$6:$E$8,MATCH(E18,Inputs!$B$6:$B$8,1),MATCH(H18,Inputs!$A$20:$A$22,0))) | M18: =IF(G18="","",INDEX(Inputs!$B$12:$B$16,MATCH(G18,Inputs!$A$12:$A$16,0))) | N18: =IF(OR(L18="",M18=""),"",L18*M18) | O18: =IF(OR(I18="",N18=""),0,I18*N18) -> 0 | P18: =IF(G18="","",INDEX(Inputs!$D$12:$D$16,MATCH(G18,Inputs!$A$12:$A$16,0)))
B19: =IF(A19="","",DATE(YEAR(A19),MONTH(A19),1)) | I19: =IF(E19="","",E19*12) | J19: =IF(OR(E19="",F19=""),"",E19*F19) | K19: =IF(E19="","",INDEX(Inputs!$A$6:$A$8,MATCH(E19,Inputs!$B$6:$B$8,1))) | L19: =IF(OR(E19="",H19=""),"",INDEX(Inputs!$C$6:$E$8,MATCH(E19,Inputs!$B$6:$B$8,1),MATCH(H19,Inputs!$A$20:$A$22,0))) | M19: =IF(G19="","",INDEX(Inputs!$B$12:$B$16,MATCH(G19,Inputs!$A$12:$A$16,0))) | N19: =IF(OR(L19="",M19=""),"",L19*M19) | O19: =IF(OR(I19="",N19=""),0,I19*N19) -> 0 | P19: =IF(G19="","",INDEX(Inputs!$D$12:$D$16,MATCH(G19,Inputs!$A$12:$A$16,0)))
B20: =IF(A20="","",DATE(YEAR(A20),MONTH(A20),1)) | I20: =IF(E20="","",E20*12) | J20: =IF(OR(E20="",F20=""),"",E20*F20) | K20: =IF(E20="","",INDEX(Inputs!$A$6:$A$8,MATCH(E20,Inputs!$B$6:$B$8,1))) | L20: =IF(OR(E20="",H20=""),"",INDEX(Inputs!$C$6:$E$8,MATCH(E20,Inputs!$B$6:$B$8,1),MATCH(H20,Inputs!$A$20:$A$22,0))) | M20: =IF(G20="","",INDEX(Inputs!$B$12:$B$16,MATCH(G20,Inputs!$A$12:$A$16,0))) | N20: =IF(OR(L20="",M20=""),"",L20*M20) | O20: =IF(OR(I20="",N20=""),0,I20*N20) -> 0 | P20: =IF(G20="","",INDEX(Inputs!$D$12:$D$16,MATCH(G20,Inputs!$A$12:$A$16,0)))
B21: =IF(A21="","",DATE(YEAR(A21),MONTH(A21),1)) | I21: =IF(E21="","",E21*12) | J21: =IF(OR(E21="",F21=""),"",E21*F21) | K21: =IF(E21="","",INDEX(Inputs!$A$6:$A$8,MATCH(E21,Inputs!$B$6:$B$8,1))) | L21: =IF(OR(E21="",H21=""),"",INDEX(Inputs!$C$6:$E$8,MATCH(E21,Inputs!$B$6:$B$8,1),MATCH(H21,Inputs!$A$20:$A$22,0))) | M21: =IF(G21="","",INDEX(Inputs!$B$12:$B$16,MATCH(G21,Inputs!$A$12:$A$16,0))) | N21: =IF(OR(L21="",M21=""),"",L21*M21) | O21: =IF(OR(I21="",N21=""),0,I21*N21) -> 0 | P21: =IF(G21="","",INDEX(Inputs!$D$12:$D$16,MATCH(G21,Inputs!$A$12:$A$16,0)))
B22: =IF(A22="","",DATE(YEAR(A22),MONTH(A22),1)) | I22: =IF(E22="","",E22*12) | J22: =IF(OR(E22="",F22=""),"",E22*F22) | K22: =IF(E22="","",INDEX(Inputs!$A$6:$A$8,MATCH(E22,Inputs!$B$6:$B$8,1))) | L22: =IF(OR(E22="",H22=""),"",INDEX(Inputs!$C$6:$E$8,MATCH(E22,Inputs!$B$6:$B$8,1),MATCH(H22,Inputs!$A$20:$A$22,0))) | M22: =IF(G22="","",INDEX(Inputs!$B$12:$B$16,MATCH(G22,Inputs!$A$12:$A$16,0))) | N22: =IF(OR(L22="",M22=""),"",L22*M22) | O22: =IF(OR(I22="",N22=""),0,I22*N22) -> 0 | P22: =IF(G22="","",INDEX(Inputs!$D$12:$D$16,MATCH(G22,Inputs!$A$12:$A$16,0)))
... B64: =IF(A64="","",DATE(YEAR(A64),MONTH(A64),1)) | I64: =IF(E64="","",E64*12) | J64: =IF(OR(E64="",F64=""),"",E64*F64) | K64: =IF(E64="","",INDEX(Inputs!$A$6:$A$8,MATCH(E64,Inputs!$B$6:$B$8,1))) | L64: =IF(OR(E64="",H64=""),"",INDEX(Inputs!$C$6:$E$8,MATCH(E64,Inputs!$B$6:$B$8,1),MATCH(H64,Inputs!$A$20:$A$22,0))) | M64: =IF(G64="","",INDEX(Inputs!$B$12:$B$16,MATCH(G64,Inputs!$A$12:$A$16,0))) | N64: =IF(OR(L64="",M64=""),"",L64*M64) | O64: =IF(OR(I64="",N64=""),0,I64*N64) -> 0 | P64: =IF(G64="","",INDEX(Inputs!$D$12:$D$16,MATCH(G64,Inputs!$A$12:$A$16,0)))
N65: TOTAL | O65: =SUM(O5:O64) -> 9016.944

Sheet Monthly Scorecard
A1: Monthly Scorecard – targets, gates and payout
A2: Enter MQLs and demos (blue). Deals and MRR pull from Deal Log. Target defaults to Inputs but can be overridden per month. Commission is shown in the month earned; cash payout timing follows the 'When paid' rule.
A4: Month | B4: MQLs routed to her | C4: Demos held | D4: Deals won (all) | E4: Deals won (inbound + co-sourced) | F4: New MRR closed ($) | G4: MQL → Won % | H4: New MRR target ($) | I4: Revenue attainment | J4: Revenue tier mult. | K4: Conversion target met? | L4: Final payout mult. | M4: Commission earned ($) | N4: Payout after gates ($) | O4: Notes
A5: 46327 | B5: 60 | C5: 14 | D5: =COUNTIFS('Deal Log'!$B$5:$B$64,A5) -> 5 | E5: =COUNTIFS('Deal Log'!$B$5:$B$64,A5,'Deal Log'!$H$5:$H$64,"<>Self-sourced") -> 4 | F5: =SUMIFS('Deal Log'!$E$5:$E$64,'Deal Log'!$B$5:$B$64,A5) -> 6797.4 | G5: =IF(N(B5)=0,0,E5/B5) -> 0.066666667 | H5: =Inputs!$B$25 -> 6000 | I5: =IF(N(H5)=0,0,F5/H5) -> 1.1329 | J5: =INDEX(Inputs!$B$34:$B$38,MATCH(I5,Inputs!$A$34:$A$38,1)) -> 1 | K5: =IF(N(B5)=0,"n/a",IF(G5>=Inputs!$B$26,"Yes","No")) -> Yes | L5: =J5*IF(K5="No",Inputs!$B$27,1) -> 1 | M5: =SUMIFS('Deal Log'!$O$5:$O$64,'Deal Log'!$B$5:$B$64,A5) -> 8057.904 | N5: =IF(Inputs!$B$28>0,MIN(M5*L5,Inputs!$B$28),M5*L5) -> 8057.904
A6: 46357 | B6: 55 | C6: 12 | D6: =COUNTIFS('Deal Log'!$B$5:$B$64,A6) -> 1 | E6: =COUNTIFS('Deal Log'!$B$5:$B$64,A6,'Deal Log'!$H$5:$H$64,"<>Self-sourced") -> 0 | F6: =SUMIFS('Deal Log'!$E$5:$E$64,'Deal Log'!$B$5:$B$64,A6) -> 799.2 | G6: =IF(N(B6)=0,0,E6/B6) -> 0 | H6: =Inputs!$B$25 -> 6000 | I6: =IF(N(H6)=0,0,F6/H6) -> 0.1332 | J6: =INDEX(Inputs!$B$34:$B$38,MATCH(I6,Inputs!$A$34:$A$38,1)) -> 0 | K6: =IF(N(B6)=0,"n/a",IF(G6>=Inputs!$B$26,"Yes","No")) -> No | L6: =J6*IF(K6="No",Inputs!$B$27,1) -> 0 | M6: =SUMIFS('Deal Log'!$O$5:$O$64,'Deal Log'!$B$5:$B$64,A6) -> 959.04 | N6: =IF(Inputs!$B$28>0,MIN(M6*L6,Inputs!$B$28),M6*L6) -> 0
A7: 46388 | D7: =COUNTIFS('Deal Log'!$B$5:$B$64,A7) -> 0 | E7: =COUNTIFS('Deal Log'!$B$5:$B$64,A7,'Deal Log'!$H$5:$H$64,"<>Self-sourced") -> 0 | F7: =SUMIFS('Deal Log'!$E$5:$E$64,'Deal Log'!$B$5:$B$64,A7) -> 0 | G7: =IF(N(B7)=0,0,E7/B7) -> 0 | H7: =Inputs!$B$25 -> 6000 | I7: =IF(N(H7)=0,0,F7/H7) -> 0 | J7: =INDEX(Inputs!$B$34:$B$38,MATCH(I7,Inputs!$A$34:$A$38,1)) -> 0 | K7: =IF(N(B7)=0,"n/a",IF(G7>=Inputs!$B$26,"Yes","No")) -> n/a | L7: =J7*IF(K7="No",Inputs!$B$27,1) -> 0 | M7: =SUMIFS('Deal Log'!$O$5:$O$64,'Deal Log'!$B$5:$B$64,A7) -> 0 | N7: =IF(Inputs!$B$28>0,MIN(M7*L7,Inputs!$B$28),M7*L7) -> 0
A8: 46419 | D8: =COUNTIFS('Deal Log'!$B$5:$B$64,A8) -> 0 | E8: =COUNTIFS('Deal Log'!$B$5:$B$64,A8,'Deal Log'!$H$5:$H$64,"<>Self-sourced") -> 0 | F8: =SUMIFS('Deal Log'!$E$5:$E$64,'Deal Log'!$B$5:$B$64,A8) -> 0 | G8: =IF(N(B8)=0,0,E8/B8) -> 0 | H8: =Inputs!$B$25 -> 6000 | I8: =IF(N(H8)=0,0,F8/H8) -> 0 | J8: =INDEX(Inputs!$B$34:$B$38,MATCH(I8,Inputs!$A$34:$A$38,1)) -> 0 | K8: =IF(N(B8)=0,"n/a",IF(G8>=Inputs!$B$26,"Yes","No")) -> n/a | L8: =J8*IF(K8="No",Inputs!$B$27,1) -> 0 | M8: =SUMIFS('Deal Log'!$O$5:$O$64,'Deal Log'!$B$5:$B$64,A8) -> 0 | N8: =IF(Inputs!$B$28>0,MIN(M8*L8,Inputs!$B$28),M8*L8) -> 0
A9: 46447 | D9: =COUNTIFS('Deal Log'!$B$5:$B$64,A9) -> 0 | E9: =COUNTIFS('Deal Log'!$B$5:$B$64,A9,'Deal Log'!$H$5:$H$64,"<>Self-sourced") -> 0 | F9: =SUMIFS('Deal Log'!$E$5:$E$64,'Deal Log'!$B$5:$B$64,A9) -> 0 | G9: =IF(N(B9)=0,0,E9/B9) -> 0 | H9: =Inputs!$B$25 -> 6000 | I9: =IF(N(H9)=0,0,F9/H9) -> 0 | J9: =INDEX(Inputs!$B$34:$B$38,MATCH(I9,Inputs!$A$34:$A$38,1)) -> 0 | K9: =IF(N(B9)=0,"n/a",IF(G9>=Inputs!$B$26,"Yes","No")) -> n/a | L9: =J9*IF(K9="No",Inputs!$B$27,1) -> 0 | M9: =SUMIFS('Deal Log'!$O$5:$O$64,'Deal Log'!$B$5:$B$64,A9) -> 0 | N9: =IF(Inputs!$B$28>0,MIN(M9*L9,Inputs!$B$28),M9*L9) -> 0
A10: 46478 | D10: =COUNTIFS('Deal Log'!$B$5:$B$64,A10) -> 0 | E10: =COUNTIFS('Deal Log'!$B$5:$B$64,A10,'Deal Log'!$H$5:$H$64,"<>Self-sourced") -> 0 | F10: =SUMIFS('Deal Log'!$E$5:$E$64,'Deal Log'!$B$5:$B$64,A10) -> 0 | G10: =IF(N(B10)=0,0,E10/B10) -> 0 | H10: =Inputs!$B$25 -> 6000 | I10: =IF(N(H10)=0,0,F10/H10) -> 0 | J10: =INDEX(Inputs!$B$34:$B$38,MATCH(I10,Inputs!$A$34:$A$38,1)) -> 0 | K10: =IF(N(B10)=0,"n/a",IF(G10>=Inputs!$B$26,"Yes","No")) -> n/a | L10: =J10*IF(K10="No",Inputs!$B$27,1) -> 0 | M10: =SUMIFS('Deal Log'!$O$5:$O$64,'Deal Log'!$B$5:$B$64,A10) -> 0 | N10: =IF(Inputs!$B$28>0,MIN(M10*L10,Inputs!$B$28),M10*L10) -> 0
A11: 46508 | D11: =COUNTIFS('Deal Log'!$B$5:$B$64,A11) -> 0 | E11: =COUNTIFS('Deal Log'!$B$5:$B$64,A11,'Deal Log'!$H$5:$H$64,"<>Self-sourced") -> 0 | F11: =SUMIFS('Deal Log'!$E$5:$E$64,'Deal Log'!$B$5:$B$64,A11) -> 0 | G11: =IF(N(B11)=0,0,E11/B11) -> 0 | H11: =Inputs!$B$25 -> 6000 | I11: =IF(N(H11)=0,0,F11/H11) -> 0 | J11: =INDEX(Inputs!$B$34:$B$38,MATCH(I11,Inputs!$A$34:$A$38,1)) -> 0 | K11: =IF(N(B11)=0,"n/a",IF(G11>=Inputs!$B$26,"Yes","No")) -> n/a | L11: =J11*IF(K11="No",Inputs!$B$27,1) -> 0 | M11: =SUMIFS('Deal Log'!$O$5:$O$64,'Deal Log'!$B$5:$B$64,A11) -> 0 | N11: =IF(Inputs!$B$28>0,MIN(M11*L11,Inputs!$B$28),M11*L11) -> 0
A12: 46539 | D12: =COUNTIFS('Deal Log'!$B$5:$B$64,A12) -> 0 | E12: =COUNTIFS('Deal Log'!$B$5:$B$64,A12,'Deal Log'!$H$5:$H$64,"<>Self-sourced") -> 0 | F12: =SUMIFS('Deal Log'!$E$5:$E$64,'Deal Log'!$B$5:$B$64,A12) -> 0 | G12: =IF(N(B12)=0,0,E12/B12) -> 0 | H12: =Inputs!$B$25 -> 6000 | I12: =IF(N(H12)=0,0,F12/H12) -> 0 | J12: =INDEX(Inputs!$B$34:$B$38,MATCH(I12,Inputs!$A$34:$A$38,1)) -> 0 | K12: =IF(N(B12)=0,"n/a",IF(G12>=Inputs!$B$26,"Yes","No")) -> n/a | L12: =J12*IF(K12="No",Inputs!$B$27,1) -> 0 | M12: =SUMIFS('Deal Log'!$O$5:$O$64,'Deal Log'!$B$5:$B$64,A12) -> 0 | N12: =IF(Inputs!$B$28>0,MIN(M12*L12,Inputs!$B$28),M12*L12) -> 0
A13: 46569 | D13: =COUNTIFS('Deal Log'!$B$5:$B$64,A13) -> 0 | E13: =COUNTIFS('Deal Log'!$B$5:$B$64,A13,'Deal Log'!$H$5:$H$64,"<>Self-sourced") -> 0 | F13: =SUMIFS('Deal Log'!$E$5:$E$64,'Deal Log'!$B$5:$B$64,A13) -> 0 | G13: =IF(N(B13)=0,0,E13/B13) -> 0 | H13: =Inputs!$B$25 -> 6000 | I13: =IF(N(H13)=0,0,F13/H13) -> 0 | J13: =INDEX(Inputs!$B$34:$B$38,MATCH(I13,Inputs!$A$34:$A$38,1)) -> 0 | K13: =IF(N(B13)=0,"n/a",IF(G13>=Inputs!$B$26,"Yes","No")) -> n/a | L13: =J13*IF(K13="No",Inputs!$B$27,1) -> 0 | M13: =SUMIFS('Deal Log'!$O$5:$O$64,'Deal Log'!$B$5:$B$64,A13) -> 0 | N13: =IF(Inputs!$B$28>0,MIN(M13*L13,Inputs!$B$28),M13*L13) -> 0
A14: 46600 | D14: =COUNTIFS('Deal Log'!$B$5:$B$64,A14) -> 0 | E14: =COUNTIFS('Deal Log'!$B$5:$B$64,A14,'Deal Log'!$H$5:$H$64,"<>Self-sourced") -> 0 | F14: =SUMIFS('Deal Log'!$E$5:$E$64,'Deal Log'!$B$5:$B$64,A14) -> 0 | G14: =IF(N(B14)=0,0,E14/B14) -> 0 | H14: =Inputs!$B$25 -> 6000 | I14: =IF(N(H14)=0,0,F14/H14) -> 0 | J14: =INDEX(Inputs!$B$34:$B$38,MATCH(I14,Inputs!$A$34:$A$38,1)) -> 0 | K14: =IF(N(B14)=0,"n/a",IF(G14>=Inputs!$B$26,"Yes","No")) -> n/a | L14: =J14*IF(K14="No",Inputs!$B$27,1) -> 0 | M14: =SUMIFS('Deal Log'!$O$5:$O$64,'Deal Log'!$B$5:$B$64,A14) -> 0 | N14: =IF(Inputs!$B$28>0,MIN(M14*L14,Inputs!$B$28),M14*L14) -> 0
A15: 46631 | D15: =COUNTIFS('Deal Log'!$B$5:$B$64,A15) -> 0 | E15: =COUNTIFS('Deal Log'!$B$5:$B$64,A15,'Deal Log'!$H$5:$H$64,"<>Self-sourced") -> 0 | F15: =SUMIFS('Deal Log'!$E$5:$E$64,'Deal Log'!$B$5:$B$64,A15) -> 0 | G15: =IF(N(B15)=0,0,E15/B15) -> 0 | H15: =Inputs!$B$25 -> 6000 | I15: =IF(N(H15)=0,0,F15/H15) -> 0 | J15: =INDEX(Inputs!$B$34:$B$38,MATCH(I15,Inputs!$A$34:$A$38,1)) -> 0 | K15: =IF(N(B15)=0,"n/a",IF(G15>=Inputs!$B$26,"Yes","No")) -> n/a | L15: =J15*IF(K15="No",Inputs!$B$27,1) -> 0 | M15: =SUMIFS('Deal Log'!$O$5:$O$64,'Deal Log'!$B$5:$B$64,A15) -> 0 | N15: =IF(Inputs!$B$28>0,MIN(M15*L15,Inputs!$B$28),M15*L15) -> 0
A16: 46661 | D16: =COUNTIFS('Deal Log'!$B$5:$B$64,A16) -> 0 | E16: =COUNTIFS('Deal Log'!$B$5:$B$64,A16,'Deal Log'!$H$5:$H$64,"<>Self-sourced") -> 0 | F16: =SUMIFS('Deal Log'!$E$5:$E$64,'Deal Log'!$B$5:$B$64,A16) -> 0 | G16: =IF(N(B16)=0,0,E16/B16) -> 0 | H16: =Inputs!$B$25 -> 6000 | I16: =IF(N(H16)=0,0,F16/H16) -> 0 | J16: =INDEX(Inputs!$B$34:$B$38,MATCH(I16,Inputs!$A$34:$A$38,1)) -> 0 | K16: =IF(N(B16)=0,"n/a",IF(G16>=Inputs!$B$26,"Yes","No")) -> n/a | L16: =J16*IF(K16="No",Inputs!$B$27,1) -> 0 | M16: =SUMIFS('Deal Log'!$O$5:$O$64,'Deal Log'!$B$5:$B$64,A16) -> 0 | N16: =IF(Inputs!$B$28>0,MIN(M16*L16,Inputs!$B$28),M16*L16) -> 0
A17: TOTAL | B17: =SUM(B5:B16) -> 115 | C17: =SUM(C5:C16) -> 26 | D17: =SUM(D5:D16) -> 6 | E17: =SUM(E5:E16) -> 4 | F17: =SUM(F5:F16) -> 7596.6 | G17: =IF(B17=0,0,E17/B17) -> 0.034782609 | H17: =SUM(H5:H16) -> 72000 | I17: =IF(H17=0,0,F17/H17) -> 0.10550833 | M17: =SUM(M5:M16) -> 9016.944 | N17: =SUM(N5:N16) -> 8057.904

Sheet Benchmarks
A1: Benchmarks – research behind the defaults
A2: Typical ranges from public SaaS comp surveys and comp-planning guides (e.g., Bridge Group SaaS AE reports, RepVue, Pavilion, Xactly/CaptivateIQ/Spiff plan guides). Treat as directional, not exact.
A4: Topic | B4: Typical SaaS practice | C4: How it's applied here
A5: Commission rate (full-cycle AE) | B5: ~8–12% of first-year ACV; ~10% is the common midpoint | C5: Self-sourced rates 10–14% by deal size
A6: Commission rate (closer on inbound) | B6: Lower than full-cycle, often ~5–8%, since lead-gen cost sits with marketing | C6: Inbound rates 6–8% by deal size
A7: Self-sourced premium | B7: +25–100% over inbound, or a separate SDR-style spiff | C7: Self-sourced ≈ 1.6–1.75x inbound; co-sourced in between
A8: Commission base | B8: First-year ACV (or ARR). Multi-year TCV is rarely fully commissioned | C8: Always Year-1 ACV = Net MRR × 12
A9: Multi-year deals | B9: Kicker of ~10–50% on yr-1 rate, or small % on out-years; more for upfront cash | C9: 1.30x upfront / 1.15x billed annually
A10: Annual contract, monthly billing | B10: Often paid as cash is collected, or at a reduced rate | C10: 0.75x, paid in two halves (month 1 and 6)
A11: Month-to-month | B11: Often no commission, or only after N months retained | C11: 0.40x, paid after 3rd payment
A12: Pay mix | B12: AEs ~50/50; hybrid / AM / non-quota roles ~70/30 or 80/20 | C12: 70/30 used for the OTE sanity check
A13: Quota threshold & accelerators | B13: No/partial payout below 50–70% attainment; accelerators 1.25–2x above 100% | C13: 0x <50%, 0.5x, 0.8x, 1.0x at target, 1.25x at 120%+
A14: Funnel conversion | B14: MQL→customer ~1–5% in B2B SaaS; demo/SQL→won ~20–30% | C14: MQL→won target 5% (calibrate to your data)
A15: Clawback | B15: 60–180 days if customer churns or doesn't pay | C15: 90 days
A16: Pay on cash vs booking | B16: Smaller companies usually pay on cash collected | C16: Paid on cash collected
