Workbook

Sheet Summary
A1: Account management at TripleDart: capacity and hiring plan
A2: Built 21 Oct 2026 from the Current Org Structure sheet. All numbers are formulas over the other tabs.
A4: Question | B4: Answer | C4: Where it comes from
A5: Engagements today (paid, SEO, RevOps) | B5: =Assumptions!$B$24 -> 73 | C5: Assumptions
A6: Unique client accounts in AM scope today (paid and SEO) | B6: =Capacity!B19 -> 55 | C6: Capacity, version 1
A7: Clients buying both paid and SEO | B7: =Capacity!B20 -> 8 | C7: Capacity, version 1
A8: Weighted units today | B8: =Capacity!B11 -> 61.75 | C8: Capacity, version 1
A9: Version 3, lean start: AMs to hire now | B9: =Capacity!B42+Capacity!B43 -> 3 | C9: Capacity, version 3
A10: Version 3: share of today's book covered | B10: =Capacity!E45 -> 0.70040486 | C10: Capacity, version 3
A11: Version 1: AMs for full coverage of today's book | B11: =Capacity!B16 -> 5 | C11: Capacity, version 1
A12: Version 2: AMs for 100 engagements | B12: =Capacity!B36 -> 7 | C12: Capacity, version 2
A13: Of which on US + Canada hours at 100 engagements | B13: =Capacity!B37 -> 2 | C13: Capacity, version 2
A14: Annual cost of the modelled stage, loaded ($) | B14: =Seats!L14 -> 247116.87 | C14: Seats
A15: Annual cost of the modelled stage (₹ lakh) | B15: =Seats!N14 -> 232.28986 | C15: Seats
A16: Coverage in Jan 2027 (modelled stage) | B16: ='Hiring Ramp'!D25 -> 0.41664934 | C16: Hiring Ramp
A17: Coverage in Apr 2027 (modelled stage) | B17: ='Hiring Ramp'!G25 -> 0.95495617 | C17: Hiring Ramp
A18: India AM pay: fixed + variable at target (₹ lakh) | B18: =Assumptions!$B$38+Assumptions!$B$39 -> 25 | C18: Assumptions
A20: How to use this workbook
A21: Change inputs only on the Assumptions tab (blue text). Yellow cells are the assumptions to confirm first.
A22: Add or remove clients on the Client Book tab: copy a row, then type the account, service line, pod, owner, region, MRR and status.
A23: Set "Hiring stage to model" on Assumptions to 1, 2 or 3 to see the ramp and cost for each version.
A24: RevOps is out of AM scope by default. Set the RevOps switch on Assumptions to 1 to include it.

Sheet Assumptions
A1: Assumptions
A2: Blue text = input you can change. Yellow fill = key assumption to confirm. Every other tab reads from here.
A4: Assumption | B4: Value | C4: Why this number / source
A5: Capacity: how much one account manager can carry
A6: Target weighted units per ramped AM | B6: 13 | C6: One unit = one mid-size, single-service retainer. 13 units is about 12-15 accounts. Pods and PMs run delivery, so the AM owns relationship, retention and expansion only. ThunderClap AMs carry 5-6 design projects because they also run delivery.
A7: Stretch units per AM (short periods only) | B7: 16 | C7: Ceiling during onboarding spikes. Above this, 1:1s and expansion work stop happening.
A8: Weight: Enterprise retainer | B8: 1.5 | C8: More stakeholders, monthly business reviews, more expansion surface.
A9: Weight: Mid retainer | B9: 1 | C9: Baseline unit.
A10: Weight: Starter retainer | B10: 0.75 | C10: Smaller scope, fewer stakeholders.
A11: Enterprise threshold, MRR per service line ($) | B11: 7000 | C11: Paid roster tags $7K+ as tier 1.
A12: Mid threshold, MRR per service line ($) | B12: 4000 | C12: Paid roster flags under $4K as below the price floor.
A13: Factor for a second service line on the same account | B13: 0.5 | C13: A full-service client is one relationship. The second line adds half its weight, not a full account.
A14: Onboarding add-on per new engagement (first 60 days) | B14: 0.5 | C14: Kickoff, questionnaire, dashboard, POC 1:1s. Applies to signed-not-started deals and every new engagement in the ramp.
A15: Units the Head of AM carries personally | B15: 6 | C15: Gayu keeps a small book (tier-1 and full-service accounts) so she stays close to clients. Rest of her time: team, process, escalations.
A16: Account MRR at which the Head of AM owns the account ($) | B16: 12000 | C16: Accounts at or above this combined MRR (across all service lines) sit with the Head of AM. Today: Atlas and GE Appliances.
A17: Service lines in scope
A18: Include RevOps in AM coverage? (1 = yes, 0 = no) | B18: 0 | C18: User direction: RevOps stays as it is for now (JK owns). Switch to 1 to see the extra AM load.
A19: RevOps engagements today | B19: 10 | C19: Source: Current Org Structure sheet, Revops tab, Oct 2026.
A20: RevOps MRR today ($) | B20: 50000 | C20: Source: Current Org Structure sheet, Revops tab, Oct 2026.
A21: Weight per RevOps engagement | B21: 1 | C21: Treated as a mid retainer until the RevOps client list is added.
A22: Share of untagged SEO accounts that need US hours | B22: 0.3 | C22: 14 SEO accounts have no region tag yet. Manoj to tag them; this split is a placeholder.
A23: Growth: path to 100 engagements
A24: Engagements today (paid + SEO rows in Client Book, plus RevOps) | B24: =COUNTA('Client Book'!A6:A68)+B19 -> 73 | C24: Counts service-line engagements, so a client buying paid and SEO counts twice.
A25: Target engagements | B25: 100 | C25: User direction: 100 engagements.
A26: Months to reach the target | B26: 2 | C26: User direction: next 2 months (Nov and Dec 2026).
A27: New engagements per month after the target | B27: 4 | C27: Placeholder. Replace with the HubSpot run-rate.
A28: Ramp of a new account manager
A29: Capacity in month 1 | B29: 0.4 | C29: Shadowing and immersion (see the onboarding plan, weeks 1-2).
A30: Capacity in month 2 | B30: 0.7 | C30: Takes over the first book (weeks 3-6).
A31: Capacity from month 3 | B31: 1 | C31: Full book.
A32: Pay and currency
A33: INR per USD | B33: 94 | C33: Same FX as the TripleDart investment model.
A34: CAD per USD | B34: 1.38 | C34: Approximate, Oct 2026. Update before an offer.
A35: ZAR per USD | B35: 18 | C35: Approximate, Oct 2026. Update before an offer.
A36: Employer load, India payroll | B36: 0.04 | C36: Same as the investment model.
A37: Employer load, Canada or South Africa (EOR or contractor) | B37: 0.12 | C37: Same as the investment model for USD roles. An EOR fee may add more.
A38: India AM fixed pay (₹ lakh a year) | B38: 15 | C38: User direction: up to ₹15L fixed, depending on the person.
A39: India AM variable at 100% of target (₹ lakh a year) | B39: 10 | C39: User direction: try for up to ₹10L variable.
A40: Canada AM fixed pay (CAD a year) | B40: 75000 | C40: Estimate for a mid-level agency AM in Toronto. Check against offers.
A41: Canada AM variable at target (CAD a year) | B41: 25000 | C41: Estimate. Same plan design as India.
...

Sheet Client Book
A1: Client book: every paid and SEO engagement today
A2: One row per service-line engagement. Black columns are formulas. RevOps client names are not in the source sheet, so RevOps is counted in Assumptions.
A3: Sorted by service line, then pod. Accounts that appear twice buy more than one service.
A5: Account | B5: Name in roster | C5: Service line | D5: Pod | E5: Relationship owner today | F5: Region | G5: Shift | H5: MRR ($) | I5: Status | J5: Health flag | K5: Tier | L5: Base weight | M5: Rank within account | N5: Line role | O5: Weighted units | P5: Account MRR, all lines ($) | Q5: Proposed owner
A6: CleverTap | B6: Clevertap | C6: Paid media | D6: Bas | E6: Sabari | F6: India | G6: =IF(OR(F6="US",F6="US + Canada"),"US + Canada",IF(F6="Untagged","Untagged","India + RoW")) -> India + RoW | H6: 5000 | I6: Live | K6: =IF(H6>=Assumptions!$B$11,"Enterprise",IF(H6>=Assumptions!$B$12,"Mid","Starter")) -> Mid | L6: =IF(K6="Enterprise",Assumptions!$B$8,IF(K6="Mid",Assumptions!$B$9,Assumptions!$B$10)) -> 1 | M6: =COUNTIFS($A$6:$A$68,A6,$H$6:$H$68,">"&H6)+COUNTIFS($A$5:A5,A6,$H$5:H5,H6) -> 0 | N6: =IF(M6=0,"Primary line","Second line") -> Primary line | O6: =L6*IF(M6=0,1,Assumptions!$B$13)+IF(I6="Signed, not started",Assumptions!$B$14,0) -> 1 | P6: =SUMIFS($H$6:$H$68,$A$6:$A$68,A6) -> 5000 | Q6: =IF(P6>=Assumptions!$B$16,"Head of AM (Gayu)",IF(M6>0,"Same AM as the primary line",IF(G6="US + Canada","AM, US + Canada (test hire)",IF(C6="Paid media","AM, Paid Media, India + RoW","AM, SEO and GEO, India + RoW")))) -> AM, Paid Media, India + RoW
A7: TimeDoctor | B7: TimeDoctor | C7: Paid media | D7: Bas | E7: SN | F7: US | G7: =IF(OR(F7="US",F7="US + Canada"),"US + Canada",IF(F7="Untagged","Untagged","India + RoW")) -> US + Canada | H7: 4000 | I7: Live | K7: =IF(H7>=Assumptions!$B$11,"Enterprise",IF(H7>=Assumptions!$B$12,"Mid","Starter")) -> Mid | L7: =IF(K7="Enterprise",Assumptions!$B$8,IF(K7="Mid",Assumptions!$B$9,Assumptions!$B$10)) -> 1 | M7: =COUNTIFS($A$6:$A$68,A7,$H$6:$H$68,">"&H7)+COUNTIFS($A$5:A6,A7,$H$5:H6,H7) -> 0 | N7: =IF(M7=0,"Primary line","Second line") -> Primary line | O7: =L7*IF(M7=0,1,Assumptions!$B$13)+IF(I7="Signed, not started",Assumptions!$B$14,0) -> 1 | P7: =SUMIFS($H$6:$H$68,$A$6:$A$68,A7) -> 4000 | Q7: =IF(P7>=Assumptions!$B$16,"Head of AM (Gayu)",IF(M7>0,"Same AM as the primary line",IF(G7="US + Canada","AM, US + Canada (test hire)",IF(C7="Paid media","AM, Paid Media, India + RoW","AM, SEO and GEO, India + RoW")))) -> AM, US + Canada (test hire)
A8: MakeMyTrip | B8: Makemytrip | C8: Paid media | D8: Bas | E8: Sabari | F8: India | G8: =IF(OR(F8="US",F8="US + Canada"),"US + Canada",IF(F8="Untagged","Untagged","India + RoW")) -> India + RoW | H8: 5000 | I8: Live | K8: =IF(H8>=Assumptions!$B$11,"Enterprise",IF(H8>=Assumptions!$B$12,"Mid","Starter")) -> Mid | L8: =IF(K8="Enterprise",Assumptions!$B$8,IF(K8="Mid",Assumptions!$B$9,Assumptions!$B$10)) -> 1 | M8: =COUNTIFS($A$6:$A$68,A8,$H$6:$H$68,">"&H8)+COUNTIFS($A$5:A7,A8,$H$5:H7,H8) -> 0 | N8: =IF(M8=0,"Primary line","Second line") -> Primary line | O8: =L8*IF(M8=0,1,Assumptions!$B$13)+IF(I8="Signed, not started",Assumptions!$B$14,0) -> 1 | P8: =SUMIFS($H$6:$H$68,$A$6:$A$68,A8) -> 5000 | Q8: =IF(P8>=Assumptions!$B$16,"Head of AM (Gayu)",IF(M8>0,"Same AM as the primary line",IF(G8="US + Canada","AM, US + Canada (test hire)",IF(C8="Paid media","AM, Paid Media, India + RoW","AM, SEO and GEO, India + RoW")))) -> AM, Paid Media, India + RoW
A9: Lightyear | B9: Lightyear | C9: Paid media | D9: Bas | E9: SN | F9: US | G9: =IF(OR(F9="US",F9="US + Canada"),"US + Canada",IF(F9="Untagged","Untagged","India + RoW")) -> US + Canada | H9: 5500 | I9: Live | K9: =IF(H9>=Assumptions!$B$11,"Enterprise",IF(H9>=Assumptions!$B$12,"Mid","Starter")) -> Mid | L9: =IF(K9="Enterprise",Assumptions!$B$8,IF(K9="Mid",Assumptions!$B$9,Assumptions!$B$10)) -> 1 | M9: =COUNTIFS($A$6:$A$68,A9,$H$6:$H$68,">"&H9)+COUNTIFS($A$5:A8,A9,$H$5:H8,H9) -> 0 | N9: =IF(M9=0,"Primary line","Second line") -> Primary line | O9: =L9*IF(M9=0,1,Assumptions!$B$13)+IF(I9="Signed, not started",Assumptions!$B$14,0) -> 1 | P9: =SUMIFS($H$6:$H$68,$A$6:$A$68,A9) -> 5500 | Q9: =IF(P9>=Assumptions!$B$16,"Head of AM (Gayu)",IF(M9>0,"Same AM as the primary line",IF(G9="US + Canada","AM, US + Canada (test hire)",IF(C9="Paid media","AM, Paid Media, India + RoW","AM, SEO and GEO, India + RoW")))) -> AM, US + Canada (test hire)
A10: EmailOctopus | B10: EmailOctopus | C10: Paid media | D10: Bas | E10: SN | F10: EU | G10: =IF(OR(F10="US",F10="US + Canada"),"US + Canada",IF(F10="Untagged","Untagged","India + RoW")) -> India + RoW | H10: 4950 | I10: Live | K10: =IF(H10>=Assumptions!$B$11,"Enterprise",IF(H10>=Assumptions!$B$12,"Mid","Starter")) -> Mid | L10: =IF(K10="Enterprise",Assumptions!$B$8,IF(K10="Mid",Assumptions!$B$9,Assumptions!$B$10)) -> 1 | M10: =COUNTIFS($A$6:$A$68,A10,$H$6:$H$68,">"&H10)+COUNTIFS($A$5:A9,A10,$H$5:H9,H10) -> 0 | N10: =IF(M10=0,"Primary line","Second line") -> Primary line | O10: =L10*IF(M10=0,1,Assumptions!$B$13)+IF(I10="Signed, not started",Assumptions!$B$14,0) -> 1 | P10: =SUMIFS($H$6:$H$68,$A$6:$A$68,A10) -> 4950 | Q10: =IF(P10>=Assumptions!$B$16,"Head of AM (Gayu)",IF(M10>0,"Same AM as the primary line",IF(G10="US + Canada","AM, US + Canada (test hire)",IF(C10="Paid media","AM, Paid Media, India + RoW","AM, SEO and GEO, India + RoW")))) -> AM, Paid Media, India + RoW
A11: VWO | B11: VWO (Wingify) | C11: Paid media | D11: Bas | E11: Sabari | F11: India | G11: =IF(OR(F11="US",F11="US + Canada"),"US + Canada",IF(F11="Untagged","Untagged","India + RoW")) -> India + RoW | H11: 9000 | I11: Live | K11: =IF(H11>=Assumptions!$B$11,"Enterprise",IF(H11>=Assumptions!$B$12,"Mid","Starter")) -> Enterprise | L11: =IF(K11="Enterprise",Assumptions!$B$8,IF(K11="Mid",Assumptions!$B$9,Assumptions!$B$10)) -> 1.5 | M11: =COUNTIFS($A$6:$A$68,A11,$H$6:$H$68,">"&H11)+COUNTIFS($A$5:A10,A11,$H$5:H10,H11) -> 0 | N11: =IF(M11=0,"Primary line","Second line") -> Primary line | O11: =L11*IF(M11=0,1,Assumptions!$B$13)+IF(I11="Signed, not started",Assumptions!$B$14,0) -> 1.5 | P11: =SUMIFS($H$6:$H$68,$A$6:$A$68,A11) -> 9000 | Q11: =IF(P11>=Assumptions!$B$16,"Head of AM (Gayu)",IF(M11>0,"Same AM as the primary line",IF(G11="US + Canada","AM, US + Canada (test hire)",IF(C11="Paid media","AM, Paid Media, India + RoW","AM, SEO and GEO, India + RoW")))) -> AM, Paid Media, India + RoW
A12: CoramAI | B12: CoramAI | C12: Paid media | D12: Bas | E12: Sabari | F12: India | G12: =IF(OR(F12="US",F12="US + Canada"),"US + Canada",IF(F12="Untagged","Untagged","India + RoW")) -> India + RoW | H12: 3500 | I12: Live | J12: Below price floor | K12: =IF(H12>=Assumptions!$B$11,"Enterprise",IF(H12>=Assumptions!$B$12,"Mid","Starter")) -> Starter | L12: =IF(K12="Enterprise",Assumptions!$B$8,IF(K12="Mid",Assumptions!$B$9,Assumptions!$B$10)) -> 0.75 | M12: =COUNTIFS($A$6:$A$68,A12,$H$6:$H$68,">"&H12)+COUNTIFS($A$5:A11,A12,$H$5:H11,H12) -> 0 | N12: =IF(M12=0,"Primary line","Second line") -> Primary line | O12: =L12*IF(M12=0,1,Assumptions!$B$13)+IF(I12="Signed, not started",Assumptions!$B$14,0) -> 0.75 | P12: =SUMIFS($H$6:$H$68,$A$6:$A$68,A12) -> 3500 | Q12: =IF(P12>=Assumptions!$B$16,"Head of AM (Gayu)",IF(M12>0,"Same AM as the primary line",IF(G12="US + Canada","AM, US + Canada (test hire)",IF(C12="Paid media","AM, Paid Media, India + RoW","AM, SEO and GEO, India + RoW")))) -> AM, Paid Media, India + RoW
A13: JoinBrands | B13: JoinBrands | C13: Paid media | D13: Srushti | E13: Sabari | F13: US | G13: =IF(OR(F13="US",F13="US + Canada"),"US + Canada",IF(F13="Untagged","Untagged","India + RoW")) -> US + Canada | H13: 4000 | I13: Live | K13: =IF(H13>=Assumptions!$B$11,"Enterprise",IF(H13>=Assumptions!$B$12,"Mid","Starter")) -> Mid | L13: =IF(K13="Enterprise",Assumptions!$B$8,IF(K13="Mid",Assumptions!$B$9,Assumptions!$B$10)) -> 1 | M13: =COUNTIFS($A$6:$A$68,A13,$H$6:$H$68,">"&H13)+COUNTIFS($A$5:A12,A13,$H$5:H12,H13) -> 0 | N13: =IF(M13=0,"Primary line","Second line") -> Primary line | O13: =L13*IF(M13=0,1,Assumptions!$B$13)+IF(I13="Signed, not started",Assumptions!$B$14,0) -> 1 | P13: =SUMIFS($H$6:$H$68,$A$6:$A$68,A13) -> 4000 | Q13: =IF(P13>=Assumptions!$B$16,"Head of AM (Gayu)",IF(M13>0,"Same AM as the primary line",IF(G13="US + Canada","AM, US + Canada (test hire)",IF(C13="Paid media","AM, Paid Media, India + RoW","AM, SEO and GEO, India + RoW")))) -> AM, US + Canada (test hire)
A14: Edmingle | B14: Edmingle | C14: Paid media | D14: Srushti | E14: Sabari | F14: India | G14: =IF(OR(F14="US",F14="US + Canada"),"US + Canada",IF(F14="Untagged","Untagged","India + RoW")) -> India + RoW | H14: 3000 | I14: Live | J14: Below price floor | K14: =IF(H14>=Assumptions!$B$11,"Enterprise",IF(H14>=Assumptions!$B$12,"Mid","Starter")) -> Starter | L14: =IF(K14="Enterprise",Assumptions!$B$8,IF(K14="Mid",Assumptions!$B$9,Assumptions!$B$10)) -> 0.75 | M14: =COUNTIFS($A$6:$A$68,A14,$H$6:$H$68,">"&H14)+COUNTIFS($A$5:A13,A14,$H$5:H13,H14) -> 0 | N14: =IF(M14=0,"Primary line","Second line") -> Primary line | O14: =L14*IF(M14=0,1,Assumptions!$B$13)+IF(I14="Signed, not started",Assumptions!$B$14,0) -> 0.75 | P14: =SUMIFS($H$6:$H$68,$A$6:$A$68,A14) -> 6000 | Q14: =IF(P14>=Assumptions!$B$16,"Head of AM (Gayu)",IF(M14>0,"Same AM as the primary line",IF(G14="US + Canada","AM, US + Canada (test hire)",IF(C14="Paid media","AM, Paid Media, India + RoW","AM, SEO and GEO, India + RoW")))) -> AM, Paid Media, India + RoW
A15: Datachannel | B15: Datachannel | C15: Paid media | D15: Srushti | E15: Sabari | F15: India | G15: =IF(OR(F15="US",F15="US + Canada"),"US + Canada",IF(F15="Untagged","Untagged","India + RoW")) -> India + RoW | H15: 2000 | I15: Live | J15: Below price floor | K15: =IF(H15>=Assumptions!$B$11,"Enterprise",IF(H15>=Assumptions!$B$12,"Mid","Starter")) -> Starter | L15: =IF(K15="Enterprise",Assumptions!$B$8,IF(K15="Mid",Assumptions!$B$9,Assumptions!$B$10)) -> 0.75 | M15: =COUNTIFS($A$6:$A$68,A15,$H$6:$H$68,">"&H15)+COUNTIFS($A$5:A14,A15,$H$5:H14,H15) -> 0 | N15: =IF(M15=0,"Primary line","Second line") -> Primary line | O15: =L15*IF(M15=0,1,Assumptions!$B$13)+IF(I15="Signed, not started",Assumptions!$B$14,0) -> 0.75 | P15: =SUMIFS($H$6:$H$68,$A$6:$A$68,A15) -> 2000 | Q15: =IF(P15>=Assumptions!$B$16,"Head of AM (Gayu)",IF(M15>0,"Same AM as the primary line",IF(G15="US + Canada","AM, US + Canada (test hire)",IF(C15="Paid media","AM, Paid Media, India + RoW","AM, SEO and GEO, India + RoW")))) -> AM, Paid Media, India + RoW
A16: Payoneer | B16: Payoneer | C16: Paid media | D16: Srushti | E16: Sabari | F16: MEA | G16: =IF(OR(F16="US",F16="US + Canada"),"US + Canada",IF(F16="Untagged","Untagged","India + RoW")) -> India + RoW | H16: 7000 | I16: Live | K16: =IF(H16>=Assumptions!$B$11,"Enterprise",IF(H16>=Assumptions!$B$12,"Mid","Starter")) -> Enterprise | L16: =IF(K16="Enterprise",Assumptions!$B$8,IF(K16="Mid",Assumptions!$B$9,Assumptions!$B$10)) -> 1.5 | M16: =COUNTIFS($A$6:$A$68,A16,$H$6:$H$68,">"&H16)+COUNTIFS($A$5:A15,A16,$H$5:H15,H16) -> 0 | N16: =IF(M16=0,"Primary line","Second line") -> Primary line | O16: =L16*IF(M16=0,1,Assumptions!$B$13)+IF(I16="Signed, not started",Assumptions!$B$14,0) -> 1.5 | P16: =SUMIFS($H$6:$H$68,$A$6:$A$68,A16) -> 7000 | Q16: =IF(P16>=Assumptions!$B$16,"Head of AM (Gayu)",IF(M16>0,"Same AM as the primary line",IF(G16="US + Canada","AM, US + Canada (test hire)",IF(C16="Paid media","AM, Paid Media, India + RoW","AM, SEO and GEO, India + RoW")))) -> AM, Paid Media, India + RoW
A17: RTS Labs | B17: RTS Labs | C17: Paid media | D17: Srushti | E17: Sabari | F17: India | G17: =IF(OR(F17="US",F17="US + Canada"),"US + Canada",IF(F17="Untagged","Untagged","India + RoW")) -> India + RoW | H17: 2500 | I17: Live | J17: Below price floor | K17: =IF(H17>=Assumptions!$B$11,"Enterprise",IF(H17>=Assumptions!$B$12,"Mid","Starter")) -> Starter | L17: =IF(K17="Enterprise",Assumptions!$B$8,IF(K17="Mid",Assumptions!$B$9,Assumptions!$B$10)) -> 0.75 | M17: =COUNTIFS($A$6:$A$68,A17,$H$6:$H$68,">"&H17)+COUNTIFS($A$5:A16,A17,$H$5:H16,H17) -> 1 | N17: =IF(M17=0,"Primary line","Second line") -> Second line | O17: =L17*IF(M17=0,1,Assumptions!$B$13)+IF(I17="Signed, not started",Assumptions!$B$14,0) -> 0.375 | P17: =SUMIFS($H$6:$H$68,$A$6:$A$68,A17) -> 7500 | Q17: =IF(P17>=Assumptions!$B$16,"Head of AM (Gayu)",IF(M17>0,"Same AM as the primary line",IF(G17="US + Canada","AM, US + Canada (test hire)",IF(C17="Paid media","AM, Paid Media, India + RoW","AM, SEO and GEO, India + RoW")))) -> Same AM as the primary line
A18: TraqCheck | B18: TraqCheck | C18: Paid media | D18: Srushti | E18: Sabari | F18: EU | G18: =IF(OR(F18="US",F18="US + Canada"),"US + Canada",IF(F18="Untagged","Untagged","India + RoW")) -> India + RoW | H18: 4500 | I18: Live | K18: =IF(H18>=Assumptions!$B$11,"Enterprise",IF(H18>=Assumptions!$B$12,"Mid","Starter")) -> Mid | L18: =IF(K18="Enterprise",Assumptions!$B$8,IF(K18="Mid",Assumptions!$B$9,Assumptions!$B$10)) -> 1 | M18: =COUNTIFS($A$6:$A$68,A18,$H$6:$H$68,">"&H18)+COUNTIFS($A$5:A17,A18,$H$5:H17,H18) -> 0 | N18: =IF(M18=0,"Primary line","Second line") -> Primary line | O18: =L18*IF(M18=0,1,Assumptions!$B$13)+IF(I18="Signed, not started",Assumptions!$B$14,0) -> 1 | P18: =SUMIFS($H$6:$H$68,$A$6:$A$68,A18) -> 4500 | Q18: =IF(P18>=Assumptions!$B$16,"Head of AM (Gayu)",IF(M18>0,"Same AM as the primary line",IF(G18="US + Canada","AM, US + Canada (test hire)",IF(C18="Paid media","AM, Paid Media, India + RoW","AM, SEO and GEO, India + RoW")))) -> AM, Paid Media, India + RoW
A19: Numera | B19: Numera | C19: Paid media | D19: Srushti | E19: Sabari | F19: US | G19: =IF(OR(F19="US",F19="US + Canada"),"US + Canada",IF(F19="Untagged","Untagged","India + RoW")) -> US + Canada | H19: 5000 | I19: Live | K19: =IF(H19>=Assumptions!$B$11,"Enterprise",IF(H19>=Assumptions!$B$12,"Mid","Starter")) -> Mid | L19: =IF(K19="Enterprise",Assumptions!$B$8,IF(K19="Mid",Assumptions!$B$9,Assumptions!$B$10)) -> 1 | M19: =COUNTIFS($A$6:$A$68,A19,$H$6:$H$68,">"&H19)+COUNTIFS($A$5:A18,A19,$H$5:H18,H19) -> 0 | N19: =IF(M19=0,"Primary line","Second line") -> Primary line | O19: =L19*IF(M19=0,1,Assumptions!$B$13)+IF(I19="Signed, not started",Assumptions!$B$14,0) -> 1 | P19: =SUMIFS($H$6:$H$68,$A$6:$A$68,A19) -> 5000 | Q19: =IF(P19>=Assumptions!$B$16,"Head of AM (Gayu)",IF(M19>0,"Same AM as the primary line",IF(G19="US + Canada","AM, US + Canada (test hire)",IF(C19="Paid media","AM, Paid Media, India + RoW","AM, SEO and GEO, India + RoW")))) -> AM, US + Canada (test hire)
A20: DataMoon | B20: DataMoon | C20: Paid media | D20: Shony | E20: SN | F20: US | G20: =IF(OR(F20="US",F20="US + Canada"),"US + Canada",IF(F20="Untagged","Untagged","India + RoW")) -> US + Canada | H20: 6000 | I20: Live | K20: =IF(H20>=Assumptions!$B$11,"Enterprise",IF(H20>=Assumptions!$B$12,"Mid","Starter")) -> Mid | L20: =IF(K20="Enterprise",Assumptions!$B$8,IF(K20="Mid",Assumptions!$B$9,Assumptions!$B$10)) -> 1 | M20: =COUNTIFS($A$6:$A$68,A20,$H$6:$H$68,">"&H20)+COUNTIFS($A$5:A19,A20,$H$5:H19,H20) -> 0 | N20: =IF(M20=0,"Primary line","Second line") -> Primary line | O20: =L20*IF(M20=0,1,Assumptions!$B$13)+IF(I20="Signed, not started",Assumptions!$B$14,0) -> 1 | P20: =SUMIFS($H$6:$H$68,$A$6:$A$68,A20) -> 6000 | Q20: =IF(P20>=Assumptions!$B$16,"Head of AM (Gayu)",IF(M20>0,"Same AM as the primary line",IF(G20="US + Canada","AM, US + Canada (test hire)",IF(C20="Paid media","AM, Paid Media, India + RoW","AM, SEO and GEO, India + RoW")))) -> AM, US + Canada (test hire)
A21: GE Appliances | B21: GEAppliances | C21: Paid media | D21: Shony | E21: Sabari | F21: US | G21: =IF(OR(F21="US",F21="US + Canada"),"US + Canada",IF(F21="Untagged","Untagged","India + RoW")) -> US + Canada | H21: 6000 | I21: Live | K21: =IF(H21>=Assumptions!$B$11,"Enterprise",IF(H21>=Assumptions!$B$12,"Mid","Starter")) -> Mid | L21: =IF(K21="Enterprise",Assumptions!$B$8,IF(K21="Mid",Assumptions!$B$9,Assumptions!$B$10)) -> 1 | M21: =COUNTIFS($A$6:$A$68,A21,$H$6:$H$68,">"&H21)+COUNTIFS($A$5:A20,A21,$H$5:H20,H21) -> 1 | N21: =IF(M21=0,"Primary line","Second line") -> Second line | O21: =L21*IF(M21=0,1,Assumptions!$B$13)+IF(I21="Signed, not started",Assumptions!$B$14,0) -> 0.5 | P21: =SUMIFS($H$6:$H$68,$A$6:$A$68,A21) -> 14000 | Q21: =IF(P21>=Assumptions!$B$16,"Head of AM (Gayu)",IF(M21>0,"Same AM as the primary line",IF(G21="US + Canada","AM, US + Canada (test hire)",IF(C21="Paid media","AM, Paid Media, India + RoW","AM, SEO and GEO, India + RoW")))) -> Head of AM (Gayu)
A22: Atlas | B22: Atlas | C22: Paid media | D22: Shony | E22: SN | F22: US | G22: =IF(OR(F22="US",F22="US + Canada"),"US + Canada",IF(F22="Untagged","Untagged","India + RoW")) -> US + Canada | H22: 12000 | I22: Live | K22: =IF(H22>=Assumptions!$B$11,"Enterprise",IF(H22>=Assumptions!$B$12,"Mid","Starter")) -> Enterprise | L22: =IF(K22="Enterprise",Assumptions!$B$8,IF(K22="Mid",Assumptions!$B$9,Assumptions!$B$10)) -> 1.5 | M22: =COUNTIFS($A$6:$A$68,A22,$H$6:$H$68,">"&H22)+COUNTIFS($A$5:A21,A22,$H$5:H21,H22) -> 0 | N22: =IF(M22=0,"Primary line","Second line") -> Primary line | O22: =L22*IF(M22=0,1,Assumptions!$B$13)+IF(I22="Signed, not started",Assumptions!$B$14,0) -> 1.5 | P22: =SUMIFS($H$6:$H$68,$A$6:$A$68,A22) -> 19000 | Q22: =IF(P22>=Assumptions!$B$16,"Head of AM (Gayu)",IF(M22>0,"Same AM as the primary line",IF(G22="US + Canada","AM, US + Canada (test hire)",IF(C22="Paid media","AM, Paid Media, India + RoW","AM, SEO and GEO, India + RoW")))) -> Head of AM (Gayu)
A23: AccuSource | B23: AccuSourceHR | C23: Paid media | D23: Shony | E23: SN | F23: US | G23: =IF(OR(F23="US",F23="US + Canada"),"US + Canada",IF(F23="Untagged","Untagged","India + RoW")) -> US + Canada | H23: 3000 | I23: Live | J23: Below price floor | K23: =IF(H23>=Assumptions!$B$11,"Enterprise",IF(H23>=Assumptions!$B$12,"Mid","Starter")) -> Starter | L23: =IF(K23="Enterprise",Assumptions!$B$8,IF(K23="Mid",Assumptions!$B$9,Assumptions!$B$10)) -> 0.75 | M23: =COUNTIFS($A$6:$A$68,A23,$H$6:$H$68,">"&H23)+COUNTIFS($A$5:A22,A23,$H$5:H22,H23) -> 1 | N23: =IF(M23=0,"Primary line","Second line") -> Second line | O23: =L23*IF(M23=0,1,Assumptions!$B$13)+IF(I23="Signed, not started",Assumptions!$B$14,0) -> 0.375 | P23: =SUMIFS($H$6:$H$68,$A$6:$A$68,A23) -> 7000 | Q23: =IF(P23>=Assumptions!$B$16,"Head of AM (Gayu)",IF(M23>0,"Same AM as the primary line",IF(G23="US + Canada","AM, US + Canada (test hire)",IF(C23="Paid media","AM, Paid Media, India + RoW","AM, SEO and GEO, India + RoW")))) -> Same AM as the primary line
A24: Sirion | B24: Sirion | C24: Paid media | D24: Shony | E24: Sabari | F24: India | G24: =IF(OR(F24="US",F24="US + Canada"),"US + Canada",IF(F24="Untagged","Untagged","India + RoW")) -> India + RoW | H24: 4500 | I24: Signed, not started | K24: =IF(H24>=Assumptions!$B$11,"Enterprise",IF(H24>=Assumptions!$B$12,"Mid","Starter")) -> Mid | L24: =IF(K24="Enterprise",Assumptions!$B$8,IF(K24="Mid",Assumptions!$B$9,Assumptions!$B$10)) -> 1 | M24: =COUNTIFS($A$6:$A$68,A24,$H$6:$H$68,">"&H24)+COUNTIFS($A$5:A23,A24,$H$5:H23,H24) -> 0 | N24: =IF(M24=0,"Primary line","Second line") -> Primary line | O24: =L24*IF(M24=0,1,Assumptions!$B$13)+IF(I24="Signed, not started",Assumptions!$B$14,0) -> 1.5 | P24: =SUMIFS($H$6:$H$68,$A$6:$A$68,A24) -> 4500 | Q24: =IF(P24>=Assumptions!$B$16,"Head of AM (Gayu)",IF(M24>0,"Same AM as the primary line",IF(G24="US + Canada","AM, US + Canada (test hire)",IF(C24="Paid media","AM, Paid Media, India + RoW","AM, SEO and GEO, India + RoW")))) -> AM, Paid Media, India + RoW
A25: Yanolja Cloud | B25: Yanoljacloudsolution | C25: Paid media | D25: Sabari direct | E25: Sabari | F25: India | G25: =IF(OR(F25="US",F25="US + Canada"),"US + Canada",IF(F25="Untagged","Untagged","India + RoW")) -> India + RoW | H25: 4000 | I25: Live | K25: =IF(H25>=Assumptions!$B$11,"Enterprise",IF(H25>=Assumptions!$B$12,"Mid","Starter")) -> Mid | L25: =IF(K25="Enterprise",Assumptions!$B$8,IF(K25="Mid",Assumptions!$B$9,Assumptions!$B$10)) -> 1 | M25: =COUNTIFS($A$6:$A$68,A25,$H$6:$H$68,">"&H25)+COUNTIFS($A$5:A24,A25,$H$5:H24,H25) -> 0 | N25: =IF(M25=0,"Primary line","Second line") -> Primary line | O25: =L25*IF(M25=0,1,Assumptions!$B$13)+IF(I25="Signed, not started",Assumptions!$B$14,0) -> 1 | P25: =SUMIFS($H$6:$H$68,$A$6:$A$68,A25) -> 4000 | Q25: =IF(P25>=Assumptions!$B$16,"Head of AM (Gayu)",IF(M25>0,"Same AM as the primary line",IF(G25="US + Canada","AM, US + Canada (test hire)",IF(C25="Paid media","AM, Paid Media, India + RoW","AM, SEO and GEO, India + RoW")))) -> AM, Paid Media, India + RoW
A26: Restolabs | B26: Restolabs | C26: Paid media | D26: Sabari direct | E26: Sabari | F26: India | G26: =IF(OR(F26="US",F26="US + Canada"),"US + Canada",IF(F26="Untagged","Untagged","India + RoW")) -> India + RoW | H26: 3000 | I26: Live | J26: Below price floor | K26: =IF(H26>=Assumptions!$B$11,"Enterprise",IF(H26>=Assumptions!$B$12,"Mid","Starter")) -> Starter | L26: =IF(K26="Enterprise",Assumptions!$B$8,IF(K26="Mid",Assumptions!$B$9,Assumptions!$B$10)) -> 0.75 | M26: =COUNTIFS($A$6:$A$68,A26,$H$6:$H$68,">"&H26)+COUNTIFS($A$5:A25,A26,$H$5:H25,H26) -> 0 | N26: =IF(M26=0,"Primary line","Second line") -> Primary line | O26: =L26*IF(M26=0,1,Assumptions!$B$13)+IF(I26="Signed, not started",Assumptions!$B$14,0) -> 0.75 | P26: =SUMIFS($H$6:$H$68,$A$6:$A$68,A26) -> 6000 | Q26: =IF(P26>=Assumptions!$B$16,"Head of AM (Gayu)",IF(M26>0,"Same AM as the primary line",IF(G26="US + Canada","AM, US + Canada (test hire)",IF(C26="Paid media","AM, Paid Media, India + RoW","AM, SEO and GEO, India + RoW")))) -> AM, Paid Media, India + RoW
A27: Fyle | B27: Fyle | C27: Paid media | D27: Raghu | E27: Mahesh | F27: India | G27: =IF(OR(F27="US",F27="US + Canada"),"US + Canada",IF(F27="Untagged","Untagged","India + RoW")) -> India + RoW | H27: 5000 | I27: Live | K27: =IF(H27>=Assumptions!$B$11,"Enterprise",IF(H27>=Assumptions!$B$12,"Mid","Starter")) -> Mid | L27: =IF(K27="Enterprise",Assumptions!$B$8,IF(K27="Mid",Assumptions!$B$9,Assumptions!$B$10)) -> 1 | M27: =COUNTIFS($A$6:$A$68,A27,$H$6:$H$68,">"&H27)+COUNTIFS($A$5:A26,A27,$H$5:H26,H27) -> 0 | N27: =IF(M27=0,"Primary line","Second line") -> Primary line | O27: =L27*IF(M27=0,1,Assumptions!$B$13)+IF(I27="Signed, not started",Assumptions!$B$14,0) -> 1 | P27: =SUMIFS($H$6:$H$68,$A$6:$A$68,A27) -> 5000 | Q27: =IF(P27>=Assumptions!$B$16,"Head of AM (Gayu)",IF(M27>0,"Same AM as the primary line",IF(G27="US + Canada","AM, US + Canada (test hire)",IF(C27="Paid media","AM, Paid Media, India + RoW","AM, SEO and GEO, India + RoW")))) -> AM, Paid Media, India + RoW
A28: Limelight | B28: Limelight Inc | C28: Paid media | D28: Raghu | E28: Mahesh | F28: US | G28: =IF(OR(F28="US",F28="US + Canada"),"US + Canada",IF(F28="Untagged","Untagged","India + RoW")) -> US + Canada | H28: 3500 | I28: Live | J28: Below price floor | K28: =IF(H28>=Assumptions!$B$11,"Enterprise",IF(H28>=Assumptions!$B$12,"Mid","Starter")) -> Starter | L28: =IF(K28="Enterprise",Assumptions!$B$8,IF(K28="Mid",Assumptions!$B$9,Assumptions!$B$10)) -> 0.75 | M28: =COUNTIFS($A$6:$A$68,A28,$H$6:$H$68,">"&H28)+COUNTIFS($A$5:A27,A28,$H$5:H27,H28) -> 1 | N28: =IF(M28=0,"Primary line","Second line") -> Second line | O28: =L28*IF(M28=0,1,Assumptions!$B$13)+IF(I28="Signed, not started",Assumptions!$B$14,0) -> 0.375 | P28: =SUMIFS($H$6:$H$68,$A$6:$A$68,A28) -> 8625 | Q28: =IF(P28>=Assumptions!$B$16,"Head of AM (Gayu)",IF(M28>0,"Same AM as the primary line",IF(G28="US + Canada","AM, US + Canada (test hire)",IF(C28="Paid media","AM, Paid Media, India + RoW","AM, SEO and GEO, India + RoW")))) -> Same AM as the primary line
A29: Infobip | B29: Infobip | C29: Paid media | D29: Raghu | E29: Mahesh | F29: India | G29: =IF(OR(F29="US",F29="US + Canada"),"US + Canada",IF(F29="Untagged","Untagged","India + RoW")) -> India + RoW | H29: 5000 | I29: Live | K29: =IF(H29>=Assumptions!$B$11,"Enterprise",IF(H29>=Assumptions!$B$12,"Mid","Starter")) -> Mid | L29: =IF(K29="Enterprise",Assumptions!$B$8,IF(K29="Mid",Assumptions!$B$9,Assumptions!$B$10)) -> 1 | M29: =COUNTIFS($A$6:$A$68,A29,$H$6:$H$68,">"&H29)+COUNTIFS($A$5:A28,A29,$H$5:H28,H29) -> 0 | N29: =IF(M29=0,"Primary line","Second line") -> Primary line | O29: =L29*IF(M29=0,1,Assumptions!$B$13)+IF(I29="Signed, not started",Assumptions!$B$14,0) -> 1 | P29: =SUMIFS($H$6:$H$68,$A$6:$A$68,A29) -> 5000 | Q29: =IF(P29>=Assumptions!$B$16,"Head of AM (Gayu)",IF(M29>0,"Same AM as the primary line",IF(G29="US + Canada","AM, US + Canada (test hire)",IF(C29="Paid media","AM, Paid Media, India + RoW","AM, SEO and GEO, India + RoW")))) -> AM, Paid Media, India + RoW
A30: Helpshift | B30: Helpshift | C30: Paid media | D30: Vidya | E30: Mahesh | F30: India | G30: =IF(OR(F30="US",F30="US + Canada"),"US + Canada",IF(F30="Untagged","Untagged","India + RoW")) -> India + RoW | H30: 2500 | I30: Live | J30: Below price floor | K30: =IF(H30>=Assumptions!$B$11,"Enterprise",IF(H30>=Assumptions!$B$12,"Mid","Starter")) -> Starter | L30: =IF(K30="Enterprise",Assumptions!$B$8,IF(K30="Mid",Assumptions!$B$9,Assumptions!$B$10)) -> 0.75 | M30: =COUNTIFS($A$6:$A$68,A30,$H$6:$H$68,">"&H30)+COUNTIFS($A$5:A29,A30,$H$5:H29,H30) -> 1 | N30: =IF(M30=0,"Primary line","Second line") -> Second line | O30: =L30*IF(M30=0,1,Assumptions!$B$13)+IF(I30="Signed, not started",Assumptions!$B$14,0) -> 0.375 | P30: =SUMIFS($H$6:$H$68,$A$6:$A$68,A30) -> 5500 | Q30: =IF(P30>=Assumptions!$B$16,"Head of AM (Gayu)",IF(M30>0,"Same AM as the primary line",IF(G30="US + Canada","AM, US + Canada (test hire)",IF(C30="Paid media","AM, Paid Media, India + RoW","AM, SEO and GEO, India + RoW")))) -> Same AM as the primary line
A31: Paddle | B31: Paddle | C31: Paid media | D31: Vidya | E31: Mahesh | F31: EU | G31: =IF(OR(F31="US",F31="US + Canada"),"US + Canada",IF(F31="Untagged","Untagged","India + RoW")) -> India + RoW | H31: 10000 | I31: Live | K31: =IF(H31>=Assumptions!$B$11,"Enterprise",IF(H31>=Assumptions!$B$12,"Mid","Starter")) -> Enterprise | L31: =IF(K31="Enterprise",Assumptions!$B$8,IF(K31="Mid",Assumptions!$B$9,Assumptions!$B$10)) -> 1.5 | M31: =COUNTIFS($A$6:$A$68,A31,$H$6:$H$68,">"&H31)+COUNTIFS($A$5:A30,A31,$H$5:H30,H31) -> 0 | N31: =IF(M31=0,"Primary line","Second line") -> Primary line | O31: =L31*IF(M31=0,1,Assumptions!$B$13)+IF(I31="Signed, not started",Assumptions!$B$14,0) -> 1.5 | P31: =SUMIFS($H$6:$H$68,$A$6:$A$68,A31) -> 10000 | Q31: =IF(P31>=Assumptions!$B$16,"Head of AM (Gayu)",IF(M31>0,"Same AM as the primary line",IF(G31="US + Canada","AM, US + Canada (test hire)",IF(C31="Paid media","AM, Paid Media, India + RoW","AM, SEO and GEO, India + RoW")))) -> AM, Paid Media, India + RoW
A32: IFS | B32: IFS | C32: Paid media | D32: Srushti | E32: SN | F32: US | G32: =IF(OR(F32="US",F32="US + Canada"),"US + Canada",IF(F32="Untagged","Untagged","India + RoW")) -> US + Canada | H32: 10000 | I32: Signed, not started | K32: =IF(H32>=Assumptions!$B$11,"Enterprise",IF(H32>=Assumptions!$B$12,"Mid","Starter")) -> Enterprise | L32: =IF(K32="Enterprise",Assumptions!$B$8,IF(K32="Mid",Assumptions!$B$9,Assumptions!$B$10)) -> 1.5 | M32: =COUNTIFS($A$6:$A$68,A32,$H$6:$H$68,">"&H32)+COUNTIFS($A$5:A31,A32,$H$5:H31,H32) -> 0 | N32: =IF(M32=0,"Primary line","Second line") -> Primary line | O32: =L32*IF(M32=0,1,Assumptions!$B$13)+IF(I32="Signed, not started",Assumptions!$B$14,0) -> 2 | P32: =SUMIFS($H$6:$H$68,$A$6:$A$68,A32) -> 10000 | Q32: =IF(P32>=Assumptions!$B$16,"Head of AM (Gayu)",IF(M32>0,"Same AM as the primary line",IF(G32="US + Canada","AM, US + Canada (test hire)",IF(C32="Paid media","AM, Paid Media, India + RoW","AM, SEO and GEO, India + RoW")))) -> AM, US + Canada (test hire)
A33: Whatfix | B33: Whatfix | C33: Paid media | D33: Bas | E33: Sabari | F33: India | G33: =IF(OR(F33="US",F33="US + Canada"),"US + Canada",IF(F33="Untagged","Untagged","India + RoW")) -> India + RoW | H33: 5000 | I33: Signed, not started | K33: =IF(H33>=Assumptions!$B$11,"Enterprise",IF(H33>=Assumptions!$B$12,"Mid","Starter")) -> Mid | L33: =IF(K33="Enterprise",Assumptions!$B$8,IF(K33="Mid",Assumptions!$B$9,Assumptions!$B$10)) -> 1 | M33: =COUNTIFS($A$6:$A$68,A33,$H$6:$H$68,">"&H33)+COUNTIFS($A$5:A32,A33,$H$5:H32,H33) -> 0 | N33: =IF(M33=0,"Primary line","Second line") -> Primary line | O33: =L33*IF(M33=0,1,Assumptions!$B$13)+IF(I33="Signed, not started",Assumptions!$B$14,0) -> 1.5 | P33: =SUMIFS($H$6:$H$68,$A$6:$A$68,A33) -> 5000 | Q33: =IF(P33>=Assumptions!$B$16,"Head of AM (Gayu)",IF(M33>0,"Same AM as the primary line",IF(G33="US + Canada","AM, US + Canada (test hire)",IF(C33="Paid media","AM, Paid Media, India + RoW","AM, SEO and GEO, India + RoW")))) -> AM, Paid Media, India + RoW
A34: MMT Happay | B34: MMT Happay | C34: Paid media | D34: Sabari direct | E34: Sabari | F34: India | G34: =IF(OR(F34="US",F34="US + Canada"),"US + Canada",IF(F34="Untagged","Untagged","India + RoW")) -> India + RoW | H34: 3000 | I34: Signed, not started | K34: =IF(H34>=Assumptions!$B$11,"Enterprise",IF(H34>=Assumptions!$B$12,"Mid","Starter")) -> Starter | L34: =IF(K34="Enterprise",Assumptions!$B$8,IF(K34="Mid",Assumptions!$B$9,Assumptions!$B$10)) -> 0.75 | M34: =COUNTIFS($A$6:$A$68,A34,$H$6:$H$68,">"&H34)+COUNTIFS($A$5:A33,A34,$H$5:H33,H34) -> 0 | N34: =IF(M34=0,"Primary line","Second line") -> Primary line | O34: =L34*IF(M34=0,1,Assumptions!$B$13)+IF(I34="Signed, not started",Assumptions!$B$14,0) -> 1.25 | P34: =SUMIFS($H$6:$H$68,$A$6:$A$68,A34) -> 3000 | Q34: =IF(P34>=Assumptions!$B$16,"Head of AM (Gayu)",IF(M34>0,"Same AM as the primary line",IF(G34="US + Canada","AM, US + Canada (test hire)",IF(C34="Paid media","AM, Paid Media, India + RoW","AM, SEO and GEO, India + RoW")))) -> AM, Paid Media, India + RoW
A35: Everstage | B35: Everstage | C35: SEO and GEO | D35: Pod 1 | E35: Glenn | F35: India + RoW | G35: =IF(OR(F35="US",F35="US + Canada"),"US + Canada",IF(F35="Untagged","Untagged","India + RoW")) -> India + RoW | H35: 7500 | I35: Live | J35: Unstable | K35: =IF(H35>=Assumptions!$B$11,"Enterprise",IF(H35>=Assumptions!$B$12,"Mid","Starter")) -> Enterprise | L35: =IF(K35="Enterprise",Assumptions!$B$8,IF(K35="Mid",Assumptions!$B$9,Assumptions!$B$10)) -> 1.5 | M35: =COUNTIFS($A$6:$A$68,A35,$H$6:$H$68,">"&H35)+COUNTIFS($A$5:A34,A35,$H$5:H34,H35) -> 0 | N35: =IF(M35=0,"Primary line","Second line") -> Primary line | O35: =L35*IF(M35=0,1,Assumptions!$B$13)+IF(I35="Signed, not started",Assumptions!$B$14,0) -> 1.5 | P35: =SUMIFS($H$6:$H$68,$A$6:$A$68,A35) -> 7500 | Q35: =IF(P35>=Assumptions!$B$16,"Head of AM (Gayu)",IF(M35>0,"Same AM as the primary line",IF(G35="US + Canada","AM, US + Canada (test hire)",IF(C35="Paid media","AM, Paid Media, India + RoW","AM, SEO and GEO, India + RoW")))) -> AM, SEO and GEO, India + RoW
A36: Mailreach | B36: Mailreach | C36: SEO and GEO | D36: Pod 1 | E36: Glenn | F36: India + RoW | G36: =IF(OR(F36="US",F36="US + Canada"),"US + Canada",IF(F36="Untagged","Untagged","India + RoW")) -> India + RoW | H36: 7700 | I36: Live | K36: =IF(H36>=Assumptions!$B$11,"Enterprise",IF(H36>=Assumptions!$B$12,"Mid","Starter")) -> Enterprise | L36: =IF(K36="Enterprise",Assumptions!$B$8,IF(K36="Mid",Assumptions!$B$9,Assumptions!$B$10)) -> 1.5 | M36: =COUNTIFS($A$6:$A$68,A36,$H$6:$H$68,">"&H36)+COUNTIFS($A$5:A35,A36,$H$5:H35,H36) -> 0 | N36: =IF(M36=0,"Primary line","Second line") -> Primary line | O36: =L36*IF(M36=0,1,Assumptions!$B$13)+IF(I36="Signed, not started",Assumptions!$B$14,0) -> 1.5 | P36: =SUMIFS($H$6:$H$68,$A$6:$A$68,A36) -> 7700 | Q36: =IF(P36>=Assumptions!$B$16,"Head of AM (Gayu)",IF(M36>0,"Same AM as the primary line",IF(G36="US + Canada","AM, US + Canada (test hire)",IF(C36="Paid media","AM, Paid Media, India + RoW","AM, SEO and GEO, India + RoW")))) -> AM, SEO and GEO, India + RoW
A37: ZingHR | B37: ZingHR | C37: SEO and GEO | D37: Pod 1 | E37: Glenn | F37: India + RoW | G37: =IF(OR(F37="US",F37="US + Canada"),"US + Canada",IF(F37="Untagged","Untagged","India + RoW")) -> India + RoW | H37: 5500 | I37: Live | K37: =IF(H37>=Assumptions!$B$11,"Enterprise",IF(H37>=Assumptions!$B$12,"Mid","Starter")) -> Mid | L37: =IF(K37="Enterprise",Assumptions!$B$8,IF(K37="Mid",Assumptions!$B$9,Assumptions!$B$10)) -> 1 | M37: =COUNTIFS($A$6:$A$68,A37,$H$6:$H$68,">"&H37)+COUNTIFS($A$5:A36,A37,$H$5:H36,H37) -> 0 | N37: =IF(M37=0,"Primary line","Second line") -> Primary line | O37: =L37*IF(M37=0,1,Assumptions!$B$13)+IF(I37="Signed, not started",Assumptions!$B$14,0) -> 1 | P37: =SUMIFS($H$6:$H$68,$A$6:$A$68,A37) -> 5500 | Q37: =IF(P37>=Assumptions!$B$16,"Head of AM (Gayu)",IF(M37>0,"Same AM as the primary line",IF(G37="US + Canada","AM, US + Canada (test hire)",IF(C37="Paid media","AM, Paid Media, India + RoW","AM, SEO and GEO, India + RoW")))) -> AM, SEO and GEO, India + RoW
A38: FarEye | B38: Fareye | C38: SEO and GEO | D38: Pod 1 | E38: Glenn | F38: India + RoW | G38: =IF(OR(F38="US",F38="US + Canada"),"US + Canada",IF(F38="Untagged","Untagged","India + RoW")) -> India + RoW | H38: 5000 | I38: Live | K38: =IF(H38>=Assumptions!$B$11,"Enterprise",IF(H38>=Assumptions!$B$12,"Mid","Starter")) -> Mid | L38: =IF(K38="Enterprise",Assumptions!$B$8,IF(K38="Mid",Assumptions!$B$9,Assumptions!$B$10)) -> 1 | M38: =COUNTIFS($A$6:$A$68,A38,$H$6:$H$68,">"&H38)+COUNTIFS($A$5:A37,A38,$H$5:H37,H38) -> 0 | N38: =IF(M38=0,"Primary line","Second line") -> Primary line | O38: =L38*IF(M38=0,1,Assumptions!$B$13)+IF(I38="Signed, not started",Assumptions!$B$14,0) -> 1 | P38: =SUMIFS($H$6:$H$68,$A$6:$A$68,A38) -> 5000 | Q38: =IF(P38>=Assumptions!$B$16,"Head of AM (Gayu)",IF(M38>0,"Same AM as the primary line",IF(G38="US + Canada","AM, US + Canada (test hire)",IF(C38="Paid media","AM, Paid Media, India + RoW","AM, SEO and GEO, India + RoW")))) -> AM, SEO and GEO, India + RoW
A39: RTS Labs | B39: RTSLabs | C39: SEO and GEO | D39: Pod 1 | E39: Glenn | F39: India + RoW | G39: =IF(OR(F39="US",F39="US + Canada"),"US + Canada",IF(F39="Untagged","Untagged","India + RoW")) -> India + RoW | H39: 5000 | I39: Live | K39: =IF(H39>=Assumptions!$B$11,"Enterprise",IF(H39>=Assumptions!$B$12,"Mid","Starter")) -> Mid | L39: =IF(K39="Enterprise",Assumptions!$B$8,IF(K39="Mid",Assumptions!$B$9,Assumptions!$B$10)) -> 1 | M39: =COUNTIFS($A$6:$A$68,A39,$H$6:$H$68,">"&H39)+COUNTIFS($A$5:A38,A39,$H$5:H38,H39) -> 0 | N39: =IF(M39=0,"Primary line","Second line") -> Primary line | O39: =L39*IF(M39=0,1,Assumptions!$B$13)+IF(I39="Signed, not started",Assumptions!$B$14,0) -> 1 | P39: =SUMIFS($H$6:$H$68,$A$6:$A$68,A39) -> 7500 | Q39: =IF(P39>=Assumptions!$B$16,"Head of AM (Gayu)",IF(M39>0,"Same AM as the primary line",IF(G39="US + Canada","AM, US + Canada (test hire)",IF(C39="Paid media","AM, Paid Media, India + RoW","AM, SEO and GEO, India + RoW")))) -> AM, SEO and GEO, India + RoW
A40: SKU IQ | B40: SKU IQ | C40: SEO and GEO | D40: Pod 1 | E40: Glenn | F40: US | G40: =IF(OR(F40="US",F40="US + Canada"),"US + Canada",IF(F40="Untagged","Untagged","India + RoW")) -> US + Canada | H40: 5000 | I40: Live | J40: Needs US hours | K40: =IF(H40>=Assumptions!$B$11,"Enterprise",IF(H40>=Assumptions!$B$12,"Mid","Starter")) -> Mid | L40: =IF(K40="Enterprise",Assumptions!$B$8,IF(K40="Mid",Assumptions!$B$9,Assumptions!$B$10)) -> 1 | M40: =COUNTIFS($A$6:$A$68,A40,$H$6:$H$68,">"&H40)+COUNTIFS($A$5:A39,A40,$H$5:H39,H40) -> 0 | N40: =IF(M40=0,"Primary line","Second line") -> Primary line | O40: =L40*IF(M40=0,1,Assumptions!$B$13)+IF(I40="Signed, not started",Assumptions!$B$14,0) -> 1 | P40: =SUMIFS($H$6:$H$68,$A$6:$A$68,A40) -> 5000 | Q40: =IF(P40>=Assumptions!$B$16,"Head of AM (Gayu)",IF(M40>0,"Same AM as the primary line",IF(G40="US + Canada","AM, US + Canada (test hire)",IF(C40="Paid media","AM, Paid Media, India + RoW","AM, SEO and GEO, India + RoW")))) -> AM, US + Canada (test hire)
A41: Field1st | B41: Field1st | C41: SEO and GEO | D41: Pod 1 | E41: Glenn | F41: India + RoW | G41: =IF(OR(F41="US",F41="US + Canada"),"US + Canada",IF(F41="Untagged","Untagged","India + RoW")) -> India + RoW | H41: 3000 | I41: Live | K41: =IF(H41>=Assumptions!$B$11,"Enterprise",IF(H41>=Assumptions!$B$12,"Mid","Starter")) -> Starter | L41: =IF(K41="Enterprise",Assumptions!$B$8,IF(K41="Mid",Assumptions!$B$9,Assumptions!$B$10)) -> 0.75 | M41: =COUNTIFS($A$6:$A$68,A41,$H$6:$H$68,">"&H41)+COUNTIFS($A$5:A40,A41,$H$5:H40,H41) -> 0 | N41: =IF(M41=0,"Primary line","Second line") -> Primary line | O41: =L41*IF(M41=0,1,Assumptions!$B$13)+IF(I41="Signed, not started",Assumptions!$B$14,0) -> 0.75 | P41: =SUMIFS($H$6:$H$68,$A$6:$A$68,A41) -> 3000 | Q41: =IF(P41>=Assumptions!$B$16,"Head of AM (Gayu)",IF(M41>0,"Same AM as the primary line",IF(G41="US + Canada","AM, US + Canada (test hire)",IF(C41="Paid media","AM, Paid Media, India + RoW","AM, SEO and GEO, India + RoW")))) -> AM, SEO and GEO, India + RoW
...

Sheet Capacity
A1: Capacity: how many account managers each version needs
A2: Weighted units come from the Client Book. One ramped AM carries the target units in Assumptions.
A4: Version 1. Today's book: weighted units by service line and shift
A5: Service line | B5: India + RoW | C5: US + Canada | D5: Untagged | E5: Untagged to US | F5: Untagged to India + RoW | G5: Units, India + RoW | H5: Units, US + Canada
A6: Paid media | B6: =SUMIFS('Client Book'!$O$6:$O$68,'Client Book'!$C$6:$C$68,$A6,'Client Book'!$G$6:$G$68,"India + RoW") -> 19.5 | C6: =SUMIFS('Client Book'!$O$6:$O$68,'Client Book'!$C$6:$C$68,$A6,'Client Book'!$G$6:$G$68,"US + Canada") -> 9.75 | D6: =SUMIFS('Client Book'!$O$6:$O$68,'Client Book'!$C$6:$C$68,$A6,'Client Book'!$G$6:$G$68,"Untagged") -> 0 | E6: =D6*Assumptions!$B$22 -> 0 | F6: =D6-E6 -> 0 | G6: =B6+F6 -> 19.5 | H6: =C6+E6 -> 9.75
A7: SEO and GEO | B7: =SUMIFS('Client Book'!$O$6:$O$68,'Client Book'!$C$6:$C$68,$A7,'Client Book'!$G$6:$G$68,"India + RoW") -> 13.5 | C7: =SUMIFS('Client Book'!$O$6:$O$68,'Client Book'!$C$6:$C$68,$A7,'Client Book'!$G$6:$G$68,"US + Canada") -> 5.25 | D7: =SUMIFS('Client Book'!$O$6:$O$68,'Client Book'!$C$6:$C$68,$A7,'Client Book'!$G$6:$G$68,"Untagged") -> 13.75 | E7: =D7*Assumptions!$B$22 -> 4.125 | F7: =D7-E7 -> 9.625 | G7: =B7+F7 -> 23.125 | H7: =C7+E7 -> 9.375
A8: RevOps (only if included) | B8: =Assumptions!$B$19*Assumptions!$B$21*Assumptions!$B$18 -> 0 | C8: 0 | D8: 0 | E8: =D8*Assumptions!$B$22 -> 0 | F8: =D8-E8 -> 0 | G8: =B8+F8 -> 0 | H8: =C8+E8 -> 0
A9: Total | B9: =SUM(B6:B8) -> 33 | C9: =SUM(C6:C8) -> 15 | D9: =SUM(D6:D8) -> 13.75 | E9: =SUM(E6:E8) -> 4.125 | F9: =SUM(F6:F8) -> 9.625 | G9: =SUM(G6:G8) -> 42.625 | H9: =SUM(H6:H8) -> 19.125
A11: Total weighted units, today's book | B11: =G9+H9 -> 61.75
A12: Units the Head of AM owns directly (accounts at or above her MRR line) | B12: =SUMIFS('Client Book'!$O$6:$O$68,'Client Book'!$Q$6:$Q$68,"Head of AM (Gayu)") -> 4.25
A13: Units the Head of AM carries (capped at her capacity) | B13: =MIN(B12,Assumptions!$B$15) -> 4.25
A14: Units left for account managers | B14: =B11-B13 -> 57.5
A15: FTE needed at target load | B15: =B14/Assumptions!$B$6 -> 4.4230769
A16: Account managers to hire for full coverage of today's book | B16: =ROUNDUP(B15,0) -> 5
A17: Of which on US + Canada hours | B17: =ROUND(H9/Assumptions!$B$6,0) -> 1
A18: Of which on India + RoW hours | B18: =B16-B17 -> 4
A19: Accounts today (paid and SEO, unique clients) | B19: =SUMPRODUCT(--('Client Book'!$N$6:$N$68="Primary line")) -> 55
A20: Clients buying both paid and SEO | B20: =SUMPRODUCT(--('Client Book'!$N$6:$N$68="Second line")) -> 8
A21: MRR in scope today ($) | B21: =SUM('Client Book'!$H$6:$H$68)+Assumptions!$B$20*Assumptions!$B$18 -> 307225
A22: MRR per account manager ($) | B22: =IF(B16=0,0,B21/B16) -> 61445
A24: Version 2. 100 engagements in two months
A25: Engagements today (all service lines) | B25: =Assumptions!$B$24 -> 73
A26: Engagements today in AM scope (paid + SEO, plus RevOps if included) | B26: =COUNTA('Client Book'!$A$6:$A$68)+Assumptions!$B$19*Assumptions!$B$18 -> 63
A27: Target engagements | B27: =Assumptions!$B$25 -> 100
A28: Target engagements in AM scope (same mix as today) | B28: =B27*B26/B25 -> 86.30137
A29: Weighted units per in-scope engagement today | B29: =IF(B26=0,0,B11/B26) -> 0.98015873
A30: Steady-state units at the target | B30: =B28*B29 -> 84.589041
A31: Onboarding load from new in-scope engagements | B31: =(B28-B26)*Assumptions!$B$14 -> 11.650685
A32: Peak units while new accounts onboard | B32: =B30+B31 -> 96.239726
A33: Units left for AMs at steady state (after the Head of AM) | B33: =B30-Assumptions!$B$15 -> 78.589041
A34: Account managers needed at steady state | B34: =ROUNDUP(B33/Assumptions!$B$6,0) -> 7
A35: Account managers needed at the onboarding peak, at stretch load | B35: =ROUNDUP((B32-Assumptions!$B$15)/Assumptions!$B$7,0) -> 6
A36: Account managers to plan for (larger of the two) | B36: =MAX(B34,B35) -> 7
A37: Of which on US + Canada hours (same share as today) | B37: =ROUND(B36*H9/B11,0) -> 2
A38: Of which on India + RoW hours | B38: =B36-B37 -> 5
A40: Version 3. Lean start: one SEO AM and two paid media AMs
A41: Service line | B41: AMs in this version | C41: Capacity (units) | D41: Units in today's book | E41: Coverage | F41: Units not covered
A42: Paid media | B42: 2 | C42: =B42*Assumptions!$B$6 -> 26 | D42: =SUMIFS('Client Book'!$O$6:$O$68,'Client Book'!$C$6:$C$68,"Paid media",'Client Book'!$Q$6:$Q$68,"<>Head of AM (Gayu)") -> 27.25 | E42: =IF(D42=0,0,MIN(1,C42/D42)) -> 0.95412844 | F42: =MAX(0,D42-C42) -> 1.25
A43: SEO and GEO | B43: 1 | C43: =B43*Assumptions!$B$6 -> 13 | D43: =SUMIFS('Client Book'!$O$6:$O$68,'Client Book'!$C$6:$C$68,"SEO and GEO",'Client Book'!$Q$6:$Q$68,"<>Head of AM (Gayu)") -> 30.25 | E43: =IF(D43=0,0,MIN(1,C43/D43)) -> 0.42975207 | F43: =MAX(0,D43-C43) -> 17.25
A44: Head of AM (tier-1 and full-service) | B44: 1 | C44: =Assumptions!$B$15 -> 6 | D44: =B12 -> 4.25 | E44: =IF(D44=0,0,MIN(1,C44/D44)) -> 1 | F44: =MAX(0,D44-C44) -> 0
...

Sheet Seats
A1: Seats: every account management role, its stage, start month and cost
A2: Stage 1 = lean start. Stage 2 = full coverage of today's book. Stage 3 = 100 engagements. Start month is the month index on the Hiring Ramp (1 = Nov 2026).
A4: # | B4: Seat | C4: Service line | D4: Book | E4: Location | F4: Shift | G4: Stage | H4: Start month (1 = Nov 2026) | I4: Fixed (local) | J4: Variable at target (local) | K4: Currency | L4: Annual cost, loaded ($) | M4: Monthly cost, loaded ($) | N4: Annual cost (₹ lakh)
A5: 0 | B5: Head of Account Management (Gayu, title to confirm) | C5: All | D5: Tier-1 and full-service accounts, the team, process | E5: India | F5: Both, overlap 5-10 pm IST | G5: 1 | H5: 1 | I5: =Assumptions!$B$44 -> 0 | J5: 0 | K5: INR lakh | L5: =(I5+J5)*100000/Assumptions!$B$33*(1+Assumptions!$B$36) -> 0 | M5: =L5/12 -> 0 | N5: =L5*Assumptions!$B$33/100000 -> 0
A6: 1 | B6: Account Manager, Paid Media | C6: Paid media | D6: India + RoW paid accounts | E6: India | F6: GMT | G6: 1 | H6: 2 | I6: =Assumptions!$B$38 -> 15 | J6: =Assumptions!$B$39 -> 10 | K6: INR lakh | L6: =(I6+J6)*100000/Assumptions!$B$33*(1+Assumptions!$B$36) -> 27659.574 | M6: =L6/12 -> 2304.9645 | N6: =L6*Assumptions!$B$33/100000 -> 26
A7: 2 | B7: Account Manager, US + Canada (test hire) | C7: Paid media first, then SEO US | D7: US + Canada accounts, all lines | E7: =Assumptions!$B$45 -> Canada | F7: EST | G7: 1 | H7: 3 | I7: =IF(Assumptions!$B$45="Canada",Assumptions!$B$40,Assumptions!$B$42) -> 75000 | J7: =IF(Assumptions!$B$45="Canada",Assumptions!$B$41,Assumptions!$B$43) -> 25000 | K7: =IF(Assumptions!$B$45="Canada","CAD","ZAR") -> CAD | L7: =(I7+J7)/IF(K7="CAD",Assumptions!$B$34,Assumptions!$B$35)*(1+Assumptions!$B$37) -> 81159.42 | M7: =L7/12 -> 6763.285 | N7: =L7*Assumptions!$B$33/100000 -> 76.289855
A8: 3 | B8: Account Manager, SEO and GEO | C8: SEO and GEO | D8: India + RoW SEO accounts, at-risk first | E8: India | F8: GMT | G8: 1 | H8: 2 | I8: =Assumptions!$B$38 -> 15 | J8: =Assumptions!$B$39 -> 10 | K8: INR lakh | L8: =(I8+J8)*100000/Assumptions!$B$33*(1+Assumptions!$B$36) -> 27659.574 | M8: =L8/12 -> 2304.9645 | N8: =L8*Assumptions!$B$33/100000 -> 26
A9: 4 | B9: Account Manager, SEO and GEO | C9: SEO and GEO | D9: Rest of India + RoW SEO, untagged accounts | E9: India | F9: GMT | G9: 2 | H9: 3 | I9: =Assumptions!$B$38 -> 15 | J9: =Assumptions!$B$39 -> 10 | K9: INR lakh | L9: =(I9+J9)*100000/Assumptions!$B$33*(1+Assumptions!$B$36) -> 27659.574 | M9: =L9/12 -> 2304.9645 | N9: =L9*Assumptions!$B$33/100000 -> 26
A10: 5 | B10: Account Manager, Paid Media and full-service | C10: Paid media | D10: Second paid book; full-service accounts below the Head of AM line | E10: India | F10: GMT | G10: 2 | H10: 3 | I10: =Assumptions!$B$38 -> 15 | J10: =Assumptions!$B$39 -> 10 | K10: INR lakh | L10: =(I10+J10)*100000/Assumptions!$B$33*(1+Assumptions!$B$36) -> 27659.574 | M10: =L10/12 -> 2304.9645 | N10: =L10*Assumptions!$B$33/100000 -> 26
A11: 6 | B11: Account Manager, US + Canada (EST shift) | C11: All | D11: Second US book as US engagements grow | E11: India | F11: EST | G11: 3 | H11: 4 | I11: =Assumptions!$B$38 -> 15 | J11: =Assumptions!$B$39 -> 10 | K11: INR lakh | L11: =(I11+J11)*100000/Assumptions!$B$33*(1+Assumptions!$B$36) -> 27659.574 | M11: =L11/12 -> 2304.9645 | N11: =L11*Assumptions!$B$33/100000 -> 26
A12: 7 | B12: Account Manager, India + RoW (paid or SEO, whichever book fills first) | C12: Paid media or SEO and GEO | D12: New India + RoW engagements | E12: India | F12: GMT | G12: 3 | H12: 4 | I12: =Assumptions!$B$38 -> 15 | J12: =Assumptions!$B$39 -> 10 | K12: INR lakh | L12: =(I12+J12)*100000/Assumptions!$B$33*(1+Assumptions!$B$36) -> 27659.574 | M12: =L12/12 -> 2304.9645 | N12: =L12*Assumptions!$B$33/100000 -> 26
B14: Seats in the modelled stage | G14: =COUNTIFS(G6:G12,"<="&Assumptions!$B$58) -> 7 | K14: Annual cost, modelled stage | L14: =SUMIFS(L5:L12,G5:G12,"<="&Assumptions!$B$58) -> 247116.87 | N14: =L14*Assumptions!$B$33/100000 -> 232.28986
B16: Fixed and variable are in the local currency of the seat: ₹ lakh for India, CAD or ZAR for the test hire. Cost assumes variable paid at 100% of target. Gayu is already on payroll, so her row shows only the role uplift.
B17: Past 100 engagements, add one account manager for roughly every 13 new engagements (one target book).

Sheet Hiring Ramp
A1: Hiring ramp: demand against account manager capacity, month by month
A2: Demand grows to the target engagements, then by the monthly run-rate. New AMs ramp 40% / 70% / 100%. Seats come from the Seats tab for the stage set in Assumptions.
A4: Month | B4: Nov 2026 | C4: Dec 2026 | D4: Jan 2027 | E4: Feb 2027 | F4: Mar 2027 | G4: Apr 2027 | H4: May 2027 | I4: Jun 2027 | J4: Jul 2027
A5: Month index | B5: 1 | C5: 2 | D5: 3 | E5: 4 | F5: 5 | G5: 6 | H5: 7 | I5: 8 | J5: 9
A7: Demand
A8: Engagements, all lines (end of month) | B8: =IF(B$5<=Assumptions!$B$26,Assumptions!$B$24+(Assumptions!$B$25-Assumptions!$B$24)*B$5/Assumptions!$B$26,Assumptions!$B$25+(B$5-Assumptions!$B$26)*Assumptions!$B$27) -> 86.5 | C8: =IF(C$5<=Assumptions!$B$26,Assumptions!$B$24+(Assumptions!$B$25-Assumptions!$B$24)*C$5/Assumptions!$B$26,Assumptions!$B$25+(C$5-Assumptions!$B$26)*Assumptions!$B$27) -> 100 | D8: =IF(D$5<=Assumptions!$B$26,Assumptions!$B$24+(Assumptions!$B$25-Assumptions!$B$24)*D$5/Assumptions!$B$26,Assumptions!$B$25+(D$5-Assumptions!$B$26)*Assumptions!$B$27) -> 104 | E8: =IF(E$5<=Assumptions!$B$26,Assumptions!$B$24+(Assumptions!$B$25-Assumptions!$B$24)*E$5/Assumptions!$B$26,Assumptions!$B$25+(E$5-Assumptions!$B$26)*Assumptions!$B$27) -> 108 | F8: =IF(F$5<=Assumptions!$B$26,Assumptions!$B$24+(Assumptions!$B$25-Assumptions!$B$24)*F$5/Assumptions!$B$26,Assumptions!$B$25+(F$5-Assumptions!$B$26)*Assumptions!$B$27) -> 112 | G8: =IF(G$5<=Assumptions!$B$26,Assumptions!$B$24+(Assumptions!$B$25-Assumptions!$B$24)*G$5/Assumptions!$B$26,Assumptions!$B$25+(G$5-Assumptions!$B$26)*Assumptions!$B$27) -> 116 | H8: =IF(H$5<=Assumptions!$B$26,Assumptions!$B$24+(Assumptions!$B$25-Assumptions!$B$24)*H$5/Assumptions!$B$26,Assumptions!$B$25+(H$5-Assumptions!$B$26)*Assumptions!$B$27) -> 120 | I8: =IF(I$5<=Assumptions!$B$26,Assumptions!$B$24+(Assumptions!$B$25-Assumptions!$B$24)*I$5/Assumptions!$B$26,Assumptions!$B$25+(I$5-Assumptions!$B$26)*Assumptions!$B$27) -> 124 | J8: =IF(J$5<=Assumptions!$B$26,Assumptions!$B$24+(Assumptions!$B$25-Assumptions!$B$24)*J$5/Assumptions!$B$26,Assumptions!$B$25+(J$5-Assumptions!$B$26)*Assumptions!$B$27) -> 128
A9: Engagements in AM scope | B9: =B8*Capacity!$B$26/Capacity!$B$25 -> 74.650685 | C9: =C8*Capacity!$B$26/Capacity!$B$25 -> 86.30137 | D9: =D8*Capacity!$B$26/Capacity!$B$25 -> 89.753425 | E9: =E8*Capacity!$B$26/Capacity!$B$25 -> 93.205479 | F9: =F8*Capacity!$B$26/Capacity!$B$25 -> 96.657534 | G9: =G8*Capacity!$B$26/Capacity!$B$25 -> 100.10959 | H9: =H8*Capacity!$B$26/Capacity!$B$25 -> 103.56164 | I9: =I8*Capacity!$B$26/Capacity!$B$25 -> 107.0137 | J9: =J8*Capacity!$B$26/Capacity!$B$25 -> 110.46575
A10: New in-scope engagements in the last two months | B10: =MAX(0,B9-Capacity!$B$26) -> 11.650685 | C10: =MAX(0,C9-Capacity!$B$26) -> 23.30137 | D10: =MAX(0,D9-B9) -> 15.10274 | E10: =MAX(0,E9-C9) -> 6.9041096 | F10: =MAX(0,F9-D9) -> 6.9041096 | G10: =MAX(0,G9-E9) -> 6.9041096 | H10: =MAX(0,H9-F9) -> 6.9041096 | I10: =MAX(0,I9-G9) -> 6.9041096 | J10: =MAX(0,J9-H9) -> 6.9041096
A11: Weighted units of demand | B11: =B9*Capacity!$B$29+B10*Assumptions!$B$14 -> 78.994863 | C11: =C9*Capacity!$B$29+C10*Assumptions!$B$14 -> 96.239726 | D11: =D9*Capacity!$B$29+D10*Assumptions!$B$14 -> 95.523973 | E11: =E9*Capacity!$B$29+E10*Assumptions!$B$14 -> 94.808219 | F11: =F9*Capacity!$B$29+F10*Assumptions!$B$14 -> 98.191781 | G11: =G9*Capacity!$B$29+G10*Assumptions!$B$14 -> 101.57534 | H11: =H9*Capacity!$B$29+H10*Assumptions!$B$14 -> 104.9589 | I11: =I9*Capacity!$B$29+I10*Assumptions!$B$14 -> 108.34247 | J11: =J9*Capacity!$B$29+J10*Assumptions!$B$14 -> 111.72603
A13: Capacity by seat (weighted units)
A14: =Seats!A5&". "&Seats!B5&IF(Seats!G5>Assumptions!$B$58," (not in modelled stage)","") -> 0. Head of Account Management (Gayu, title to confirm) | B14: =IF(B$5<Seats!$H$5,0,Assumptions!$B$15) -> 6 | C14: =IF(C$5<Seats!$H$5,0,Assumptions!$B$15) -> 6 | D14: =IF(D$5<Seats!$H$5,0,Assumptions!$B$15) -> 6 | E14: =IF(E$5<Seats!$H$5,0,Assumptions!$B$15) -> 6 | F14: =IF(F$5<Seats!$H$5,0,Assumptions!$B$15) -> 6 | G14: =IF(G$5<Seats!$H$5,0,Assumptions!$B$15) -> 6 | H14: =IF(H$5<Seats!$H$5,0,Assumptions!$B$15) -> 6 | I14: =IF(I$5<Seats!$H$5,0,Assumptions!$B$15) -> 6 | J14: =IF(J$5<Seats!$H$5,0,Assumptions!$B$15) -> 6
A15: =Seats!A6&". "&Seats!B6&IF(Seats!G6>Assumptions!$B$58," (not in modelled stage)","") -> 1. Account Manager, Paid Media | B15: =IF(OR(Seats!$G$6>Assumptions!$B$58,B$5<Seats!$H$6),0,Assumptions!$B$6*IF((B$5-Seats!$H$6)=0,Assumptions!$B$29,IF((B$5-Seats!$H$6)=1,Assumptions!$B$30,Assumptions!$B$31))) -> 0 | C15: =IF(OR(Seats!$G$6>Assumptions!$B$58,C$5<Seats!$H$6),0,Assumptions!$B$6*IF((C$5-Seats!$H$6)=0,Assumptions!$B$29,IF((C$5-Seats!$H$6)=1,Assumptions!$B$30,Assumptions!$B$31))) -> 5.2 | D15: =IF(OR(Seats!$G$6>Assumptions!$B$58,D$5<Seats!$H$6),0,Assumptions!$B$6*IF((D$5-Seats!$H$6)=0,Assumptions!$B$29,IF((D$5-Seats!$H$6)=1,Assumptions!$B$30,Assumptions!$B$31))) -> 9.1 | E15: =IF(OR(Seats!$G$6>Assumptions!$B$58,E$5<Seats!$H$6),0,Assumptions!$B$6*IF((E$5-Seats!$H$6)=0,Assumptions!$B$29,IF((E$5-Seats!$H$6)=1,Assumptions!$B$30,Assumptions!$B$31))) -> 13 | F15: =IF(OR(Seats!$G$6>Assumptions!$B$58,F$5<Seats!$H$6),0,Assumptions!$B$6*IF((F$5-Seats!$H$6)=0,Assumptions!$B$29,IF((F$5-Seats!$H$6)=1,Assumptions!$B$30,Assumptions!$B$31))) -> 13 | G15: =IF(OR(Seats!$G$6>Assumptions!$B$58,G$5<Seats!$H$6),0,Assumptions!$B$6*IF((G$5-Seats!$H$6)=0,Assumptions!$B$29,IF((G$5-Seats!$H$6)=1,Assumptions!$B$30,Assumptions!$B$31))) -> 13 | H15: =IF(OR(Seats!$G$6>Assumptions!$B$58,H$5<Seats!$H$6),0,Assumptions!$B$6*IF((H$5-Seats!$H$6)=0,Assumptions!$B$29,IF((H$5-Seats!$H$6)=1,Assumptions!$B$30,Assumptions!$B$31))) -> 13 | I15: =IF(OR(Seats!$G$6>Assumptions!$B$58,I$5<Seats!$H$6),0,Assumptions!$B$6*IF((I$5-Seats!$H$6)=0,Assumptions!$B$29,IF((I$5-Seats!$H$6)=1,Assumptions!$B$30,Assumptions!$B$31))) -> 13 | J15: =IF(OR(Seats!$G$6>Assumptions!$B$58,J$5<Seats!$H$6),0,Assumptions!$B$6*IF((J$5-Seats!$H$6)=0,Assumptions!$B$29,IF((J$5-Seats!$H$6)=1,Assumptions!$B$30,Assumptions!$B$31))) -> 13
